Workbook
Name Apr: #REF!
Name Apr: #REF!
Name Aug: #REF!
Name Aug: #REF!
Name Dec: #REF!
Name Dec: #REF!
Name Feb: #REF!
Name Feb: #REF!
Name Jan: Apr!$B$1:$R$59
Name Jan: Aug!$B$1:$R$73
Name Jan: Dec!$B$1:$R$63
Name Jan: Feb!$B$1:$R$65
Name Jan: Jan!$B$1:$R$66
Name Jan: Jul!$B$1:$R$66
Name Jan: Jun!$B$1:$R$62
Name Jan: Mar!$B$1:$R$67
Name Jan: May!$B$1:$R$68
Name Jan: Nov!$B$1:$R$75
Name Jan: Oct!$B$1:$R$76
Name Jan: #REF!
Name Jan: Sept!$B$1:$R$60
Name Jan: #REF!
Name July: #REF!
Name July: #REF!
Name June: Apr!$B$1:$R$59
Name June: Aug!$B$1:$R$73
Name June: Dec!$B$1:$R$63
Name June: Feb!$B$1:$R$65
Name June: Jan!$B$1:$R$66
Name June: Jul!$B$1:$R$66
Name June: Jun!$B$1:$R$62
Name June: Mar!$B$1:$R$67
Name June: May!$B$1:$R$68
Name June: Nov!$B$1:$R$75
Name June: Oct!$B$1:$R$76
Name June: #REF!
Name June: Sept!$B$1:$R$60
Name June: #REF!
Name Mar: #REF!
Name Mar: #REF!
Name May: #REF!
Name May: #REF!
Name Nov: #REF!
Name Nov: #REF!
Name Oct: #REF!
Name Oct: #REF!
Name Sept: #REF!
Name Sept: #REF!
Name Summary: 'Monthly summary loss'!$A$1:$Y$44

Sheet Print
E1: PRINT BUTTONS (click to print)
B3: Mthly Report | D3: Pareto Charts | F3: Mthly Report | H3: Pareto Charts

Sheet Monthly summary loss
L2: Monthly Operating Report
K3: Bottling Line Downtime - Monthly Summary 2026
A5: Month | E5: Delays(hours)
B6: Operator Errors | C6: Change Over | D6: Product Delay | E6: Low Air Pressure | F6: Low CO2 Pressure | G6: Low Water Pressure | H6: Low Steam Pressure | I6: Uncaser | J6: Washer | K6: EBI | L6: Filler | M6: Pasteuriser | N6: Labeller | O6: Videojet (Coder) | P6: Conveyors | Q6: Packer | R6: Carton Errector | S6: Crate Rinser | T6: Other Explained | U6: Other Unexplained | V6: Bottle Supply | W6: Space Availability | X6: Total Downtime | Y6: Avg. monthly downtime (YTD) | AA6: Hls Bottled
A7: Jan | B7: =Jan!$H$61/60 -> 2.1833333 | C7: =Jan!$I$61/60 -> 21.583333 | D7: =Jan!$J$61/60 -> 9.55 | E7: =Jan!$K$61/60 -> 0.23333333 | F7: =Jan!$L$61/60 -> 0.26666667 | G7: =Jan!$M$61/60 -> 1.35 | H7: =Jan!$N$61/60 -> 0 | I7: =Jan!$O$61/60 -> 9.3833333 | J7: =Jan!$P$61/60 -> 21.366667 | K7: =Jan!$Q$61/60 -> 7.4333333 | L7: =Jan!$R$61/60 -> 4.6166667 | M7: =Jan!$S$61/60 -> 14.416667 | N7: =Jan!$T$61/60 -> 3.4 | O7: =Jan!$U$61/60 -> 1.9166667 | P7: =Jan!$V$61/60 -> 101.28333 | Q7: =Jan!$W$61/60 -> 1.2166667 | R7: =Jan!$X$61/60 -> 0 | S7: =Jan!$Y$61/60 -> 0 | T7: =Jan!$Z$61/60 -> 43.933333 | U7: =Jan!$AA$61/60 -> 0.85 | V7: =Jan!$AB$61/60 -> 5.3833333 | W7: =Jan!$AC$61/60 -> 0 | X7: =SUM(B7:W7) -> 250.36667 | Y7: =+AVERAGE($X$7:X7) -> 250.36667
A8: Feb | B8: =Feb!H$60/60 -> 0.25 | C8: =Feb!I$60/60 -> 18.266667 | D8: =Feb!J$60/60 -> 11.316667 | E8: =Feb!K$60/60 -> 0.76666667 | F8: =Feb!L$60/60 -> 0.61666667 | G8: =Feb!M$60/60 -> 1.9833333 | H8: =Feb!N$60/60 -> 6 | I8: =Feb!O$60/60 -> 32.75 | ... W8: =Feb!AC$60/60 -> 0 | X8: =SUM(B8:W8) -> 234.76667 | Y8: =+AVERAGE($X$7:X8) -> 242.56667
A9: Mar | B9: =Mar!H$62/60 -> 0.75 | C9: =Mar!I$62/60 -> 20.866667 | D9: =Mar!J$62/60 -> 7.5166667 | E9: =Mar!K$62/60 -> 3.7333333 | F9: =Mar!L$62/60 -> 0.23333333 | G9: =Mar!M$62/60 -> 1.2166667 | H9: =Mar!N$62/60 -> 1.15 | I9: =Mar!O$62/60 -> 12.9 | ... W9: =Mar!AC$62/60 -> 0 | X9: =SUM(B9:W9) -> 227.2 | Y9: =+AVERAGE($X$7:X9) -> 237.44444
A10: Apr | B10: =Apr!H$54/60 -> 0.95 | C10: =Apr!I$54/60 -> 21.883333 | D10: =Apr!J$54/60 -> 6.2 | E10: =Apr!K$54/60 -> 0.33333333 | F10: =Apr!L$54/60 -> 1.35 | G10: =Apr!M$54/60 -> 0 | H10: =Apr!N$54/60 -> 2.9166667 | I10: =Apr!O$54/60 -> 7.2666667 | ... W10: =Apr!AC$54/60 -> 0 | X10: =SUM(B10:W10) -> 208.18333 | Y10: =+AVERAGE($X$7:X10) -> 230.12917
A11: May | B11: =May!H$63/60 -> 0 | C11: =May!I$63/60 -> 22.166667 | D11: =May!J$63/60 -> 12.483333 | E11: =May!K$63/60 -> 0.05 | F11: =May!L$63/60 -> 0.91666667 | G11: =May!M$63/60 -> 0.1 | H11: =May!N$63/60 -> 0 | I11: =May!O$63/60 -> 6.9666667 | ... W11: =May!AC$63/60 -> 0 | X11: =SUM(B11:W11) -> 141.23333 | Y11: =+AVERAGE($X$7:X11) -> 212.35
A12: Jun | B12: =Jun!H$57/60 -> 0.31666667 | C12: =Jun!I$57/60 -> 9.75 | D12: =Jun!J$57/60 -> 2.6666667 | E12: =Jun!K$57/60 -> 1.15 | F12: =Jun!L$57/60 -> 1.5666667 | G12: =Jun!M$57/60 -> 0.65 | H12: =Jun!N$57/60 -> 0 | I12: =Jun!O$57/60 -> 1.4166667 | ... W12: =Jun!AC$57/60 -> 0 | X12: =SUM(B12:W12) -> 95.816667 | Y12: =+AVERAGE($X$7:X12) -> 192.92778
A13: Jul | B13: =Jul!H$61/60 -> 0.51666667 | C13: =Jul!I$61/60 -> 25.483333 | D13: =Jul!J$61/60 -> 39.35 | E13: =Jul!K$61/60 -> 0 | F13: =Jul!L$61/60 -> 3.4 | G13: =Jul!M$61/60 -> 0.96666667 | H13: =Jul!N$61/60 -> 0 | I13: =Jul!O$61/60 -> 5.4 | ... W13: =Jul!AC$61/60 -> 0.15 | X13: =SUM(B13:W13) -> 264.51667 | Y13: =+AVERAGE($X$7:X13) -> 203.15476
A14: Aug | B14: =Aug!H$68/60 -> 2.05 | C14: =Aug!I$68/60 -> 22.183333 | D14: =Aug!J$68/60 -> 6.35 | E14: =Aug!K$68/60 -> 1.9 | F14: =Aug!L$68/60 -> 1.2166667 | G14: =Aug!M$68/60 -> 0.86666667 | H14: =Aug!N$68/60 -> 0 | I14: =Aug!O$68/60 -> 6.0666667 | ... M14: =Aug!S$68/60 -> 13.216667 | N14: =Aug!T68/60 -> 19.183333 | O14: =Aug!U$68/60 -> 1.3833333 | P14: =Aug!V$68/60 -> 12.916667 | Q14: =Aug!W$68/60 -> 2.45 | R14: =Aug!X$68/60 -> 2.9666667 | S14: =Aug!Y$68/60 -> 0 | T14: =Aug!Z$68/60 -> 17.783333 | U14: =Aug!AA$68/60 -> 0.05 | V14: =Aug!AB$68/60 -> 8.7833333 | W14: =Aug!AC$68/60 -> 4.5166667 | X14: =SUM(B14:W14) -> 156.08333 | Y14: =+AVERAGE($X$7:X14) -> 197.27083
A15: Sep | B15: =Sept!H$55/60 -> 0.63333333 | C15: =Sept!I$55/60 -> 16.683333 | D15: =Sept!J$55/60 -> 18.316667 | E15: =Sept!K$55/60 -> 0.85 | F15: =Sept!L$55/60 -> 0.45 | G15: =Sept!M$55/60 -> 0 | H15: =Sept!N$55/60 -> 1.4666667 | I15: =Sept!O$55/60 -> 4.2166667 | ... W15: =Sept!AC$55/60 -> 0 | X15: =SUM(B15:W15) -> 129.63333 | Y15: =+AVERAGE($X$7:X15) -> 189.75556
A16: Oct | B16: =Oct!H$71/60 -> 0 | C16: =Oct!I$71/60 -> 0 | D16: =Oct!J$71/60 -> 0 | E16: =Oct!K$71/60 -> 0 | F16: =Oct!L$71/60 -> 0 | G16: =Oct!M$71/60 -> 0 | H16: =Oct!N$71/60 -> 0 | I16: =Oct!O$71/60 -> 0 | ... W16: =Oct!AC$71/60 -> 0 | X16: =SUM(B16:W16) -> 0.45 | Y16: =+AVERAGE($X$7:X16) -> 170.825
A17: Nov | B17: =Nov!H$70/60 -> 0 | C17: =Nov!I$70/60 -> 0 | D17: =Nov!J$70/60 -> 0 | E17: =Nov!K$70/60 -> 0 | F17: =Nov!L$70/60 -> 0 | G17: =Nov!M$70/60 -> 0 | H17: =Nov!N$70/60 -> 0 | I17: =Nov!O$70/60 -> 0 | ... W17: =Nov!AC$70/60 -> 0 | X17: =SUM(B17:W17) -> 0 | Y17: =+AVERAGE($X$7:X17) -> 155.29545
A18: Dec | B18: =Dec!H$58/60 -> 0 | C18: =Dec!I$58/60 -> 0 | D18: =Dec!J$58/60 -> 0 | E18: =Dec!K$58/60 -> 0 | F18: =Dec!L$58/60 -> 0 | G18: =Dec!M$58/60 -> 0 | H18: =Dec!N$58/60 -> 0 | I18: =Dec!O$58/60 -> 0 | ... W18: =Dec!AC$58/60 -> 0 | X18: =SUM(B18:W18) -> 0 | Y18: =+AVERAGE($X$7:X18) -> 142.35417
A19: YTD | B19: =SUM(B7:B18) -> 7.65 | C19: =SUM(C7:C18) -> 178.86667 | D19: =SUM(D7:D18) -> 113.75 | E19: =SUM(E7:E18) -> 9.0166667 | F19: =SUM(F7:F18) -> 10.016667 | G19: =SUM(G7:G18) -> 7.1333333 | H19: =SUM(H7:H18) -> 11.533333 | I19: =SUM(I7:I18) -> 86.366667 | ... X19: =SUM(X7:X18) -> 1708.25 | AA19: =SUM(AA7:AA18) -> 0
A21: YTD% | B21: =(B19/$X19) -> 0.0044782672 | C21: =(C19/$X19) -> 0.10470755 | D21: =(D19/$X19) -> 0.066588614 | E21: =(E19/$X19) -> 0.0052783063 | F21: =(F19/$X19) -> 0.0058637007 | G21: =(G19/$X19) -> 0.0041758135 | H21: =(H19/$X19) -> 0.0067515489 | I21: =(I19/$X19) -> 0.050558564 | ... W21: =(W19/$X19) -> 0.0027318406
B23: =B15/$X$15 -> 0.0048855747 | C23: =C15/$X$15 -> 0.12869632 | D23: =D15/$X$15 -> 0.14129596 | E23: =E15/$X$15 -> 0.0065569555 | F23: =F15/$X$15 -> 0.0034713294 | G23: =G15/$X$15 -> 0 | H23: =H15/$X$15 -> 0.011313962 | I23: =I15/$X$15 -> 0.032527642 | ... W23: =W15/$X$15 -> 0
A43: Notes | M43: - 1 bottling is 300 hl | AA43: -Stops in excess of 5 minutes must be recorded
AA44: -All downtimes are relative to the filler

Sheet Pareto YTD

Sheet Pareto Data
C2: January | G2: February | H2: Feb | K2: March | L2: Mar | O2: April | P2: Apr
C3: Machines | D3: Percent | E3: Cumulative Percent | G3: Machines | H3: Percent | I3: Cumulative Percent | K3: Machines | L3: Percent | M3: Cumulative Percent | O3: Machines | P3: Percent | Q3: Cumulative Percent
C4: Washer | D4: ='Monthly summary loss'!$J$7/'Monthly summary loss'!$X$7 -> 0.085341499 | E4: =SUM(D$4:D4) -> 0.085341499 | G4: Washer | H4: ='Monthly summary loss'!$J8/'Monthly summary loss'!$X$8 -> 0.26068437 | I4: =SUM(H$4:H4) -> 0.26068437 | K4: Washer | L4: ='Monthly summary loss'!$J9/'Monthly summary loss'!$X9 -> 0.3070716 | M4: =SUM(L$4:L4) -> 0.3070716 | O4: Washer | P4: ='Monthly summary loss'!$J10/'Monthly summary loss'!$X10 -> 0.14210231 | Q4: =SUM(P$4:P4) -> 0.14210231
C5: Labeller | D5: ='Monthly summary loss'!$N$7/'Monthly summary loss'!$X$7 -> 0.013580083 | E5: =SUM(D$4:D5) -> 0.098921582 | G5: Change Over | H5: ='Monthly summary loss'!$C8/'Monthly summary loss'!$X$8 -> 0.077807752 | I5: =SUM(H$4:H5) -> 0.33849212 | K5: Product Delay | L5: ='Monthly summary loss'!$D9/'Monthly summary loss'!$X$9 -> 0.03308392 | M5: =SUM(L$4:L5) -> 0.34015552 | O5: Logistics Supply (bottles, crowns) | P5: ='Monthly summary loss'!$W10/'Monthly summary loss'!$X10 -> 0 | Q5: =SUM(P$4:P5) -> 0.14210231
C6: Filler | D6: ='Monthly summary loss'!$L$7/'Monthly summary loss'!$X$7 -> 0.018439622 | E6: =SUM(D$4:D6) -> 0.1173612 | G6: Labeller | H6: ='Monthly summary loss'!$N8/'Monthly summary loss'!$X$8 -> 0.012210706 | I6: =SUM(H$4:H6) -> 0.35070283 | K6: Conveyors | L6: ='Monthly summary loss'!$P9/'Monthly summary loss'!$X9 -> 0.059932512 | M6: =SUM(L$4:L6) -> 0.40008803 | O6: Labeller | P6: ='Monthly summary loss'!$N10/'Monthly summary loss'!$X10 -> 0.043311184 | Q6: =SUM(P$4:P6) -> 0.1854135
C7: Change Over | D7: ='Monthly summary loss'!$C$7/'Monthly summary loss'!$X$7 -> 0.086206897 | E7: =SUM(D$4:D7) -> 0.2035681 | G7: Product Delay | H7: ='Monthly summary loss'!$D8/'Monthly summary loss'!$X$8 -> 0.04820389 | I7: =SUM(H$4:H7) -> 0.39890672 | K7: EBI | L7: ='Monthly summary loss'!$K9/'Monthly summary loss'!$X9 -> 0.060372653 | M7: =SUM(L$4:L7) -> 0.46046068 | O7: Other Explained | P7: ='Monthly summary loss'!$T10/'Monthly summary loss'!$X10 -> 0.091425827 | Q7: =SUM(P$4:P7) -> 0.27683932
C8: Other Explained | D8: ='Monthly summary loss'!$T$7/'Monthly summary loss'!$X$7 -> 0.17547597 | E8: =SUM(D$4:D8) -> 0.37904407 | G8: Conveyors | H8: ='Monthly summary loss'!$P8/'Monthly summary loss'!$X$8 -> 0.080789436 | I8: =SUM(H$4:H8) -> 0.47969615 | K8: Change Over | L8: ='Monthly summary loss'!$C$9/'Monthly summary loss'!$X$9 -> 0.091842723 | M8: =SUM(L$4:L8) -> 0.5523034 | O8: Change Over | P8: ='Monthly summary loss'!$C$10/'Monthly summary loss'!$X$10 -> 0.10511568 | Q8: =SUM(P$4:P8) -> 0.38195501
C9: Product Delay | D9: ='Monthly summary loss'!$D$7/'Monthly summary loss'!$X$7 -> 0.038144055 | E9: =SUM(D$4:D9) -> 0.41718812 | G9: Filler | H9: ='Monthly summary loss'!$L8/'Monthly summary loss'!$X$8 -> 0.017819111 | I9: =SUM(H$4:H9) -> 0.49751526 | K9: Labeller | L9: ='Monthly summary loss'!$N9/'Monthly summary loss'!$X9 -> 0.021713615 | M9: =SUM(L$4:L9) -> 0.57401702 | O9: Filler | P9: ='Monthly summary loss'!$L10/'Monthly summary loss'!$X10 -> 0.21087183 | Q9: =SUM(P$4:P9) -> 0.59282684
C10: Conveyors | D10: ='Monthly summary loss'!$P$7/'Monthly summary loss'!$X$7 -> 0.40454001 | E10: =SUM(D$4:D10) -> 0.82172813 | G10: Low Steam Pressure | H10: ='Monthly summary loss'!$H8/'Monthly summary loss'!$X$8 -> 0.025557291 | I10: =SUM(H$4:H10) -> 0.52307255 | K10: Filler | L10: ='Monthly summary loss'!$L9/'Monthly summary loss'!$X9 -> 0.047975352 | M10: =SUM(L$4:L10) -> 0.62199237 | O10: Low Water Pressure | P10: ='Monthly summary loss'!$G10/'Monthly summary loss'!$X10 -> 0 | Q10: =SUM(P$4:P10) -> 0.59282684
C11: EBI | D11: ='Monthly summary loss'!$K$7/'Monthly summary loss'!$X$7 -> 0.029689788 | E11: =SUM(D$4:D11) -> 0.85141792 | G11: Other Explained | H11: ='Monthly summary loss'!$T8/'Monthly summary loss'!$X$8 -> 0.11216811 | I11: =SUM(H$4:H11) -> 0.63524066 | K11: Logistics Supply (bottles, crowns) | L11: ='Monthly summary loss'!$W$9/'Monthly summary loss'!$X$9 -> 0 | M11: =SUM(L$4:L11) -> 0.62199237 | O11: EBI | P11: ='Monthly summary loss'!$K10/'Monthly summary loss'!$X10 -> 0.052757986 | Q11: =SUM(P$4:P11) -> 0.64558482
C12: Low Water Pressure | D12: ='Monthly summary loss'!$G$7/'Monthly summary loss'!$X$7 -> 0.0053920916 | E12: =SUM(D$4:D12) -> 0.85681001 | G12: Low Water Pressure | H12: ='Monthly summary loss'!$G8/'Monthly summary loss'!$X$8 -> 0.0084481045 | I12: =SUM(H$4:H12) -> 0.64368877 | K12: Other Explained | L12: ='Monthly summary loss'!$T9/'Monthly summary loss'!$X9 -> 0.13556338 | M12: =SUM(L$4:L12) -> 0.75755575 | O12: Conveyors | P12: ='Monthly summary loss'!$P10/'Monthly summary loss'!$X10 -> 0.13729886 | Q12: =SUM(P$4:P12) -> 0.78288368
C13: Packer | D13: ='Monthly summary loss'!$Q$7/'Monthly summary loss'!$X$7 -> 0.0048595393 | E13: =SUM(D$4:D13) -> 0.86166955 | G13: Logistics Supply (bottles, crowns) | H13: ='Monthly summary loss'!W8/'Monthly summary loss'!$X$8 -> 0 | I13: =SUM(H$4:H13) -> 0.64368877 | K13: Pasteuriser | L13: ='Monthly summary loss'!$M9/'Monthly summary loss'!$X9 -> 0.044160798 | M13: =SUM(L$4:L13) -> 0.80171655 | O13: Uncaser | P13: ='Monthly summary loss'!$I10/'Monthly summary loss'!$X10 -> 0.034905132 | Q13: =SUM(P$4:P13) -> 0.81778881
C14: Pasteuiser | D14: ='Monthly summary loss'!$M$7/'Monthly summary loss'!$X$7 -> 0.057582213 | E14: =SUM(D$4:D14) -> 0.91925176 | G14: Packer | H14: ='Monthly summary loss'!$Q8/'Monthly summary loss'!$X$8 -> 0.013417578 | I14: =SUM(H$4:H14) -> 0.65710635 | K14: Low Water Pressure | L14: ='Monthly summary loss'!$G9/'Monthly summary loss'!$X9 -> 0.0053550469 | M14: =SUM(L$4:L14) -> 0.8070716 | O14: Low Air Pressure | P14: ='Monthly summary loss'!$E10/'Monthly summary loss'!$X10 -> 0.0016011528 | Q14: =SUM(P$4:P14) -> 0.81938996
C15: Low Air Pressure | D15: ='Monthly summary loss'!$E$7/'Monthly summary loss'!$X$7 -> 0.00093196645 | E15: =SUM(D$4:D15) -> 0.92018373 | G15: EBI | H15: ='Monthly summary loss'!$K8/'Monthly summary loss'!$X$8 -> 0.10805055 | I15: =SUM(H$4:H15) -> 0.76515689 | K15: Uncaser | L15: ='Monthly summary loss'!$I9/'Monthly summary loss'!$X9 -> 0.056778169 | M15: =SUM(L$4:L15) -> 0.86384977 | O15: Product Delay | P15: ='Monthly summary loss'!$D10/'Monthly summary loss'!$X$10 -> 0.029781443 | Q15: =SUM(P$4:P15) -> 0.8491714
C16: VideoJet (Coder) | D16: ='Monthly summary loss'!$O$7/'Monthly summary loss'!$X$7 -> 0.0076554387 | E16: =SUM(D$4:D16) -> 0.92783917 | G16: Low Air Pressure | H16: ='Monthly summary loss'!$E8/'Monthly summary loss'!$X$8 -> 0.0032656538 | I16: =SUM(H$4:H16) -> 0.76842255 | K16: Low Steam Pressure | L16: ='Monthly summary loss'!$H9/'Monthly summary loss'!$X9 -> 0.0050616197 | M16: =SUM(L$4:L16) -> 0.86891138 | O16: Low Steam Pressure | P16: ='Monthly summary loss'!$H10/'Monthly summary loss'!$X10 -> 0.014010087 | Q16: =SUM(P$4:P16) -> 0.86318149
C17: Logistics Supply (bottles, crowns) | D17: ='Monthly summary loss'!$W$7/'Monthly summary loss'!$X$7 -> 0 | E17: =SUM(D$4:D17) -> 0.92783917 | G17: Uncaser | H17: ='Monthly summary loss'!$I$8/'Monthly summary loss'!$X$8 -> 0.13950021 | I17: =SUM(H$4:H17) -> 0.90792276 | K17: VideoJet (Coder) | L17: ='Monthly summary loss'!$O9/'Monthly summary loss'!$X9 -> 0.0043280516 | M17: =SUM(L$4:L17) -> 0.87323944 | O17: Low CO2 Pressure | P17: ='Monthly summary loss'!$F10/'Monthly summary loss'!$X10 -> 0.006484669 | Q17: =SUM(P$4:P17) -> 0.86966616
C18: Low Steam Pressure | D18: ='Monthly summary loss'!$H$7/'Monthly summary loss'!$X$7 -> 0 | E18: =SUM(D$4:D18) -> 0.92783917 | G18: VideoJet (Coder) | H18: ='Monthly summary loss'!$O$8/'Monthly summary loss'!$X$8 -> 0.0045435184 | I18: =SUM(H$4:H18) -> 0.91246628 | K18: Packer | L18: ='Monthly summary loss'!$Q9/'Monthly summary loss'!$X9 -> 0.044014085 | M18: =SUM(L$4:L18) -> 0.91725352 | O18: Operator Errors | P18: ='Monthly summary loss'!$B$10/'Monthly summary loss'!$X$10 -> 0.0045632856 | Q18: =SUM(P$4:P18) -> 0.87422945
C19: Uncaser | D19: ='Monthly summary loss'!$I$7/'Monthly summary loss'!$X$7 -> 0.037478365 | E19: =SUM(D$4:D19) -> 0.96531753 | G19: Other Unexplained | H19: ='Monthly summary loss'!$U$8/'Monthly summary loss'!$X$8 -> 0.0029106915 | I19: =SUM(H$4:H19) -> 0.91537697 | K19: Low Air Pressure | L19: ='Monthly summary loss'!$E9/'Monthly summary loss'!$X9 -> 0.016431925 | M19: =SUM(L$4:L19) -> 0.93368545 | O19: Packer | P19: ='Monthly summary loss'!$Q10/'Monthly summary loss'!$X10 -> 0.048594988 | Q19: =SUM(P$4:P19) -> 0.92282443
C20: Operator Errors | D20: ='Monthly summary loss'!$B$7/'Monthly summary loss'!$X$7 -> 0.0087205432 | E20: =SUM(D$4:D20) -> 0.97403808 | G20: Operator Errors | H20: ='Monthly summary loss'!$B$8/'Monthly summary loss'!$X$8 -> 0.0010648871 | I20: =SUM(H$4:H20) -> 0.91644186 | K20: Operator Errors | L20: ='Monthly summary loss'!$B$9/'Monthly summary loss'!$X$9 -> 0.0033010563 | M20: =SUM(L$4:L20) -> 0.9369865 | O20: VideoJet (Coder) | P20: ='Monthly summary loss'!$O10/'Monthly summary loss'!$X10 -> 0.018733488 | Q20: =SUM(P$4:P20) -> 0.94155792
C21: Low CO2 Pressure | D21: ='Monthly summary loss'!$F$7/'Monthly summary loss'!$X$7 -> 0.0010651045 | E21: =SUM(D$4:D21) -> 0.97510318 | G21: Low CO2 Pressure | H21: ='Monthly summary loss'!$F8/'Monthly summary loss'!$X$8 -> 0.0026267216 | I21: =SUM(H$4:H21) -> 0.91906858 | K21: Low CO2 Pressure | L21: ='Monthly summary loss'!$F9/'Monthly summary loss'!$X9 -> 0.0010269953 | M21: =SUM(L$4:L21) -> 0.9380135 | O21: Pasteuriser | P21: ='Monthly summary loss'!$M10/'Monthly summary loss'!$X10 -> 0.010727724 | Q21: =SUM(P$4:P21) -> 0.95228565
C22: Other Unexplained | D22: ='Monthly summary loss'!$U$7/'Monthly summary loss'!$X$7 -> 0.0033950206 | E22: =SUM(D$4:D22) -> 0.9784982 | G22: Crate Rinser | H22: ='Monthly summary loss'!$S8/'Monthly summary loss'!$X$8 -> 0.0015618344 | I22: =SUM(H$4:H22) -> 0.92063041 | K22: Other Unexplained | L22: ='Monthly summary loss'!U9/'Monthly summary loss'!X9 -> 0.0018339202 | M22: =SUM(L$4:L22) -> 0.93984742 | O22: Crate Rinser | P22: ='Monthly summary loss'!$S10/'Monthly summary loss'!$X10 -> 0 | Q22: =SUM(P$4:P22) -> 0.95228565
C23: Carton Errector | D23: ='Monthly summary loss'!$R$7/'Monthly summary loss'!$X$7 -> 0 | E23: =SUM(D$4:D23) -> 0.9784982 | G23: Pasteuiser | H23: ='Monthly summary loss'!$M8/'Monthly summary loss'!$X$8 -> 0.048558853 | I23: =SUM(H$4:H23) -> 0.96918927 | K23: Carton Errector | L23: ='Monthly summary loss'!$R9/'Monthly summary loss'!$X9 -> 0.033744131 | M23: =SUM(L$4:L23) -> 0.97359155 | O23: Other Unexplained | P23: ='Monthly summary loss'!U10/'Monthly summary loss'!X10 -> 0.00056040349 | Q23: =SUM(P$4:P23) -> 0.95284605
C24: Crate Rinser | D24: ='Monthly summary loss'!$S$7/'Monthly summary loss'!$X$7 -> 0 | E24: =SUM(D$4:D24) -> 0.9784982 | G24: Carton Errector | H24: ='Monthly summary loss'!$R8/'Monthly summary loss'!$X$8 -> 0.01405651 | I24: =SUM(H$4:H24) -> 0.98324578 | K24: Crate Rinser | L24: ='Monthly summary loss'!$S9/'Monthly summary loss'!$X9 -> 0.00080692488 | M24: =SUM(L$4:L24) -> 0.97439847 | O24: Carton Errector | P24: ='Monthly summary loss'!$R10/'Monthly summary loss'!$X$10 -> 0.028660636 | Q24: =SUM(P$4:P24) -> 0.98150668
C26: May | G26: June | K26: July | O26: August
C28: Machines | D28: Percent | E28: Cumulative Percent | G28: Machines | H28: Percent | I28: Cumulative Percent | K28: Machines | L28: Percent | M28: Cumulative Percent | O28: Machines | P28: Percent | Q28: Cumulative Percent
C29: Washer | D29: ='Monthly summary loss'!$J11/'Monthly summary loss'!$X11 -> 0.06868067 | E29: =SUM(D$29:D29) -> 0.06868067 | G29: Washer | H29: ='Monthly summary loss'!$J12/'Monthly summary loss'!$X12 -> 0.069403374 | I29: =SUM(H$29:H29) -> 0.069403374 | K29: Washer | L29: ='Monthly summary loss'!$J13/'Monthly summary loss'!$X13 -> 0.054438914 | M29: =+L29 -> 0.054438914 | O29: Filler | P29: ='Monthly summary loss'!$L$14/'Monthly summary loss'!$X$14 -> 0.07538708 | Q29: =SUM(P$29:P29) -> 0.07538708
C30: Filler | D30: ='Monthly summary loss'!$L11/'Monthly summary loss'!$X11 -> 0.10762332 | E30: =SUM(D$29:D30) -> 0.17630399 | G30: Other Explained | H30: ='Monthly summary loss'!$T12/'Monthly summary loss'!$X12 -> 0.11149765 | I30: =SUM(H$29:H30) -> 0.18090103 | K30: Other Explained | L30: ='Monthly summary loss'!$T13/'Monthly summary loss'!$X13 -> 0.23168042 | M30: =SUM(L$29:L30) -> 0.28611934 | O30: Labeller | P30: ='Monthly summary loss'!$N$14/'Monthly summary loss'!$X$14 -> 0.12290443 | Q30: =SUM(P$29:P30) -> 0.19829151
C31: Low Steam Pressure | D31: ='Monthly summary loss'!$H11/'Monthly summary loss'!$X11 -> 0 | E31: =SUM(D$29:D31) -> 0.17630399 | G31: Conveyors | H31: ='Monthly summary loss'!$P12/'Monthly summary loss'!$X12 -> 0.064880849 | I31: =SUM(H$29:H31) -> 0.24578188 | K31: Conveyors | L31: ='Monthly summary loss'!$P13/'Monthly summary loss'!$X13 -> 0.060739714 | M31: =SUM(L$29:L31) -> 0.34685905 | O31: Washer | P31: ='Monthly summary loss'!$J$14/'Monthly summary loss'!$X$14 -> 0.068766684 | Q31: =+P31 -> 0.068766684
C32: Other Explained | D32: ='Monthly summary loss'!$T11/'Monthly summary loss'!$X$11 -> 0.14078357 | E32: =SUM(D$29:D32) -> 0.31708756 | G32: Low Water Pressure | H32: ='Monthly summary loss'!$G12/'Monthly summary loss'!$X12 -> 0.0067837885 | I32: =SUM(H$29:H32) -> 0.25256566 | K32: Product Delay | L32: ='Monthly summary loss'!$D13/'Monthly summary loss'!$X$13 -> 0.14876189 | M32: =SUM(L$29:L32) -> 0.49562094 | O32: Other Explained | P32: ='Monthly summary loss'!$T$14/'Monthly summary loss'!$X$14 -> 0.11393486 | Q32: =SUM(P$29:P32) -> 0.38099306
C33: Product Delay | D33: ='Monthly summary loss'!$D11/'Monthly summary loss'!$X11 -> 0.08838801 | E33: =SUM(D$29:D33) -> 0.40547557 | G33: Filler | H33: ='Monthly summary loss'!$L12/'Monthly summary loss'!$X12 -> 0.012523917 | I33: =SUM(H$29:H33) -> 0.26508958 | K33: Change Over | L33: ='Monthly summary loss'!$C$13/'Monthly summary loss'!$X$13 -> 0.096339235 | M33: =SUM(L$29:L33) -> 0.59196018 | O33: Conveyors | P33: ='Monthly summary loss'!$P$14/'Monthly summary loss'!$X$14 -> 0.082754939 | Q33: =SUM(P$29:P33) -> 0.463748
C34: Conveyors | D34: ='Monthly summary loss'!$P11/'Monthly summary loss'!$X11 -> 0.098654709 | E34: =SUM(D$29:D34) -> 0.50413028 | G34: EBI | H34: ='Monthly summary loss'!$K12/'Monthly summary loss'!$X12 -> 0.042963994 | I34: =SUM(H$29:H34) -> 0.30805357 | K34: Low Steam Pressure | L34: ='Monthly summary loss'!$H13/'Monthly summary loss'!$X13 -> 0 | M34: =SUM(L$29:L34) -> 0.59196018 | O34: Change Over | P34: ='Monthly summary loss'!$C$14/'Monthly summary loss'!$X$14 -> 0.14212493 | Q34: =SUM(P$29:P34) -> 0.60587293
C35: EBI | D35: ='Monthly summary loss'!$K11/'Monthly summary loss'!$X11 -> 0.13865943 | E35: =SUM(D$29:D35) -> 0.64278971 | G35: Change Over | H35: ='Monthly summary loss'!$C$12/'Monthly summary loss'!$X$12 -> 0.10175683 | I35: =SUM(H$29:H35) -> 0.4098104 | K35: Filler | L35: ='Monthly summary loss'!$L13/'Monthly summary loss'!$X13 -> 0.030432865 | M35: =SUM(L$29:L35) -> 0.62239304 | O35: Uncaser | P35: ='Monthly summary loss'!$I$14/'Monthly summary loss'!$X$14 -> 0.038868126 | Q35: =SUM(P$29:P35) -> 0.64474106
C36: Uncaser | D36: ='Monthly summary loss'!$I11/'Monthly summary loss'!$X11 -> 0.049327354 | E36: =SUM(D$29:D36) -> 0.69211706 | G36: Uncaser | H36: ='Monthly summary loss'!$I12/'Monthly summary loss'!$X12 -> 0.01478518 | I36: =SUM(H$29:H36) -> 0.42459558 | K36: Labeller | L36: ='Monthly summary loss'!$N13/'Monthly summary loss'!$X13 -> 0.052233634 | M36: =SUM(L$29:L36) -> 0.67462668 | O36: EBI | P36: ='Monthly summary loss'!$K$14/'Monthly summary loss'!$X$14 -> 0.062146289 | Q36: =SUM(P$29:P36) -> 0.70688735
C37: Labeller | D37: ='Monthly summary loss'!$N11/'Monthly summary loss'!$X11 -> 0.034812367 | E37: =SUM(D$29:D37) -> 0.72692943 | G37: Product Delay | H37: ='Monthly summary loss'!$D12/'Monthly summary loss'!$X$12 -> 0.027830927 | I37: =SUM(H$29:H37) -> 0.45242651 | K37: Uncaser | L37: ='Monthly summary loss'!$I13/'Monthly summary loss'!$X13 -> 0.020414593 | M37: =SUM(L$29:L37) -> 0.69504127 | O37: Product Delay | P37: ='Monthly summary loss'!$D$14/'Monthly summary loss'!$X$14 -> 0.040683396 | Q37: =SUM(P$29:P37) -> 0.74757074
C38: Packer | D38: ='Monthly summary loss'!$Q11/'Monthly summary loss'!$X$11 -> 0.025489733 | E38: =SUM(D$29:D38) -> 0.75241916 | G38: Labeller | H38: ='Monthly summary loss'!$N12/'Monthly summary loss'!$X12 -> 0.015480953 | I38: =SUM(H$29:H38) -> 0.46790746 | K38: EBI | L38: ='Monthly summary loss'!$K13/'Monthly summary loss'!$X13 -> 0.060928738 | M38: =SUM(L$29:L38) -> 0.75597001 | O38: VideoJet (Coder) | P38: ='Monthly summary loss'!$O$14/'Monthly summary loss'!$X$14 -> 0.008862787 | Q38: =SUM(P$29:P38) -> 0.75643353
C39: Change Over | D39: ='Monthly summary loss'!$C$11/'Monthly summary loss'!$X$11 -> 0.15695067 | E39: =SUM(D$29:D39) -> 0.90936984 | G39: Low Steam Pressure | H39: ='Monthly summary loss'!$H12/'Monthly summary loss'!$X12 -> 0 | I39: =SUM(H$29:H39) -> 0.46790746 | K39: Low Water Pressure | L39: ='Monthly summary loss'!$G13/'Monthly summary loss'!$X13 -> 0.0036544641 | M39: =SUM(L$29:L39) -> 0.75962447 | O39: Low Steam Pressure | P39: ='Monthly summary loss'!$H$14/'Monthly summary loss'!$X$14 -> 0 | Q39: =SUM(P$29:P39) -> 0.75643353
C40: Low Air Pressure | D40: ='Monthly summary loss'!$E11/'Monthly summary loss'!$X11 -> 0.00035402407 | E40: =SUM(D$29:D40) -> 0.90972386 | G40: Pasteuriser | H40: ='Monthly summary loss'!$M12/'Monthly summary loss'!$X12 -> 0.46895112 | I40: =SUM(H$29:H40) -> 0.93685858 | K40: Packer | L40: ='Monthly summary loss'!$Q13/'Monthly summary loss'!$X13 -> 0.024825153 | M40: =SUM(L$29:L40) -> 0.78444963 | O40: Pasteuiser | P40: ='Monthly summary loss'!$M$14/'Monthly summary loss'!$X$14 -> 0.084676989 | Q40: =SUM(P$29:P40) -> 0.84111052
C41: VideoJet (Coder) | D41: ='Monthly summary loss'!$O11/'Monthly summary loss'!$X11 -> 0.0086145858 | E41: =SUM(D$29:D41) -> 0.91833845 | G41: Low CO2 Pressure | H41: ='Monthly summary loss'!$F12/'Monthly summary loss'!$X12 -> 0.01635067 | I41: =SUM(H$29:H41) -> 0.95320925 | K41: Pasteuiser | L41: ='Monthly summary loss'!$M13/'Monthly summary loss'!$X13 -> 0.097662403 | M41: =SUM(L$29:L41) -> 0.88211203 | O41: Low Water Pressure | P41: ='Monthly summary loss'!$G$14/'Monthly summary loss'!$X$14 -> 0.0055525894 | Q41: =SUM(P$29:P41) -> 0.84666311
C42: Low Water Pressure | D42: ='Monthly summary loss'!$G11/'Monthly summary loss'!$X11 -> 0.00070804815 | E42: =SUM(D$29:D42) -> 0.9190465 | G42: VideoJet (Coder) | H42: ='Monthly summary loss'!$O12/'Monthly summary loss'!$X12 -> 0.018264046 | I42: =SUM(H$29:H42) -> 0.9714733 | K42: VideoJet (Coder) | L42: ='Monthly summary loss'!$O13/'Monthly summary loss'!$X13 -> 0.038371873 | M42: =SUM(L$29:L42) -> 0.9204839 | O42: Packer | P42: ='Monthly summary loss'!$Q$14/'Monthly summary loss'!$X$14 -> 0.015696743 | Q42: =SUM(P$29:P42) -> 0.86235985
C43: Operator Errors | D43: ='Monthly summary loss'!$B$11/'Monthly summary loss'!$X$11 -> 0 | E43: =SUM(D$29:D43) -> 0.9190465 | G43: Low Air Pressure | H43: ='Monthly summary loss'!$E12/'Monthly summary loss'!$X12 -> 0.012002087 | I43: =SUM(H$29:H43) -> 0.98347539 | K43: Low CO2 Pressure | L43: ='Monthly summary loss'!$F13/'Monthly summary loss'!$X13 -> 0.012853632 | M43: =SUM(L$29:L43) -> 0.93333753 | O43: Low Air Pressure | P43: ='Monthly summary loss'!$E$14/'Monthly summary loss'!$X$14 -> 0.012172985 | Q43: =SUM(P$29:P43) -> 0.87453284
...

Sheet Pareto analysis month 

Sheet Uncaser Downtime Detail 
A4: Date | B4: Crate Stopper | C4: Infeed Belt | D4: Discharge line (Motor) | E4: Infeed line (Motor) | F4: Plunger | G4: Start/ Stop | H4: Restart | I4: Interface Screen | J4: Lockout (marching crates) | K4: Head (hitting crates) / (Damaged crates) | L4: Rebounding crates | M4: Emergency stop Button | N4: Programming Issues | O4: Fingers (hitting crates) | P4: Head Malfunction | Q4: Sprocket | R4: Spacer | S4: Suction cups | T4: Sensor Malfunction | U4: Case Guiding rail | V4: Reflectors | W4: Tensioner | X4: Transport belt | Y4: Low air pressure (Pressure switch adjustment) | Z4: piston (air leak on on second base) | AA4: Centering device | AB4: Centering Cup | AC4: Air Regulator | AD4: Electrical issues | AE4: Head Adjustments& Misalignment | AF4: Drive Belt
A6: 2026
A7: ='Conveyor Downtime (new)'!A6 -> 46024 | AG7: =SUM(B7:AF7) -> 0 | AH7: =AG7/$AG$68 -> 0
A8: ='Conveyor Downtime (new)'!A7 -> 46027 | AG8: =SUM(B8:AF8) -> 0 | AH8: =AG8/$AG$68 -> 0
A9: ='Conveyor Downtime (new)'!A8 -> 46028 | AG9: =SUM(B9:AF9) -> 0 | AH9: =AG9/$AG$68 -> 0
A10: ='Conveyor Downtime (new)'!A9 -> 46029 | AG10: =SUM(B10:AF10) -> 0 | AH10: =AG10/$AG$68 -> 0
A11: ='Conveyor Downtime (new)'!A10 -> 46030 | AG11: =SUM(B11:AF11) -> 0 | AH11: =AG11/$AG$68 -> 0
A12: ='Conveyor Downtime (new)'!A11 -> 46031 | AG12: =SUM(B12:AF12) -> 0 | AH12: =AG12/$AG$68 -> 0
A13: ='Conveyor Downtime (new)'!A12 -> 46031 | K13: 5 | AF13: =4 -> 4 | AG13: =SUM(B13:AF13) -> 9 | AH13: =AG13/$AG$68 -> 0.01598579
A14: ='Conveyor Downtime (new)'!A13 -> 46032 | AG14: =SUM(B14:AF14) -> 0 | AH14: =AG14/$AG$68 -> 0
A15: ='Conveyor Downtime (new)'!A14 -> 46034 | K15: =8+3+6 -> 17 | S15: =7+3 -> 10 | AG15: =SUM(B15:AF15) -> 27 | AH15: =AG15/$AG$68 -> 0.047957371
A16: ='Conveyor Downtime (new)'!A15 -> 46034 | AD16: =5+29 -> 34 | AG16: =SUM(B16:AF16) -> 34 | AH16: =AG16/$AG$68 -> 0.060390764
A17: ='Conveyor Downtime (new)'!A16 -> 46034 | AG17: =SUM(B17:AF17) -> 0 | AH17: =AG17/$AG$68 -> 0
A18: ='Conveyor Downtime (new)'!A17 -> 46035 | K18: =2+3 -> 5 | S18: =6+3+3 -> 12 | AG18: =SUM(B18:AF18) -> 17 | AH18: =AG18/$AG$68 -> 0.030195382
A19: ='Conveyor Downtime (new)'!A18 -> 46035 | K19: =2 -> 2 | AG19: =SUM(B19:AF19) -> 2 | AH19: =AG19/$AG$68 -> 0.0035523979
A20: ='Conveyor Downtime (new)'!A19 -> 46036 | AG20: =SUM(B20:AF20) -> 0 | AH20: =AG20/$AG$68 -> 0
A21: ='Conveyor Downtime (new)'!A20 -> 46036 | K21: =3+5 -> 8 | T21: =24 -> 24 | AG21: =SUM(B21:AF21) -> 32 | AH21: =AG21/$AG$68 -> 0.056838366
A22: ='Conveyor Downtime (new)'!A21 -> 46037 | AG22: =SUM(B22:AF22) -> 0 | AH22: =AG22/$AG$68 -> 0
A23: ='Conveyor Downtime (new)'!A22 -> 46037 | AG23: =SUM(B23:AF23) -> 0 | AH23: =AG23/$AG$68 -> 0
A24: ='Conveyor Downtime (new)'!A23 -> 46038 | T24: =2 -> 2 | AB24: =6 -> 6 | AG24: =SUM(B24:AF24) -> 8 | AH24: =AG24/$AG$68 -> 0.014209591
A25: ='Conveyor Downtime (new)'!A24 -> 46038 | P25: =12 -> 12 | AG25: =SUM(B25:AF25) -> 12 | AH25: =AG25/$AG$68 -> 0.021314387
A26: ='Conveyor Downtime (new)'!A25 -> 46041 | H26: =5+7 -> 12 | AD26: 37 | AG26: =SUM(B26:AF26) -> 49 | AH26: =AG26/$AG$68 -> 0.087033748
A27: ='Conveyor Downtime (new)'!A26 -> 46041 | K27: =2 -> 2 | AG27: =SUM(B27:AF27) -> 2 | AH27: =AG27/$AG$68 -> 0.0035523979
A28: ='Conveyor Downtime (new)'!A27 -> 46042 | K28: =4 -> 4 | AG28: =SUM(B28:AF28) -> 4 | AH28: =AG28/$AG$68 -> 0.0071047957
A29: ='Conveyor Downtime (new)'!A28 -> 46042 | D29: =2 -> 2 | AG29: =SUM(B29:AF29) -> 2 | AH29: =AG29/$AG$68 -> 0.0035523979
A30: ='Conveyor Downtime (new)'!A29 -> 46043 | AG30: =SUM(B30:AF30) -> 0 | AH30: =AG30/$AG$68 -> 0
A31: ='Conveyor Downtime (new)'!A30 -> 46043 | P31: =4+2+8+3 -> 17 | T31: =25+60+60+30 -> 175 | AE31: =2+1+1+8 -> 12 | AG31: =SUM(B31:AF31) -> 204 | AH31: =AG31/$AG$68 -> 0.36234458
A32: ='Conveyor Downtime (new)'!A31 -> 46043 | K32: =3 -> 3 | AE32: 5 | AG32: =SUM(B32:AF32) -> 8 | AH32: =AG32/$AG$68 -> 0.014209591
A33: ='Conveyor Downtime (new)'!A32 -> 46043 | AG33: =SUM(B33:AF33) -> 0 | AH33: =AG33/$AG$68 -> 0
A34: ='Conveyor Downtime (new)'!A33 -> 46044 | AG34: =SUM(B34:AF34) -> 0 | AH34: =AG34/$AG$68 -> 0
A35: ='Conveyor Downtime (new)'!A34 -> 46045 | AG35: =SUM(B35:AF35) -> 0 | AH35: =AG35/$AG$68 -> 0
A36: ='Conveyor Downtime (new)'!A35 -> 46045 | K36: =2 -> 2 | AG36: =SUM(B36:AF36) -> 2 | AH36: =AG36/$AG$68 -> 0.0035523979
A37: ='Conveyor Downtime (new)'!A36 -> 46045 | K37: =3 -> 3 | AE37: 2 | AG37: =SUM(B37:AF37) -> 5 | AH37: =AG37/$AG$68 -> 0.0088809947
A38: ='Conveyor Downtime (new)'!A37 -> 46045 | AG38: =SUM(B38:AF38) -> 0 | AH38: =AG38/$AG$68 -> 0
A39: ='Conveyor Downtime (new)'!A38 -> 46048 | AG39: =SUM(B39:AF39) -> 0 | AH39: =AG39/$AG$68 -> 0
A40: ='Conveyor Downtime (new)'!A39 -> 46048 | K40: =3+2+5 -> 10 | T40: =4 -> 4 | AG40: =SUM(B40:AF40) -> 14 | AH40: =AG40/$AG$68 -> 0.024866785
A41: ='Conveyor Downtime (new)'!A40 -> 46049 | K41: =3+2+2+3+2+2+2+3+4 -> 23 | S41: =7 -> 7 | AG41: =SUM(B41:AF41) -> 30 | AH41: =AG41/$AG$68 -> 0.053285968
A42: ='Conveyor Downtime (new)'!A41 -> 46049 | K42: =10 -> 10 | AG42: =SUM(B42:AF42) -> 10 | AH42: =AG42/$AG$68 -> 0.017761989
A43: ='Conveyor Downtime (new)'!A42 -> 46050 | K43: =3+3+7+4 -> 17 | AG43: =SUM(B43:AF43) -> 17 | AH43: =AG43/$AG$68 -> 0.030195382
A44: ='Conveyor Downtime (new)'!A43 -> 46050 | K44: =9+11+6+5 -> 31 | AG44: =SUM(B44:AF44) -> 31 | AH44: =AG44/$AG$68 -> 0.055062167
...

Sheet Washer Downtime Detail
B3: Washer Downtime Issues
A4: Date | B4: Cam | C4: VLT | D4: Kidney | E4: Pockets | F4: New Washer Com. | G4: Washer load table area. | H4: In-feed (bottle jam/ bend) | I4: Discharge Flap (bottle jam/ bend) | J4: Discharge Clutch | K4: Discharge Chain Drive | L4: Arm | M4: Cups | N4: In-feed Clutch | O4: Main Drive Motor | P4: Filter/Strainer | Q4: Partitions | R4: In-feed/ discharge re-timing | S4: Label Extractor | T4: Infeed Guide | U4: Discharge Guides | V4: Tensioner/Plate/Sprockets | W4: Discharge Guide (Knock out Bar) | X4: Bottles (Discharge) | Y4: Washer infeed sensor | Z4: Washer discharge sensor | AA4: Gear Box | AB4: Infeed Carriers | AC4: Start Up issues | AD4: Caustic Hose | AE4: Tank 5 (Rinse) | AF4: Tank 4 | AG4: Breaker | AH4: Washer Panel/Display | AI4: Start/Stop Switch | AJ4: Washer Infeed (Finger) | AK4: Rinse Jet | AL4: Broken Starwheel chain | AM4: Final Rinse sensor | AN4: Rollers | AO4: Rinse Water Pump | AP4: Electrical | AQ4: Low Temp | AR4: Steam Leak | AS4: Caustic Carry-Over | AT4: Caustic Pump | AU4: Pump 1, 2,3 | AV4: Caustic Check | AW4: Tank #6 | AX4: Water Line | AY4: drain pipe | AZ4: Late Chemical Addition | BA4: Methylene Blue | BB4: Tank #1& 2 | BC4: Tank #3 | BD4: Label Basket | BE4: Carriers | BF4: High Rejection (labels,glue) | BG4: Jet Adjustments/ clean
A6: 2026
A8: ='Conveyor Downtime (new)'!A6 -> 46024 | H8: =6+10+5+3+3+3+5+7+3+3+5+6+3 -> 62 | I8: =2+3+6 -> 11 | AQ8: =60 -> 60 | BF8: 3 | BH8: =SUM(B8:BG8) -> 136 | BI8: =BH8/$BH$66 -> 0.10608424
A9: ='Conveyor Downtime (new)'!A7 -> 46027 | BH9: =SUM(B9:BG9) -> 0 | BI9: =BH9/$BH$66 -> 0
A10: ='Conveyor Downtime (new)'!A8 -> 46028 | BH10: =SUM(B10:BG10) -> 0 | BI10: =BH10/$BH$66 -> 0
A11: ='Conveyor Downtime (new)'!A9 -> 46029 | BH11: =SUM(B11:BG11) -> 0 | BI11: =BH11/$BH$66 -> 0
A12: ='Conveyor Downtime (new)'!A10 -> 46030 | H12: =3+4+2 -> 9 | I12: =11+4 -> 15 | BH12: =SUM(B12:BG12) -> 24 | BI12: =BH12/$BH$66 -> 0.018720749
A13: ='Conveyor Downtime (new)'!A11 -> 46031 | H13: =4 -> 4 | BF13: =4 -> 4 | BH13: =SUM(B13:BG13) -> 8 | BI13: =BH13/$BH$66 -> 0.0062402496
A14: ='Conveyor Downtime (new)'!A12 -> 46031 | H14: =6 -> 6 | I14: =2 -> 2 | BH14: =SUM(B14:BG14) -> 8 | BI14: =BH14/$BH$66 -> 0.0062402496
A15: ='Conveyor Downtime (new)'!A13 -> 46032 | I15: =5+6+4+4 -> 19 | BF15: =4 -> 4 | BH15: =SUM(B15:BG15) -> 23 | BI15: =BH15/$BH$66 -> 0.017940718
A16: ='Conveyor Downtime (new)'!A14 -> 46034 | H16: =5 -> 5 | BF16: =2+3+2+3+4+4+2 -> 20 | BH16: =SUM(B16:BG16) -> 25 | BI16: =BH16/$BH$66 -> 0.01950078
A17: ='Conveyor Downtime (new)'!A15 -> 46034 | H17: =5+6+7+4 -> 22 | I17: =4 -> 4 | BH17: =SUM(B17:BG17) -> 26 | BI17: =BH17/$BH$66 -> 0.020280811
A18: ='Conveyor Downtime (new)'!A16 -> 46034 | H18: =11 -> 11 | BH18: =SUM(B18:BG18) -> 11 | BI18: =BH18/$BH$66 -> 0.0085803432
A19: ='Conveyor Downtime (new)'!A17 -> 46035 | H19: =3+6+5+5 -> 19 | I19: =5+6+7 -> 18 | BF19: =4+3+2+3+3+2+2+2+2+2 -> 25 | BH19: =SUM(B19:BG19) -> 62 | BI19: =BH19/$BH$66 -> 0.048361934
A20: ='Conveyor Downtime (new)'!A18 -> 46035 | H20: =5+1 -> 6 | I20: =4+4 -> 8 | BF20: =4 -> 4 | BH20: =SUM(B20:BG20) -> 18 | BI20: =BH20/$BH$66 -> 0.014040562
A21: ='Conveyor Downtime (new)'!A19 -> 46036 | I21: =9+4 -> 13 | BH21: =SUM(B21:BG21) -> 13 | BI21: =BH21/$BH$66 -> 0.010140406
A22: ='Conveyor Downtime (new)'!A20 -> 46036 | H22: =3+5 -> 8 | I22: =5+3+5+6+6+4 -> 29 | BF22: =2+5+3+1+3+3+2+3+7 -> 29 | BH22: =SUM(B22:BG22) -> 66 | BI22: =BH22/$BH$66 -> 0.051482059
A23: ='Conveyor Downtime (new)'!A21 -> 46037 | H23: =5+5+11+5+2+2+6+6+6+2+5+5 -> 60 | I23: =3+2+3+4+6 -> 18 | BF23: =5+9+3+4+3+4+2+2+5 -> 37 | BH23: =SUM(B23:BF23) -> 115 | BI23: =BH23/$BH$66 -> 0.089703588
A24: ='Conveyor Downtime (new)'!A22 -> 46037 | H24: =4 -> 4 | I24: =5 -> 5 | BF24: =7+4+5+14+6+5 -> 41 | BH24: =SUM(B24:BG24) -> 50 | BI24: =BH24/$BH$66 -> 0.03900156
A25: ='Conveyor Downtime (new)'!A23 -> 46038 | H25: =4 -> 4 | I25: =2 -> 2 | BH25: =SUM(B25:BG25) -> 6 | BI25: =BH25/$BH$66 -> 0.0046801872
A26: ='Conveyor Downtime (new)'!A24 -> 46038 | H26: =3+3+4+5+6+6+4+5 -> 36 | I26: =2+2+3+4+6+4+5 -> 26 | BG26: =10+26 -> 36 | BH26: =SUM(B26:BG26) -> 98 | BI26: =BH26/$BH$66 -> 0.076443058
A27: ='Conveyor Downtime (new)'!A25 -> 46041 | H27: =5+4+5+5+3+2+2 -> 26 | I27: =3+4+16+5 -> 28 | BF27: =3 -> 3 | BH27: =SUM(B27:BG27) -> 57 | BI27: =BH27/$BH$66 -> 0.044461778
A28: ='Conveyor Downtime (new)'!A26 -> 46041 | G28: =5 -> 5 | H28: =23+2+2+2+8 -> 37 | BH28: =SUM(B28:BG28) -> 42 | BI28: =BH28/$BH$66 -> 0.03276131
A29: ='Conveyor Downtime (new)'!A27 -> 46042 | H29: =1 -> 1 | I29: =5 -> 5 | BH29: =SUM(B29:BG29) -> 6 | BI29: =BH29/$BH$66 -> 0.0046801872
A30: ='Conveyor Downtime (new)'!A28 -> 46042 | H30: =6+6+5+5+5+5 -> 32 | I30: =7 -> 7 | BH30: =SUM(B30:BG30) -> 39 | BI30: =BH30/$BH$66 -> 0.030421217
A31: ='Conveyor Downtime (new)'!A29 -> 46043 | I31: =4 -> 4 | BH31: =SUM(B31:BG31) -> 4 | BI31: =BH31/$BH$66 -> 0.0031201248
A32: ='Conveyor Downtime (new)'!A30 -> 46043 | H32: =1+1 -> 2 | BH32: =SUM(B32:BG32) -> 2 | BI32: =BH32/$BH$66 -> 0.0015600624
A33: ='Conveyor Downtime (new)'!A31 -> 46043 | H33: =4+2+4+2 -> 12 | BH33: =SUM(B33:BG33) -> 12 | BI33: =BH33/$BH$66 -> 0.0093603744
A34: ='Conveyor Downtime (new)'!A32 -> 46043 | BH34: =SUM(B34:BG34) -> 0 | BI34: =BH34/$BH$66 -> 0
A35: ='Conveyor Downtime (new)'!A33 -> 46044 | BH35: =SUM(B35:BG35) -> 0 | BI35: =BH35/$BH$66 -> 0
A36: ='Conveyor Downtime (new)'!A34 -> 46045 | BH36: =SUM(B36:BG36) -> 0 | BI36: =BH36/$BH$66 -> 0
A37: ='Conveyor Downtime (new)'!A35 -> 46045 | H37: =1+1+6+2 -> 10 | I37: =3+7 -> 10 | BE37: 25 | BF37: 2 | BH37: =SUM(B37:BG37) -> 47 | BI37: =BH37/$BH$66 -> 0.036661466
A38: ='Conveyor Downtime (new)'!A36 -> 46045 | H38: 7 | BH38: =SUM(B38:BG38) -> 7 | BI38: =BH38/$BH$66 -> 0.0054602184
A39: ='Conveyor Downtime (new)'!A37 -> 46045 | BH39: =SUM(B39:BG39) -> 0 | BI39: =BH39/$BH$66 -> 0
A40: ='Conveyor Downtime (new)'!A38 -> 46048 | BH40: =SUM(B40:BG40) -> 0 | BI40: =BH40/$BH$66 -> 0
A41: ='Conveyor Downtime (new)'!A39 -> 46048 | I41: =2+6 -> 8 | AS41: =15-18+60+55 -> 112 | BH41: =SUM(B41:BG41) -> 120 | BI41: =BH41/$BH$66 -> 0.093603744
A42: ='Conveyor Downtime (new)'!A40 -> 46049 | H42: =3+3+2+3+3+17+4+5+4+2+3+3 -> 52 | I42: =2+5+3+5+3+6 -> 24 | BF42: =4+4 -> 8 | BH42: =SUM(B42:BG42) -> 84 | BI42: =BH42/$BH$66 -> 0.065522621
A43: ='Conveyor Downtime (new)'!A41 -> 46049 | H43: =3 -> 3 | BH43: =SUM(B43:BG43) -> 3 | BI43: =BH43/$BH$66 -> 0.0023400936
A44: ='Conveyor Downtime (new)'!A42 -> 46050 | BF44: =7 -> 7 | BH44: =SUM(B44:BG44) -> 7 | BI44: =BH44/$BH$66 -> 0.0054602184
...

Sheet EBI Downtime Detail
B3: EBI Downtime Issues
A4: Date | B4: Programming | C4: Software Malfunction (Reboot) | D4: EBI Screen | E4: Shaft | F4: Down/up Bottle Sensor | G4: Sonic gap detection | H4: Neck Finish Adjustments | I4: Base Camera | J4: Height Adjustment | K4: EBI Rejection table | L4: Servo Controller | M4: EBI Infeed fault | N4: Parameter Fault/Adjustment | O4: High Rejection | P4: False Rejection | Q4: Belt | R4: Safety Door | S4: EBI Speed | T4: Alignment Issues | U4: Fallen/ jam bottles EBI Starwheel | V4: Trouble shooting | W4: Vacuum Pressure | X4: OSW glass | Y4: Fallen/ jam bottles OSW | Z4: Rail Adjustments | AA4: Stuck Labels | AB4: LCM | AC4: Base Inspector | AD4: EBI Base Camera | AE4: Test bottles failure | AF4: Bolt | AG4: Cleaning | AH4: Faulty bottles passing EBI
A5: 2026
A6: ='Conveyor Downtime (new)'!A6 -> 46024 | O6: =6+5 -> 11 | AI6: =SUM(B6:AH6) -> 11 | AJ6: =AI6/$AI$67 -> 0.024663677
A7: ='Conveyor Downtime (new)'!A7 -> 46027 | AI7: =SUM(B7:AH7) -> 0 | AJ7: =AI7/$AI$67 -> 0
A8: ='Conveyor Downtime (new)'!A8 -> 46028 | AI8: =SUM(B8:AH8) -> 0 | AJ8: =AI8/$AI$67 -> 0
A9: ='Conveyor Downtime (new)'!A9 -> 46029 | AI9: =SUM(B9:AH9) -> 0 | AJ9: =AI9/$AI$67 -> 0
A10: ='Conveyor Downtime (new)'!A10 -> 46030 | O10: =2+10 -> 12 | AI10: =SUM(B10:AH10) -> 12 | AJ10: =AI10/$AI$67 -> 0.02690583
A11: ='Conveyor Downtime (new)'!A11 -> 46031 | N11: =37+10 -> 47 | O11: 2 | U11: =2+2+2 -> 6 | Y11: =2+2 -> 4 | AI11: =SUM(B11:AH11) -> 59 | AJ11: =AI11/$AI$67 -> 0.132287
A12: ='Conveyor Downtime (new)'!A12 -> 46031 | AI12: =SUM(B12:AH12) -> 0 | AJ12: =AI12/$AI$67 -> 0
A13: ='Conveyor Downtime (new)'!A13 -> 46032 | N13: =6+5+6 -> 17 | U13: =2 -> 2 | Y13: =2 -> 2 | AI13: =SUM(B13:AH13) -> 21 | AJ13: =AI13/$AI$67 -> 0.047085202
A14: ='Conveyor Downtime (new)'!A14 -> 46034 | O14: =5+4 -> 9 | AI14: =SUM(B14:AH14) -> 9 | AJ14: =AI14/$AI$67 -> 0.020179372
A15: ='Conveyor Downtime (new)'!A15 -> 46034 | AI15: =SUM(B15:AH15) -> 0 | AJ15: =AI15/$AI$67 -> 0
A16: ='Conveyor Downtime (new)'!A16 -> 46034 | AI16: =SUM(B16:AH16) -> 0 | AJ16: =AI16/$AI$67 -> 0
A17: ='Conveyor Downtime (new)'!A17 -> 46035 | I17: =1 -> 1 | Y17: =2 -> 2 | AI17: =SUM(B17:AH17) -> 3 | AJ17: =AI17/$AI$67 -> 0.0067264574
A18: ='Conveyor Downtime (new)'!A18 -> 46035 | Y18: =2+2+3 -> 7 | AI18: =SUM(B18:AH18) -> 7 | AJ18: =AI18/$AI$67 -> 0.015695067
A19: ='Conveyor Downtime (new)'!A19 -> 46036 | AI19: =SUM(B19:AH19) -> 0 | AJ19: =AI19/$AI$67 -> 0
A20: ='Conveyor Downtime (new)'!A20 -> 46036 | O20: =3+9 -> 12 | Y20: =1+2+2 -> 5 | AI20: =SUM(B20:AH20) -> 17 | AJ20: =AI20/$AI$67 -> 0.038116592
A21: ='Conveyor Downtime (new)'!A21 -> 46037 | O21: =8+2 -> 10 | Y21: =4+3+4+3+3+4+2+3 -> 26 | AI21: =SUM(B21:AH21) -> 36 | AJ21: =AI21/$AI$67 -> 0.080717489
A22: ='Conveyor Downtime (new)'!A22 -> 46037 | Y22: =2 -> 2 | AI22: =SUM(B22:AH22) -> 2 | AJ22: =AI22/$AI$67 -> 0.0044843049
A23: ='Conveyor Downtime (new)'!A23 -> 46038 | O23: =6+9 -> 15 | U23: =2+2 -> 4 | AI23: =SUM(B23:AH23) -> 19 | AJ23: =AI23/$AI$67 -> 0.042600897
A24: ='Conveyor Downtime (new)'!A24 -> 46038 | O24: =3+4 -> 7 | U24: =2 -> 2 | Y24: =3+2+2+2+3 -> 12 | AI24: =SUM(B24:AH24) -> 21 | AJ24: =AI24/$AI$67 -> 0.047085202
A25: ='Conveyor Downtime (new)'!A25 -> 46041 | O25: =3+1+1 -> 5 | P25: 3 | U25: =3+2 -> 5 | Y25: =2+2 -> 4 | AA25: 2 | AI25: =SUM(B25:AH25) -> 19 | AJ25: =AI25/$AI$67 -> 0.042600897
A26: ='Conveyor Downtime (new)'!A26 -> 46041 | Y26: =2 -> 2 | AI26: =SUM(B26:AH26) -> 2 | AJ26: =AI26/$AI$67 -> 0.0044843049
A27: ='Conveyor Downtime (new)'!A27 -> 46042 | O27: =1+1+1+1+1+2+1+1 -> 9 | U27: =2 -> 2 | AI27: =SUM(B27:AH27) -> 11 | AJ27: =AI27/$AI$67 -> 0.024663677
A28: ='Conveyor Downtime (new)'!A28 -> 46042 | N28: =5 -> 5 | O28: =6 -> 6 | U28: =4+1+2+1+2+1+2+2+2 -> 17 | AI28: =SUM(B28:AH28) -> 28 | AJ28: =AI28/$AI$67 -> 0.062780269
A29: ='Conveyor Downtime (new)'!A29 -> 46043 | AI29: =SUM(B29:AH29) -> 0 | AJ29: =AI29/$AI$67 -> 0
A30: ='Conveyor Downtime (new)'!A30 -> 46043 | O30: =2+2+2 -> 6 | AI30: =SUM(B30:AH30) -> 6 | AJ30: =AI30/$AI$67 -> 0.013452915
A31: ='Conveyor Downtime (new)'!A31 -> 46043 | N31: =4 -> 4 | U31: =2+2 -> 4 | AI31: =SUM(B31:AH31) -> 8 | AJ31: =AI31/$AI$67 -> 0.01793722
A32: ='Conveyor Downtime (new)'!A32 -> 46043 | AI32: =SUM(B32:AH32) -> 0 | AJ32: =AI32/$AI$67 -> 0
A33: ='Conveyor Downtime (new)'!A33 -> 46044 | AI33: =SUM(B33:AH33) -> 0 | AJ33: =AI33/$AI$67 -> 0
A34: ='Conveyor Downtime (new)'!A34 -> 46045 | AI34: =SUM(B34:AH34) -> 0 | AJ34: =AI34/$AI$67 -> 0
A35: ='Conveyor Downtime (new)'!A35 -> 46045 | O35: =1+9+4+2+8+2 -> 26 | U35: =2 -> 2 | AI35: =SUM(B35:AH35) -> 28 | AJ35: =AI35/$AI$67 -> 0.062780269
A36: ='Conveyor Downtime (new)'!A36 -> 46045 | U36: 3 | AI36: =SUM(B36:AH36) -> 3 | AJ36: =AI36/$AI$67 -> 0.0067264574
A37: ='Conveyor Downtime (new)'!A37 -> 46045 | AI37: =SUM(B37:AH37) -> 0 | AJ37: =AI37/$AI$67 -> 0
A38: ='Conveyor Downtime (new)'!A38 -> 46048 | U38: =2 -> 2 | AI38: =SUM(B38:AH38) -> 2 | AJ38: =AI38/$AI$67 -> 0.0044843049
A39: ='Conveyor Downtime (new)'!A39 -> 46048 | AI39: =SUM(B39:AH39) -> 0 | AJ39: =AI39/$AI$67 -> 0
A40: ='Conveyor Downtime (new)'!A40 -> 46049 | U40: =1+1+2 -> 4 | Y40: =2 -> 2 | AI40: =SUM(B40:AH40) -> 6 | AJ40: =AI40/$AI$67 -> 0.013452915
A41: ='Conveyor Downtime (new)'!A41 -> 46049 | AI41: =SUM(B41:AH41) -> 0 | AJ41: =AI41/$AI$67 -> 0
A42: ='Conveyor Downtime (new)'!A42 -> 46050 | Y42: =2+2 -> 4 | AI42: =SUM(B42:AH42) -> 4 | AJ42: =AI42/$AI$67 -> 0.0089686099
...

Sheet Filler Downtime Detail
B2: Filler Downtime Issues
A3: Date | B3: Stuck Crowns (Chute/Hopper) | C3: Transfer plate | D3: Hopper Plate closed in | E3: VFD | F3: Crowner Flush | G3: Air Dryer Fault | H3: Fobber | I3: Crown conveyor) Transport Belt | J3: Nipples | K3: Crowner Sorter | L3: Bottle stop | M3: Bottle burst | N3: Start Up Adj. | O3: Low Air | P3: Fill Volume | Q3: Plunger for bottle type | R3: Bottle Pads | S3: Software/ Electrical issue | T3: Cleaning/Adjustments | U3: Starwheel (bottle jam) | V3: Filling Valves (Actuated Diaphragm) | W3: Filling tubes / Centering cups | X3: CO2 Valve | Y3: Sensor Malfunction/ Cleaning | Z3: Communication Fault (Unit) | AA3: Centering bell | AB3: Crown chute screw adjustment | AC3: Crowner adjustments | AD3: Gas Needle | AE3: Leg | AF3: Height Adjustment | AG3: Crimp Test (Adjustment) | AH3: CIP Plant | AI3: Vacuum pump | AJ3: Filler Infeed
A4: 2026
A5: ='Conveyor Downtime (new)'!A6 -> 46024 | G5: =2 -> 2 | Y5: =32 -> 32 | AK5: =SUM(B5:AJ5) -> 34 | AL5: =AK5/$AK$62 -> 0.12274368
A6: ='Conveyor Downtime (new)'!A7 -> 46027 | AK6: =SUM(B6:AJ6) -> 0 | AL6: =AK6/$AK$62 -> 0
A7: ='Conveyor Downtime (new)'!A8 -> 46028 | AK7: =SUM(B7:AJ7) -> 0 | AL7: =AK7/$AK$62 -> 0
A8: ='Conveyor Downtime (new)'!A9 -> 46029 | AK8: =SUM(B8:AJ8) -> 0 | AL8: =AK8/$AK$62 -> 0
A9: ='Conveyor Downtime (new)'!A10 -> 46030 | F9: =1 -> 1 | AK9: =SUM(B9:AJ9) -> 1 | AL9: =AK9/$AK$62 -> 0.0036101083
A10: ='Conveyor Downtime (new)'!A11 -> 46031 | F10: =1 -> 1 | AK10: =SUM(B10:AJ10) -> 1 | AL10: =AK10/$AK$62 -> 0.0036101083
A11: ='Conveyor Downtime (new)'!A12 -> 46031 | AK11: =SUM(B11:AJ11) -> 0 | AL11: =AK11/$AK$62 -> 0
A12: ='Conveyor Downtime (new)'!A13 -> 46032 | B12: =4 -> 4 | F12: =1 -> 1 | AE12: =9 -> 9 | AK12: =SUM(B12:AJ12) -> 14 | AL12: =AK12/$AK$62 -> 0.050541516
A13: ='Conveyor Downtime (new)'!A14 -> 46034 | F13: =1 -> 1 | W13: =4 -> 4 | AF13: =3 -> 3 | AK13: =SUM(B13:AJ13) -> 8 | AL13: =AK13/$AK$62 -> 0.028880866
A14: ='Conveyor Downtime (new)'!A15 -> 46034 | F14: =1 -> 1 | AK14: =SUM(B14:AJ14) -> 1 | AL14: =AK14/$AK$62 -> 0.0036101083
A15: ='Conveyor Downtime (new)'!A16 -> 46034 | AK15: =SUM(B15:AJ15) -> 0 | AL15: =AK15/$AK$62 -> 0
A16: ='Conveyor Downtime (new)'!A17 -> 46035 | F16: =1+1+1 -> 3 | O16: =4 -> 4 | Z16: =15 -> 15 | AK16: =SUM(B16:AJ16) -> 22 | AL16: =AK16/$AK$62 -> 0.079422383
A17: ='Conveyor Downtime (new)'!A18 -> 46035 | F17: =1+1 -> 2 | AK17: =SUM(B17:AJ17) -> 2 | AL17: =AK17/$AK$62 -> 0.0072202166
A18: ='Conveyor Downtime (new)'!A19 -> 46036 | F18: =1+1 -> 2 | P18: 4 | AK18: =SUM(B18:AJ18) -> 6 | AL18: =AK18/$AK$62 -> 0.02166065
A19: ='Conveyor Downtime (new)'!A20 -> 46036 | B19: =10 -> 10 | F19: =1+1+1 -> 3 | AK19: =SUM(B19:AJ19) -> 13 | AL19: =AK19/$AK$62 -> 0.046931408
A20: ='Conveyor Downtime (new)'!A21 -> 46037 | B20: =3+2+2+3 -> 10 | F20: =1+1 -> 2 | AK20: =SUM(B20:AJ20) -> 12 | AL20: =AK20/$AK$62 -> 0.0433213
A21: ='Conveyor Downtime (new)'!A22 -> 46037 | AD21: =15 -> 15 | AK21: =SUM(B21:AJ21) -> 15 | AL21: =AK21/$AK$62 -> 0.054151625
A22: ='Conveyor Downtime (new)'!A23 -> 46038 | B22: =3+4 -> 7 | F22: =1 -> 1 | AK22: =SUM(B22:AJ22) -> 8 | AL22: =AK22/$AK$62 -> 0.028880866
A23: ='Conveyor Downtime (new)'!A24 -> 46038 | B23: =1+2+1+2 -> 6 | F23: =1+1 -> 2 | AK23: =SUM(B23:AJ23) -> 8 | AL23: =AK23/$AK$62 -> 0.028880866
A24: ='Conveyor Downtime (new)'!A25 -> 46041 | B24: =2+1+2+1 -> 6 | F24: =1+2+1 -> 4 | AK24: =SUM(B24:AJ24) -> 10 | AL24: =AK24/$AK$62 -> 0.036101083
A25: ='Conveyor Downtime (new)'!A26 -> 46041 | B25: =1 -> 1 | AK25: =SUM(B25:AJ25) -> 1 | AL25: =AK25/$AK$62 -> 0.0036101083
A26: ='Conveyor Downtime (new)'!A27 -> 46042 | B26: =2+4 -> 6 | Z26: =3+60 -> 63 | AK26: =SUM(B26:AJ26) -> 69 | AL26: =AK26/$AK$62 -> 0.24909747
A27: ='Conveyor Downtime (new)'!A28 -> 46042 | B27: =1+1+1 -> 3 | F27: =1+1 -> 2 | AK27: =SUM(B27:AJ27) -> 5 | AL27: =AK27/$AK$62 -> 0.018050542
A28: ='Conveyor Downtime (new)'!A29 -> 46043 | AK28: =SUM(B28:AJ28) -> 0 | AL28: =AK28/$AK$62 -> 0
A29: ='Conveyor Downtime (new)'!A30 -> 46043 | AK29: =SUM(B29:AJ29) -> 0 | AL29: =AK29/$AK$62 -> 0
A30: ='Conveyor Downtime (new)'!A31 -> 46043 | AK30: =SUM(B30:AJ30) -> 0 | AL30: =AK30/$AK$62 -> 0
A31: ='Conveyor Downtime (new)'!A32 -> 46043 | AK31: =SUM(B31:AJ31) -> 0 | AL31: =AK31/$AK$62 -> 0
A32: ='Conveyor Downtime (new)'!A33 -> 46044 | AK32: =SUM(B32:AJ32) -> 0 | AL32: =AK32/$AK$62 -> 0
A33: ='Conveyor Downtime (new)'!A34 -> 46045 | AK33: =SUM(B33:AJ33) -> 0 | AL33: =AK33/$AK$62 -> 0
A34: ='Conveyor Downtime (new)'!A35 -> 46045 | AK34: =SUM(B34:AJ34) -> 0 | AL34: =AK34/$AK$62 -> 0
A35: ='Conveyor Downtime (new)'!A36 -> 46045 | B35: =1 -> 1 | AK35: =SUM(B35:AJ35) -> 1 | AL35: =AK35/$AK$62 -> 0.0036101083
A36: ='Conveyor Downtime (new)'!A37 -> 46045 | C36: =2+3 -> 5 | AK36: =SUM(B36:AJ36) -> 5 | AL36: =AK36/$AK$62 -> 0.018050542
A37: ='Conveyor Downtime (new)'!A38 -> 46048 | AK37: =SUM(B37:AJ37) -> 0 | AL37: =AK37/$AK$62 -> 0
A38: ='Conveyor Downtime (new)'!A39 -> 46048 | AK38: =SUM(B38:AJ38) -> 0 | AL38: =AK38/$AK$62 -> 0
A39: ='Conveyor Downtime (new)'!A40 -> 46049 | B39: =3 -> 3 | F39: =1+1 -> 2 | T39: =5 -> 5 | AK39: =SUM(B39:AJ39) -> 10 | AL39: =AK39/$AK$62 -> 0.036101083
A40: ='Conveyor Downtime (new)'!A41 -> 46049 | AK40: =SUM(B40:AJ40) -> 0 | AL40: =AK40/$AK$62 -> 0
A41: ='Conveyor Downtime (new)'!A42 -> 46050 | F41: =1 -> 1 | AK41: =SUM(B41:AJ41) -> 1 | AL41: =AK41/$AK$62 -> 0.0036101083
...

Sheet Pasteurizer Downtime Detail
B2: Pasteurizer Downtime Issues
A3: Date | B3: Hydraulics Malfunction | C3: Seal | D3: Cut off | E3: Teperature Gauge | F3: Pump Malfunction | G3: High PU | H3: Low PU | I3: Dry Run | J3: Burnt Fuse | K3: Low Temperature | L3: Sensor | M3: Main Valve wheel | N3: Steam line regulator flow | O3: Filter | P3: Air Leak | Q3: Nozzle/ Spray Jets | R3: Steam Leak (gasket, line) | S3: High Temperature | T3: Temperature Display Unit | U3: Man Hole | V3: Tank 3/ 5 | W3: Dead Plate | X3: Tank 4 | Y3: Air Quality/ Moisture
A4: 2026
A5: ='Conveyor Downtime (new)'!A6 -> 46024 | Z5: =SUM(B5:Y5) -> 0 | AA5: =Z5/$Z$68 -> 0
A6: ='Conveyor Downtime (new)'!A7 -> 46027 | Z6: =SUM(B6:Y6) -> 0 | AA6: =Z6/$Z$68 -> 0
A7: ='Conveyor Downtime (new)'!A8 -> 46028 | Z7: =SUM(B7:Y7) -> 0 | AA7: =Z7/$Z$68 -> 0
A8: ='Conveyor Downtime (new)'!A9 -> 46029 | Z8: =SUM(B8:Y8) -> 0 | AA8: =Z8/$Z$68 -> 0
A9: ='Conveyor Downtime (new)'!A10 -> 46030 | Z9: =SUM(B9:Y9) -> 0 | AA9: =Z9/$Z$68 -> 0
A10: ='Conveyor Downtime (new)'!A11 -> 46031 | Z10: =SUM(B10:Y10) -> 0 | AA10: =Z10/$Z$68 -> 0
A11: ='Conveyor Downtime (new)'!A12 -> 46031 | Z11: =SUM(B11:Y11) -> 0 | AA11: =Z11/$Z$68 -> 0
A12: ='Conveyor Downtime (new)'!A13 -> 46032 | Z12: =SUM(B12:Y12) -> 0 | AA12: =Z12/$Z$68 -> 0
A13: ='Conveyor Downtime (new)'!A14 -> 46034 | Z13: =SUM(B13:Y13) -> 0 | AA13: =Z13/$Z$68 -> 0
A14: ='Conveyor Downtime (new)'!A15 -> 46034 | Z14: =SUM(B14:Y14) -> 0 | AA14: =Z14/$Z$68 -> 0
A15: ='Conveyor Downtime (new)'!A16 -> 46034 | Z15: =SUM(B15:Y15) -> 0 | AA15: =Z15/$Z$68 -> 0
A16: ='Conveyor Downtime (new)'!A17 -> 46035 | Z16: =SUM(B16:Y16) -> 0 | AA16: =Z16/$Z$68 -> 0
... A18: ='Conveyor Downtime (new)'!A19 -> 46036 | Z18: =SUM(B18:Y18) -> 0 | AA18: =Z18/$Z$68 -> 0
A19: ='Conveyor Downtime (new)'!A20 -> 46036 | K19: =16 -> 16 | Z19: =SUM(B19:Y19) -> 16 | AA19: =Z19/$Z$68 -> 0.01849711
A20: ='Conveyor Downtime (new)'!A21 -> 46037 | I20: 26 | Z20: =SUM(B20:Y20) -> 26 | AA20: =Z20/$Z$68 -> 0.030057803
A21: ='Conveyor Downtime (new)'!A22 -> 46037 | Z21: =SUM(B21:Y21) -> 0 | AA21: =Z21/$Z$68 -> 0
A22: ='Conveyor Downtime (new)'!A23 -> 46038 | K22: =30 -> 30 | Z22: =SUM(B22:Y22) -> 30 | AA22: =Z22/$Z$68 -> 0.034682081
A23: ='Conveyor Downtime (new)'!A24 -> 46038 | F23: 2 | Z23: =SUM(B23:Y23) -> 2 | AA23: =Z23/$Z$68 -> 0.0023121387
A24: ='Conveyor Downtime (new)'!A25 -> 46041 | Z24: =SUM(B24:Y24) -> 0 | AA24: =Z24/$Z$68 -> 0
A25: ='Conveyor Downtime (new)'!A26 -> 46041 | Z25: =SUM(B25:Y25) -> 0 | AA25: =Z25/$Z$68 -> 0
A26: ='Conveyor Downtime (new)'!A27 -> 46042 | B26: =3+3 -> 6 | Z26: =SUM(B26:Y26) -> 6 | AA26: =Z26/$Z$68 -> 0.0069364162
A27: ='Conveyor Downtime (new)'!A28 -> 46042 | B27: =9 -> 9 | Z27: =SUM(B27:Y27) -> 9 | AA27: =Z27/$Z$68 -> 0.010404624
A28: ='Conveyor Downtime (new)'!A29 -> 46043 | Z28: =SUM(B28:Y28) -> 0 | AA28: =Z28/$Z$68 -> 0
A29: ='Conveyor Downtime (new)'!A30 -> 46043 | Z29: =SUM(B29:Y29) -> 0 | AA29: =Z29/$Z$68 -> 0
A30: ='Conveyor Downtime (new)'!A31 -> 46043 | Z30: =SUM(B30:Y30) -> 0 | AA30: =Z30/$Z$68 -> 0
A31: ='Conveyor Downtime (new)'!A32 -> 46043 | Z31: =SUM(B31:Y31) -> 0 | AA31: =Z31/$Z$68 -> 0
A32: ='Conveyor Downtime (new)'!A33 -> 46044 | Z32: =SUM(B32:Y32) -> 0 | AA32: =Z32/$Z$68 -> 0
A33: ='Conveyor Downtime (new)'!A34 -> 46045 | Z33: =SUM(B33:Y33) -> 0 | AA33: =Z33/$Z$68 -> 0
A34: ='Conveyor Downtime (new)'!A35 -> 46045 | Z34: =SUM(B34:Y34) -> 0 | AA34: =Z34/$Z$68 -> 0
A35: ='Conveyor Downtime (new)'!A36 -> 46045 | Z35: =SUM(B35:Y35) -> 0 | AA35: =Z35/$Z$68 -> 0
A36: ='Conveyor Downtime (new)'!A37 -> 46045 | Z36: =SUM(B36:Y36) -> 0 | AA36: =Z36/$Z$68 -> 0
A37: ='Conveyor Downtime (new)'!A38 -> 46048 | Z37: =SUM(B37:Y37) -> 0 | AA37: =Z37/$Z$68 -> 0
A38: ='Conveyor Downtime (new)'!A39 -> 46048 | F38: =51+480+60+60+21 -> 672 | G38: =7 -> 7 | K38: =12+60+25 -> 97 | Z38: =SUM(B38:Y38) -> 776 | AA38: =Z38/$Z$68 -> 0.89710983
A39: ='Conveyor Downtime (new)'!A40 -> 46049 | Z39: =SUM(B39:Y39) -> 0 | AA39: =Z39/$Z$68 -> 0
A40: ='Conveyor Downtime (new)'!A41 -> 46049 | Z40: =SUM(B40:Y40) -> 0 | AA40: =Z40/$Z$68 -> 0
A41: ='Conveyor Downtime (new)'!A42 -> 46050 | Z41: =SUM(B41:Y41) -> 0 | AA41: =Z41/$Z$68 -> 0
A42: ='Conveyor Downtime (new)'!A43 -> 46050 | Z42: =SUM(B42:Y42) -> 0 | AA42: =Z42/$Z$68 -> 0
...

Sheet Videojet Downtime Detail 
B3: Videojet Downtime Issues
A4: Date | B4: Not Printing Properly | C4: Date Code Adjustment | D4: Cut off | E4: Time | F4: Height | G4: Switching Videojet | H4: Colour | I4: Sensor | J4: Make up fluid | K4: Adjustment | L4: Head | M4: Alignment | N4: Date Code Change
A5: ='Conveyor Downtime (new)'!A6 -> 46024 | O5: =SUM(B5:N5) -> 0 | P5: =O5/$O$67 -> 0
A6: ='Conveyor Downtime (new)'!A7 -> 46027 | O6: =SUM(B6:N6) -> 0 | P6: =O6/$O$67 -> 0
A7: ='Conveyor Downtime (new)'!A8 -> 46028 | O7: =SUM(B7:N7) -> 0 | P7: =O7/$O$67 -> 0
A8: ='Conveyor Downtime (new)'!A9 -> 46029 | O8: =SUM(B8:N8) -> 0 | P8: =O8/$O$67 -> 0
A9: ='Conveyor Downtime (new)'!A10 -> 46030 | O9: =SUM(B9:N9) -> 0 | P9: =O9/$O$67 -> 0
A10: ='Conveyor Downtime (new)'!A11 -> 46031 | O10: =SUM(B10:N10) -> 0 | P10: =O10/$O$67 -> 0
A11: ='Conveyor Downtime (new)'!A12 -> 46031 | O11: =SUM(B11:N11) -> 0 | P11: =O11/$O$67 -> 0
A12: ='Conveyor Downtime (new)'!A13 -> 46032 | O12: =SUM(B12:N12) -> 0 | P12: =O12/$O$67 -> 0
A13: ='Conveyor Downtime (new)'!A14 -> 46034 | O13: =SUM(B13:N13) -> 0 | P13: =O13/$O$67 -> 0
A14: ='Conveyor Downtime (new)'!A15 -> 46034 | O14: =SUM(B14:N14) -> 0 | P14: =O14/$O$67 -> 0
A15: ='Conveyor Downtime (new)'!A16 -> 46034 | O15: =SUM(B15:N15) -> 0 | P15: =O15/$O$67 -> 0
A16: ='Conveyor Downtime (new)'!A17 -> 46035 | O16: =SUM(B16:N16) -> 0 | P16: =O16/$O$67 -> 0
... A23: ='Conveyor Downtime (new)'!A24 -> 46038 | O23: =SUM(B23:N23) -> 0 | P23: =O23/$O$67 -> 0
A24: ='Conveyor Downtime (new)'!A25 -> 46041 | B24: =3 -> 3 | O24: =SUM(B24:N24) -> 3 | P24: =O24/$O$67 -> 0.026086957
A25: ='Conveyor Downtime (new)'!A26 -> 46041 | O25: =SUM(B25:N25) -> 0 | P25: =O25/$O$67 -> 0
A26: ='Conveyor Downtime (new)'!A27 -> 46042 | B26: =18 -> 18 | O26: =SUM(B26:N26) -> 18 | P26: =O26/$O$67 -> 0.15652174
A27: ='Conveyor Downtime (new)'!A28 -> 46042 | B27: =4 -> 4 | O27: =SUM(B27:N27) -> 4 | P27: =O27/$O$67 -> 0.034782609
A28: ='Conveyor Downtime (new)'!A29 -> 46043 | O28: =SUM(B28:N28) -> 0 | P28: =O28/$O$67 -> 0
A29: ='Conveyor Downtime (new)'!A30 -> 46043 | O29: =SUM(B29:N29) -> 0 | P29: =O29/$O$67 -> 0
A30: ='Conveyor Downtime (new)'!A31 -> 46043 | B30: 33 | O30: =SUM(B30:N30) -> 33 | P30: =O30/$O$67 -> 0.28695652
A31: ='Conveyor Downtime (new)'!A32 -> 46043 | O31: =SUM(B31:N31) -> 0 | P31: =O31/$O$67 -> 0
A32: ='Conveyor Downtime (new)'!A33 -> 46044 | O32: =SUM(B32:N32) -> 0 | P32: =O32/$O$67 -> 0
A33: ='Conveyor Downtime (new)'!A34 -> 46045 | O33: =SUM(B33:N33) -> 0 | P33: =O33/$O$67 -> 0
A34: ='Conveyor Downtime (new)'!A35 -> 46045 | O34: =SUM(B34:N34) -> 0 | P34: =O34/$O$67 -> 0
A35: ='Conveyor Downtime (new)'!A36 -> 46045 | O35: =SUM(B35:N35) -> 0 | P35: =O35/$O$67 -> 0
A36: ='Conveyor Downtime (new)'!A37 -> 46045 | O36: =SUM(B36:N36) -> 0 | P36: =O36/$O$67 -> 0
A37: ='Conveyor Downtime (new)'!A38 -> 46048 | O37: =SUM(B37:N37) -> 0 | P37: =O37/$O$67 -> 0
A38: ='Conveyor Downtime (new)'!A39 -> 46048 | O38: =SUM(B38:N38) -> 0 | P38: =O38/$O$67 -> 0
A39: ='Conveyor Downtime (new)'!A40 -> 46049 | O39: =SUM(B39:N39) -> 0 | P39: =O39/$O$67 -> 0
A40: ='Conveyor Downtime (new)'!A41 -> 46049 | O40: =SUM(B40:N40) -> 0 | P40: =O40/$O$67 -> 0
A41: ='Conveyor Downtime (new)'!A42 -> 46050 | J41: =36+21 -> 57 | O41: =SUM(B41:N41) -> 57 | P41: =O41/$O$67 -> 0.49565217
A42: ='Conveyor Downtime (new)'!A43 -> 46050 | O42: =SUM(B42:N42) -> 0 | P42: =O42/$O$67 -> 0
A43: ='Conveyor Downtime (new)'!A44 -> 46050 | O43: =SUM(B43:N43) -> 0 | P43: =O43/$O$67 -> 0
A44: ='Conveyor Downtime (new)'!A45 -> 46051 | O44: =SUM(B44:N44) -> 0 | P44: =O44/$O$67 -> 0
A45: ='Conveyor Downtime (new)'!A46 -> 46051 | O45: =SUM(B45:N45) -> 0 | P45: =O45/$O$67 -> 0
A46: ='Conveyor Downtime (new)'!A47 -> 46051 | O46: =SUM(B46:N46) -> 0 | P46: =O46/$O$67 -> 0
A47: ='Conveyor Downtime (new)'!A48 -> 46051 | O47: =SUM(B47:N47) -> 0 | P47: =O47/$O$67 -> 0
A48: ='Conveyor Downtime (new)'!A49 -> 46052 | O48: =SUM(B48:N48) -> 0 | P48: =O48/$O$67 -> 0
...

Sheet Labeler Downtime Detail
B3: Labeler Downtime Issues
A4: Date | B4: Missing Labels | C4: Flagging/Twisted Labels | D4: Label Misalignment adjust | E4: Timing Issues | F4: Startup Adjustments | G4: Oil line | H4: Grease | I4: Starwheel | J4: Air Knife | K4: Krones Tech | L4: Neck fingers | M4: Neck Sponge | N4: Encoder | O4: New Dimension | P4: Carousel | Q4: Aggregate | R4: Glue Pump | S4: Breaker | T4: Centering cup | U4: Centering bell | V4: Back Station Adjustments | W4: Sensor | X4: Glue Scrapper | Y4: Glue Roller | Z4: Magazine | AA4: Pallet | AB4: Bottle Pads | AC4: Fine clock pulse issue | AD4: Air hose | AE4: Gripper Cylinder | AF4: Cam Follower | AG4: air guage | AH4: Gear Box | AI4: Labeller Infeed | AJ4: Brush | AK4: Motor | AL4: Cleaning | AM4: In-feed worm
A5: 2026
A6: ='Conveyor Downtime (new)'!A6 -> 46024 | AN6: =SUM(B6:AM6) -> 0 | AO6: =AN6/$AN$67 -> 0
A7: ='Conveyor Downtime (new)'!A7 -> 46027 | AN7: =SUM(B7:AM7) -> 0 | AO7: =AN7/$AN$67 -> 0
A8: ='Conveyor Downtime (new)'!A8 -> 46028 | AN8: =SUM(B8:AM8) -> 0 | AO8: =AN8/$AN$67 -> 0
A9: ='Conveyor Downtime (new)'!A9 -> 46029 | AN9: =SUM(B9:AM9) -> 0 | AO9: =AN9/$AN$67 -> 0
A10: ='Conveyor Downtime (new)'!A10 -> 46030 | F10: =7 -> 7 | AN10: =SUM(B10:AM10) -> 7 | AO10: =AN10/$AN$67 -> 0.034313725
A11: ='Conveyor Downtime (new)'!A11 -> 46031 | B11: =3+5 -> 8 | AM11: =11 -> 11 | AN11: =SUM(B11:AM11) -> 19 | AO11: =AN11/$AN$67 -> 0.093137255
