Workbook
Name Apr: [1]April!$A$1:$Q$35
Name Aug: [1]Aug!$A$1:$Q$35
Name Category: #REF!
Name Classification: #REF!
Name CO2MOR: #REF!
Name Company: #REF!
Name Date: #REF!
Name Dec: [1]Dec!$A$1:$Q$35
Name elc.beer: [2]Electricity!#REF!
Name Elec.beer: [2]Electricity!#REF!
Name elec.malt: [2]Electricity!#REF!
Name elec.oth: [2]Electricity!#REF!
Name ELECMOR: #REF!
Name Feb: [1]Feb!$A$1:$Q$35
Name FS_Area: #REF!
Name FUELMOR: #REF!
Name H20MOR: #REF!
Name IT: #REF!
Name Jan: '[1] Jan'!$A$1:$Q$35
Name July: [1]July!$A$1:$Q$35
Name June: [1]June!$A$1:$Q$35
Name Mar: [1]Mar!$A$1:$Q$35
Name May: [1]May!$A$1:$Q$35
Name MS: #REF!
Name Nov: [1]Nov!$A$1:$Q$35
Name Oct: [1]Oct!$A$1:$Q$35
Name RATIOS: #REF!
Name Reporting_body: #REF!
Name Risk: #REF!
Name Sector: #REF!
Name Sept: [1]Sept!$A$1:$Q$35
Name Status: #REF!
Name Summary: #REF!
Name TOTALMOR: #REF!

Sheet January_2026
B1: GRENADA BREWERIES LIMITED
B3: PRODUCTION DEPARTMENT
B4: 46023
B5: DATE | C5: DAY | D5: PRODUCT | E5: AVAIL. | F5: FILL | G5: CASES | H5: Line Rated | I5: Cases on Hold | J5: BBT | K5: BOTTLED | L5: Diff BBT Hls vs Hls in Package | M5: DOWNTIME (Mins) | N5: REJECTS (Cases) | O5: KEGS | P5: BOTTLED | Q5: AVERAGE | R5: AVERAGE | S5: YTD | T5: AVG
E6: TIME | F6: TIME | G6: BOTTLED | H6: Efficiency | J6: HLS | K6: HLS | P6: LOSS | Q6: CASE/HR | R6: CASE/HR | S6: Ave Case per hour | T6: CASE PER
F7: Mins | H7: % | Q7: Avail Time | R7: Fill Time | T7: DAY
B8: 46024 | C8: 1 | D8: CARIB AMBER | E8: 790 | F8: =[3]Jan!$N69 -> 559 | G8: 3360 | H8: =(G8)*24/(F8/60)/17000*100 -> 50.914448 | I8: 139 | J8: =SUM(52.3,59,65,50.9) -> 227.2 | K8: =(G8)*0.066 -> 221.76 | L8: =J8-K8 -> 5.44 | M8: =[3]Jan!$AD8 -> 276 | N8: 4 | P8: =(J8-K8)/J8*100 -> 2.3943662 | Q8: =(G8)/(E8/60) -> 255.18987 | R8: =(G8)/(F8/60) -> 360.64401 | S8: =((J9+J8)-(K9+K8))/(J9+J8)*100 -> 2.4146982
B9: 46027 | C9: 2 | D9: CARIB AMBER | E9: 1330 | F9: =[3]Jan!$N70 -> 160 | G9: 20 | H9: =(G9)*24/(F9/60)/17000*100 -> 1.0588235 | J9: =SUM(88.6)-73.2-14 -> 1.4 | K9: =(G9)*0.066 -> 1.32 | L9: =J9-K9 -> 0.08 | M9: =[3]Jan!$AD9 -> 1358 | P9: =(J9-K9)/J9*100 -> 5.7142857 | Q9: =(G9)/(E9/60) -> 0.90225564 | R9: =(G9)/(F9/60) -> 7.5
B10: 46028 | D10: EBI/FILLER COMMUNICATION BREAKDOWN | F10: =[3]Jan!$N71 -> 0 | H10: =(G10)*24/(F10/60)/17000*100 -> #DIV/0! | K10: =(G10)*0.066 -> 0 | L10: =J10-K10 -> 0 | M10: =[3]Jan!$AD10 -> 1440 | P10: =(J10-K10)/J10*100 -> #DIV/0! | Q10: =(G10)/(E10/60) -> #DIV/0! | R10: =(G10)/(F10/60) -> #DIV/0!
B11: 46029 | D11: EBI/FILLER COMMUNICATION BREAKDOWN | F11: =[3]Jan!$N72 -> 0 | H11: =(G11)*24/(F11/60)/17000*100 -> #DIV/0! | K11: =(G11)*0.066 -> 0 | L11: =J11-K11 -> 0 | M11: =[3]Jan!$AD11 -> 1440 | O11: 45 | P11: =(J11-K11)/J11*100 -> #DIV/0! | Q11: =(G11)/(E11/60) -> #DIV/0! | R11: =(G11)/(F11/60) -> #DIV/0!
B12: 46030 | C12: 3 | D12: CARIB AMBER | E12: 1440 | F12: =[3]Jan!$N73 -> 271 | G12: 1563 | H12: =(G12)*24/(F12/60)/17000*100 -> 48.854352 | J12: =SUM(98.8,64.65)-59.5 -> 103.95 | K12: =(G12)*0.066 -> 103.158 | L12: =J12-K12 -> 0.792 | M12: =[3]Jan!$AD12 -> 1264 | N12: 4 | P12: =(J12-K12)/J12*100 -> 0.76190476 | Q12: =(G12)/(E12/60) -> 65.125 | R12: =(G12)/(F12/60) -> 346.05166 | S12: =((J13+J12)-(K13+K12))/(J13+J12)*100 -> 2.8714468
B13: 46031 | C13: 4 | D13: CARIB AMBER | E13: 1185 | F13: =[3]Jan!$N74 -> 633 | G13: 3640 | H13: =(G13)*24/(F13/60)/17000*100 -> 48.709228 | J13: =SUM(93.9,59.5,96.2) -> 249.6 | K13: =(G13)*0.066 -> 240.24 | L13: =J13-K13 -> 9.36 | M13: =[3]Jan!$AD13 -> 304 | N13: =9+13 -> 22 | P13: =(J13-K13)/J13*100 -> 3.75 | Q13: =(G13)/(E13/60) -> 184.3038 | R13: =(G13)/(F13/60) -> 345.0237
B14: 46031 | C14: 4 | D14: STAR MALT | F14: =[3]Jan!$N75 -> 341 | G14: 2559 | H14: =(G14)*24/(F14/60)/17000*100 -> 63.566672 | J14: =SUM(98.4,101)-24.1 -> 175.3 | K14: =(G14)*0.066 -> 168.894 | L14: =J14-K14 -> 6.406 | M14: =[3]Jan!$AD14 -> 136 | N14: 7 | P14: =(J14-K14)/J14*100 -> 3.6543069 | Q14: =(G14)/(E13/60) -> 129.56962 | R14: =(G14)/(F14/60) -> 450.26393 | S14: =((J15+J14)-(K15+K14))/(J15+J14)*100 -> 3.4806378
B15: 46032 | C15: 5 | D15: STAR MALT | E15: 400 | F15: =[3]Jan!$N76 -> 331 | G15: 2577 | H15: =(G15)*24/(F15/60)/17000*100 -> 65.947752 | J15: =SUM(24.1,99,103.8)-51 -> 175.9 | K15: =(G15)*0.066 -> 170.082 | L15: =J15-K15 -> 5.818 | M15: =[3]Jan!$AD15 -> 107 | N15: 32 | P15: =(J15-K15)/J15*100 -> 3.3075611 | Q15: =(G15)/(E15/60) -> 386.55 | R15: =(G15)/(F15/60) -> 467.12991
B16: 46034 | C16: 6 | D16: VITA MALT ( CLASSIC) | E16: 1380 | F16: =[3]Jan!$N77 -> 375 | G16: 2656 | H16: =(G16)*24/(F16/60)/17000*100 -> 59.994353 | J16: =SUM(93.2,93.6,1.5) -> 188.3 | K16: =(G16)*0.0708 -> 188.0448 | L16: =J16-K16 -> 0.2552 | M16: =[3]Jan!$AD16 -> 191 | N16: 5 | P16: =(J16-K16)/J16*100 -> 0.13552841 | Q16: =(G16)/(E16/60) -> 115.47826 | R16: =(G16)/(F16/60) -> 424.96
B17: 46034 | C17: 6 | D17: STAR MALT | F17: =[3]Jan!$N78 -> 369 | G17: 2263 | H17: =(G17)*24/(F17/60)/17000*100 -> 51.94835 | I17: 1517 | J17: =SUM(51,102) -> 153 | K17: =(G17)*0.066 -> 149.358 | L17: =J17-K17 -> 3.642 | M17: =[3]Jan!$AD17 -> 273 | N17: =7+7 -> 14 | P17: =(J17-K17)/J17*100 -> 2.3803922 | Q17: =(G17)/(E16/60) -> 98.391304 | R17: =(G17)/(F17/60) -> 367.96748
B18: 46034 | C18: 6 | D18: STAG | F18: =[3]Jan!$N79 -> 78 | G18: 750 | H18: =(G18)*24/(F18/60)/17000*100 -> 81.447964 | J18: =SUM(94,101.5)-74.5-69 -> 52 | K18: =(G18)*0.066 -> 49.5 | L18: =J18-K18 -> 2.5 | M18: =[3]Jan!$AD18 -> 114 | N18: 2 | P18: =(J18-K18)/J18*100 -> 4.8076923 | Q18: =(G18)/(E16/60) -> 32.608696 | R18: =(G18)/(F18/60) -> 576.92308 | S18: =((J19+J18)-(K19+K18))/(J19+J18)*100 -> 2.1446625
B19: 46035 | C19: 7 | D19: STAG | E19: 1440 | F19: =[3]Jan!$N80 -> 861 | G19: 4764 | H19: =(G19)*24/(F19/60)/17000*100 -> 46.868621 | J19: =SUM(74.5,69,84.3,92.1) -> 319.9 | K19: =(G19)*0.066 -> 314.424 | L19: =J19-K19 -> 5.476 | M19: =[3]Jan!$AD19 -> 273 | N19: 11 | P19: =(J19-K19)/J19*100 -> 1.7117849 | Q19: =(G19)/(E19/60) -> 198.5 | R19: =(G19)/(F19/60) -> 331.98606
B20: 46035 | C20: 7 | D20: CARIB AMBER | F20: =[3]Jan!$N81 -> 496 | G20: 2780 | H20: =(G20)*24/(F20/60)/17000*100 -> 47.476281 | J20: =SUM(95,95)-1 -> 189 | K20: =(G20)*0.066 -> 183.48 | L20: =J20-K20 -> 5.52 | M20: =[3]Jan!$AD20 -> 181 | N20: 7 | P20: =(J20-K20)/J20*100 -> 2.9206349 | Q20: =(G20)/(E19/60) -> 115.83333 | R20: =(G20)/(F20/60) -> 336.29032 | S20: =((J21+J20)-(K21+K20))/(J21+J20)*100 -> 2.5274056
B21: 46036 | C21: 8 | D21: CARIB AMBER | E21: 1428 | F21: =[3]Jan!$N82 -> 278 | G21: 2070 | H21: =(G21)*24/(F21/60)/17000*100 -> 63.072366 | J21: =SUM(1,55.4,83) -> 139.4 | K21: =(G21)*0.066 -> 136.62 | L21: =J21-K21 -> 2.78 | M21: =[3]Jan!$AD21 -> 55 | N21: 10 | P21: =(J21-K21)/J21*100 -> 1.9942611 | Q21: =(G21)/(E19/60) -> 86.25 | R21: =(G21)/(F21/60) -> 446.76259
B22: 46036 | C22: 8 | D22: STAG | F22: =[3]Jan!$N83 -> 949 | G22: 5326 | H22: =(G22)*24/(F22/60)/17000*100 -> 47.538833 | J22: =SUM(80.8,75,50.8,72,79.8) -> 358.4 | K22: =(G22)*0.066+(10*0.19) -> 353.416 | L22: =J22-K22 -> 4.984 | M22: =[3]Jan!$AD22 -> 381 | N22: =1+10+8+1 -> 20 | O22: 10 | P22: =(J22-K22)/J22*100 -> 1.390625 | Q22: =(G22)/(E21/60) -> 223.78151 | R22: =(G22)/(F22/60) -> 336.7334
B23: 46037 | C23: 9 | D23: MACKESON | E23: 1408 | F23: =[3]Jan!$N84 -> 965 | G23: 5765 | H23: =(G23)*24/(F23/60)/17000*100 -> 50.604084 | J23: =SUM(95.2,93,98,100) -> 386.2 | K23: =(G23)*0.066 -> 380.49 | L23: =J23-K23 -> 5.71 | M23: =[3]Jan!$AD23 -> 268 | N23: =6+10+4 -> 20 | P23: =(J23-K23)/J23*100 -> 1.4785085 | Q23: =(G23)/(E23/60) -> 245.66761 | R23: =(G23)/(F23/60) -> 358.4456
B24: 46037 | C24: 9 | D24: SHANDY SORREL (LOC) | F24: =[3]Jan!$N85 -> 252 | G24: 1323 | H24: =(G24)*24/(F24/60)/17000*100 -> 44.470588 | J24: 90.6 | K24: =(G24)*0.066 -> 87.318 | L24: =J24-K24 -> 3.282 | M24: =[3]Jan!$AD24 -> 168 | N24: 10 | P24: =(J24-K24)/J24*100 -> 3.6225166 | Q24: =(G24)/(E23/60) -> 56.377841 | R24: =(G24)/(F24/60) -> 315
B25: 46038 | C25: 10 | D25: TING( GREEN) | E25: 1230 | F25: =[3]Jan!$N86 -> 311 | G25: 1792 | H25: =(G25)*24/(F25/60)/17000*100 -> 48.80802 | J25: =K25*1.02 -> 120.63744 | K25: =(G25)*0.066 -> 118.272 | L25: =J25-K25 -> 2.36544 | M25: =[3]Jan!$AD25 -> 188 | N25: 7 | P25: =(J25-K25)/J25*100 -> 1.9607843 | Q25: =(G25)/(E25/60) -> 87.414634 | R25: =(G25)/(F25/60) -> 345.72347
B26: 46038 | C26: 11 | D26: CARIB AMBER | F26: =[3]Jan!$N87 -> 731 | G26: 4642 | H26: =(G26)*24/(F26/60)/17000*100 -> 53.789973 | J26: =SUM(88,80,82.3,101.7)-39.6 -> 312.4 | K26: =(G26)*0.066 -> 306.372 | L26: =J26-K26 -> 6.028 | M26: =[3]Jan!$AD26 -> 242 | N26: =8+2 -> 10 | P26: =(J26-K26)/J26*100 -> 1.9295775 | Q26: =(G26)/(E23/60) -> 197.8125 | R26: =(G26)/(F26/60) -> 381.01231 | S26: =((J27+J26)-(K27+K26))/(J27+J26)*100 -> 1.7898116
B27: 46041 | C27: 12 | D27: CARIB AMBER | E27: 1380 | F27: =[3]Jan!$N88 -> 736 | G27: 5919 | H27: =(G27)*24/(F27/60)/17000*100 -> 68.121483 | J27: =SUM(100,77,93.5,39.6,94) -> 404.1 | K27: =(G27)*0.066+(35*0.19) -> 397.304 | L27: =J27-K27 -> 6.796 | M27: =[3]Jan!$AD27 -> 279 | N27: =6+2+4 -> 12 | O27: 35 | P27: =(J27-K27)/J27*100 -> 1.6817619 | Q27: =(G27)/(E27/60) -> 257.34783 | R27: =(G27)/(F27/60) -> 482.52717
B28: 46041 | C28: 12 | D28: STAG | F28: =[3]Jan!$N89 -> 295 | G28: 2049 | H28: =(G28)*24/(F28/60)/17000*100 -> 58.834696 | J28: =SUM(99.8,100.8)-63.3 -> 137.3 | K28: =(G28)*0.066 -> 135.234 | L28: =J28-K28 -> 2.066 | M28: =[3]Jan!$AD28 -> 86 | P28: =(J28-K28)/J28*100 -> 1.5047342 | Q28: =(G28)/(E27/60) -> 89.086957 | R28: =(G28)/(F28/60) -> 416.74576 | S28: =((J29+J28)-(K29+K28))/(J29+J28)*100 -> 1.2920354
B29: 46042 | C29: 13 | D29: STAG | E29: 1435 | F29: =[3]Jan!$N90 -> 588 | G29: 3528 | H29: =(G29)*24/(F29/60)/17000*100 -> 50.823529 | J29: =SUM( 73.3,63.3,99) -> 235.6 | K29: =(G29)*0.066 -> 232.848 | L29: =J29-K29 -> 2.752 | M29: =[3]Jan!$AD29 -> 147 | N29: =6+4 -> 10 | P29: =(J29-K29)/J29*100 -> 1.1680815 | Q29: =(G29)/(E29/60) -> 147.5122 | R29: =(G29)/(F29/60) -> 360
B30: 46042 | C30: 13 | D30: GINSENG UP (ORG) | F30: =[3]Jan!$N91 -> 572 | G30: 3008 | H30: =(G30)*24/(F30/60)/17000*100 -> 44.544632 | I30: 3 | J30: =SUM(99.3,103) -> 202.3 | K30: =(G30)*0.066 -> 198.528 | L30: =J30-K30 -> 3.772 | M30: =[3]Jan!$AD30 -> 184 | N30: =4+7 -> 11 | P30: =(J30-K30)/J30*100 -> 1.8645576 | Q30: =(G30)/(E29/60) -> 125.77003 | R30: =(G30)/(F30/60) -> 315.52448
B31: 46043 | C31: 14 | D31: SODA WATER | E31: 1440 | F31: =[3]Jan!$N92 -> 62 | G31: 417 | H31: =(G31)*24/(F31/60)/17000*100 -> 56.971537 | J31: =K31 -> 27.522 | K31: =(G31)*0.066 -> 27.522 | L31: =J31-K31 -> 0 | M31: =[3]Jan!$AD31 -> 199 | N31: 6 | P31: =(J31-K31)/J31*100 -> 0 | Q31: =(G31)/(E31/60) -> 17.375 | R31: =(G31)/(F31/60) -> 403.54839
B32: 46043 | C32: 14 | D32: KOLA CHAMP J.COOL | F32: =[3]Jan!$N93 -> 665 | G32: 1335 | H32: =(G32)*24/(F32/60)/17000*100 -> 17.004865 | J32: =(1400)*0.066 -> 92.4 | K32: =(G32)*0.066 -> 88.11 | L32: =J32-K32 -> 4.29 | M32: =[3]Jan!$AD32 -> 293 | N32: 14 | P32: =(J32-K32)/J32*100 -> 4.6428571 | Q32: =(G32)/(E31/60) -> 55.625 | R32: =(G32)/(F32/60) -> 120.45113
B33: 46043 | C33: 14 | D33: CREAM SODA | F33: =[3]Jan!$N94 -> 311 | G33: 1328 | H33: =(G33)*24/(F33/60)/17000*100 -> 36.170229 | J33: =(1400)*0.066 -> 92.4 | K33: =(G33)*0.066 -> 87.648 | L33: =J33-K33 -> 4.752 | M33: =[3]Jan!$AD33 -> 224 | N33: 10 | P33: =(J33-K33)/J33*100 -> 5.1428571 | Q33: =(G33)/(E31/60) -> 55.333333 | R33: =(G33)/(F33/60) -> 256.20579
B34: 46043 | C34: 14 | D34: BANANA | F34: =[3]Jan!$N95 -> 175 | G34: 455 | H34: =(G34)*24/(F34/60)/17000*100 -> 22.023529 | J34: =(500)*0.066 -> 33 | K34: =(G34)*0.066 -> 30.03 | L34: =J34-K34 -> 2.97 | M34: =[3]Jan!$AD34 -> 147 | N34: 16 | P34: =(J34-K34)/J34*100 -> 9 | Q34: =(G34)/(E31/60) -> 18.958333 | R34: =(G34)/(F34/60) -> 156
B35: 46044 | C35: 15 | D35: NO PRODUCTION- LOW WATER PRESSURE | H35: =(G35)*24/(F35/60)/17000*100 -> #DIV/0! | K35: =(G35)*0.066 -> 0 | L35: =J35-K35 -> 0 | M35: =[3]Jan!$AD35 -> 1440 | P35: =(J35-K35)/J35*100 -> #DIV/0! | Q35: =(G35)/(E35/60) -> #DIV/0! | R35: =(G35)/(F35/60) -> #DIV/0!
B36: 46045 | C36: 16 | D36: BANANA J.COOL | E36: 1221 | F36: =[3]Jan!$N97 -> 6 | G36: 13 | H36: =(G36)*24/(F36/60)/17000*100 -> 18.352941 | J36: =200*0.066 -> 13.2 | K36: =(G36)*0.066 -> 0.858 | L36: =J36-K36 -> 12.342 | M36: =[3]Jan!$AD36 -> 398 | N36: 12 | P36: =(J36-K36)/J36*100 -> 93.5 | Q36: =(G36)/(E36/60) -> 0.63882064 | R36: =(G36)/(F36/60) -> 130
B37: 46045 | C37: 16 | D37: j COOL GINGER | F37: =[3]Jan!$N98 -> 303 | G37: 1389 | H37: =(G37)*24/(F37/60)/17000*100 -> 38.830518 | J37: =1400*0.066 -> 92.4 | K37: =(G37)*0.066 -> 91.674 | L37: =J37-K37 -> 0.726 | M37: =[3]Jan!$AD37 -> 234 | N37: =1 -> 1 | P37: =(J37-K37)/J37*100 -> 0.78571429 | Q37: =(G37)/(E36/60) -> 68.255528 | R37: =(G37)/(F37/60) -> 275.0495
B38: 46045 | C38: 16 | D38: J COOL GRAPE | F38: =[3]Jan!$N99 -> 170 | G38: 798 | H38: =(G38)*24/(F38/60)/17000*100 -> 39.761938 | J38: =800*0.066 -> 52.8 | K38: =(G38)*0.066 -> 52.668 | L38: =J38-K38 -> 0.132 | M38: =[3]Jan!$AD38 -> 73 | N38: 6 | P38: =(J38-K38)/J38*100 -> 0.25 | Q38: =(G38)/(E36/60) -> 39.213759 | R38: =(G38)/(F38/60) -> 281.64706
B39: 46045 | C39: 16 | D39: J COOL SORREL | F39: =[3]Jan!$N100 -> 94 | G39: 637 | H39: =(G39)*24/(F39/60)/17000*100 -> 57.401752 | J39: =700*0.066 -> 46.2 | K39: =(G39)*0.066 -> 42.042 | L39: =J39-K39 -> 4.158 | M39: =[3]Jan!$AD39 -> 29 | N39: 2 | P39: =(J39-K39)/J39*100 -> 9 | Q39: =(G39)/(E36/60) -> 31.302211 | R39: =(G39)/(F39/60) -> 406.59574
B40: 46048 | C40: 17 | D40: J COOL SORREL | E40: 1380 | F40: =[3]Jan!$N101 -> 91 | G40: 586 | H40: =(G40)*24/(F40/60)/17000*100 -> 54.546865 | J40: =700*0.066 -> 46.2 | K40: =(G40)*0.066 -> 38.676 | L40: =J40-K40 -> 7.524 | M40: =[3]Jan!$AD40 -> 49 | N40: 14 | P40: =(J40-K40)/J40*100 -> 16.285714 | Q40: =(G40)/(E36/60) -> 28.796069 | R40: =(G40)/(F40/60) -> 386.37363
B41: 46048 | C41: 17 | D41: CARIB AMBER | F41: =[3]Jan!$N102 -> 1115 | G41: 1840 | H41: =(G41)*24/(F41/60)/17000*100 -> 13.97837 | J41: =SUM(100,95)-65.8 -> 129.2 | K41: =(G41)*0.066 -> 121.44 | L41: =J41-K41 -> 7.76 | M41: =[3]Jan!$AD41 -> 955 | N41: 1 | P41: =(J41-K41)/J41*100 -> 6.006192 | Q41: =(G41)/(E40/60) -> 80 | R41: =(G41)/(F41/60) -> 99.013453
...

Sheet February_2026
B1: GRENADA BREWERIES LIMITED
B3: PRODUCTION DEPARTMENT
B4: 46071
B5: DATE | C5: DAY | D5: PRODUCT | E5: AVAIL. | F5: FILL | G5: CASES | H5: Line Rated | I5: Cases on Hold | J5: BBT | K5: BOTTLED | L5: Diff BBT | M5: DOWNTIME | N5: REJECTS | O5: KEGS | P5: BOTTLED2 | Q5: AVERAGE | R5: YTD | S5: Glue | T5: AVG
E6: TIME | F6: TIME | G6: BOTTLED | H6: Efficiency | J6: HLS | K6: HLS | L6: Hls vs Hls in Package | N6: (Cases) | P6: LOSS | Q6: CASE/HR | R6: Ave Case | S6: Usage | T6: CASE PER
F7: Mins | H7: % | M7: (Mins) | Q7: Avail Time | R7: per hour | S7: lbs/case | T7: DAY
B8: 46055 | C8: 1 | D8: STAG | E8: 1380 | F8: =[3]Feb!$N68 -> 354 | G8: 2653 | H8: =(G8)*24/(F8/60)/17000*100 -> 63.481555 | J8: =SUM(100.1,77.3) -> 177.4 | K8: =(G8)*0.066 -> 175.098 | L8: =J8-K8 -> 2.302 | M8: =[3]Feb!$AD8 -> 221 | N8: 5 | P8: =(J8-K8)/J8*100 -> 1.2976325 | Q8: =G8/(E8/60) -> 115.34783 | S8: ='[4]Daily glue FEB'!$H$2 -> 0.011221557
B9: 46055 | C9: 1 | D9: CARIB AMBER | F9: =[3]Feb!$N69 -> 724 | G9: 5267 | H9: =(G9)*24/(F9/60)/17000*100 -> 61.622359 | J9: =SUM(94,100.2,98,89.2)-26.8 -> 354.6 | K9: =(G9)*0.066 -> 347.622 | L9: =J9-K9 -> 6.978 | M9: =[3]Feb!$AD9 -> 166 | N9: 1 | P9: =(J9-K9)/J9*100 -> 1.9678511 | Q9: =E8/(F9/60) -> 114.36464 | S9: ='[4]Daily glue FEB'!$H$4 -> 0.015132429
B10: 46056 | C10: 2 | D10: CARIB AMBER | E10: 1440 | F10: =[3]Feb!$N70 -> 1147 | G10: 8556 | H10: =(G10)*24/(F10/60)/17000*100 -> 63.18601 | J10: =SUM(26.8,91,94,97.8,52.5,77.8,99.2,53,51)-12.8-56 -> 574.3 | K10: =(G10)*0.066 -> 564.696 | L10: =J10-K10 -> 9.604 | M10: =[3]Feb!$AD10 -> 433 | N10: =2+2+3 -> 7 | P10: =(J10-K10)/J10*100 -> 1.6722967 | Q10: =G10/(E10/60) -> 356.5 | S10: ='[4]Daily glue FEB'!$H$5+'[4]Daily glue FEB'!$H$7+'[4]Daily glue FEB'!$H$7 -> 0.045202835
B11: 46057 | C11: 3 | D11: CARIB FLINT ( EXP) | E11: 1422 | F11: =[3]Feb!$N71 -> 711 | G11: 2804 | H11: =(G11)*24/(F11/60)/17000*100 -> 33.405808 | J11: =SUM(12.8,56,101,17) -> 186.8 | K11: =(G11)*0.066 -> 185.064 | L11: =J11-K11 -> 1.736 | M11: =[3]Feb!$AD11 -> 342 | N11: =6+6 -> 12 | P11: =(J11-K11)/J11*100 -> 0.92933619 | Q11: =G11/(E11/60) -> 118.31224 | S11: =SUM('[4]Daily glue FEB'!$H$8,'[4]Daily glue FEB'!$H$9) -> 0.046256743
B12: 46057 | C12: 3 | D12: CARIBE ROSE | F12: =[3]Feb!$N72 -> 489 | G12: 1568 | H12: =(G12)*24/(F12/60)/17000*100 -> 27.161314 | J12: =SUM(70.8,91.4)-49.3 -> 112.9 | K12: =(G12)*0.066 -> 103.488 | L12: =J12-K12 -> 9.412 | M12: =[3]Feb!$AD12 -> 406 | N12: 0 | P12: =(J12-K12)/J12*100 -> 8.336581 | Q12: =G12/(E11/60) -> 66.160338 | R12: =((J13+J12)-(K13+K12))/(J13+J12)*100 -> 5.8828607 | S12: =SUM('[4]Daily glue FEB'!$H$10) -> 0.02154023
B13: 46058 | C13: 4 | D13: CARIBE ROSE | E13: 1430 | F13: =[3]Feb!$N73 -> 144 | G13: 745 | H13: =(G13)*24/(F13/60)/17000*100 -> 43.823529 | J13: 49.3 | K13: =(G13)*0.066 -> 49.17 | L13: =J13-K13 -> 0.13 | M13: =[3]Feb!$AD13 -> 68 | N13: =5+3 -> 8 | P13: =(J13-K13)/J13*100 -> 0.26369168 | Q13: =G13/(E13/60) -> 31.258741 | S13: =SUM('[4]Daily glue FEB'!$H$11) -> 0.016954162
B14: 46058 | C14: 4 | D14: GUINNESS | F14: =[3]Feb!$N74 -> 718 | G14: 2789 | H14: =(G14)*24/(F14/60)/17000*100 -> 32.903162 | J14: =SUM(94,92) -> 186 | K14: =(G14)*0.066 -> 184.074 | L14: =J14-K14 -> 1.926 | M14: =[3]Feb!$AD14 -> 312 | N14: =9+3 -> 12 | P14: =(J14-K14)/J14*100 -> 1.0354839 | Q14: =G14/(E13/60) -> 117.02098 | S14: =SUM('[4]Daily glue FEB'!$H$12) -> 0.023555866
B15: 46058 | C15: 4 | D15: CARIB AMBER | F15: =[3]Feb!$N75 -> 276 | G15: 1967 | H15: =(G15)*24/(F15/60)/17000*100 -> 60.368286 | J15: =SUM(97.5,99.8)-63.7 -> 133.6 | K15: =(G15)*0.066 -> 129.822 | L15: =J15-K15 -> 3.778 | M15: =[3]Feb!$AD15 -> 181 | N15: 2 | P15: =(J15-K15)/J15*100 -> 2.8278443 | Q15: =G15/(E13/60) -> 82.531469 | R15: =((J16+J15)-(K16+K15))/(J16+J15)*100 -> 1.5361674 | S15: =SUM('[4]Daily glue FEB'!$H$13) -> 0.012453482
B16: 46059 | C16: 5 | D16: CARIB AMBER | E16: 1250 | F16: =[3]Feb!$N76 -> 940 | G16: 4736 | H16: =(G16)*24/(F16/60)/17000*100 -> 42.677347 | J16: =SUM(63.7,88,100,92)-28 -> 315.7 | K16: =(G16)*0.066 -> 312.576 | L16: =J16-K16 -> 3.124 | M16: =[3]Feb!$AD16 -> 283 | N16: =3+1 -> 4 | P16: =(J16-K16)/J16*100 -> 0.98954704 | Q16: =G16/(E16/60) -> 227.328 | S16: =SUM('[4]Daily glue FEB'!$H$14:$H$15) -> 0.034392808
B17: 46059 | C17: 5 | D17: SHANDY GINGER | F17: =[3]Feb!$N77 -> 200 | G17: 1262 | H17: =(G17)*24/(F17/60)/17000*100 -> 53.449412 | I17: 8 | J17: =SUM(97.1,99.9)-51.6-57.9 -> 87.5 | K17: =(G17)*0.066 -> 83.292 | L17: =J17-K17 -> 4.208 | M17: =[3]Feb!$AD17 -> 76 | N17: 5 | P17: =(J17-K17)/J17*100 -> 4.8091429 | Q17: =G17/(E16/60) -> 60.576 | S17: =SUM('[4]Daily glue FEB'!$H$16) -> 0.017362569
B18: 46062 | C18: 6 | D18: SHANDY GINGER ( LOCAL) | E18: 1380 | F18: =[3]Feb!$N78 -> 165 | G18: 960 | H18: =(G18)*24/(F18/60)/17000*100 -> 49.283422 | J18: =SUM(51.6,57.8) -> 109.4 | K18: =(G18+G19)*0.066 -> 106.656 | L18: =J18-K18 -> 2.744 | M18: =[3]Feb!$AD18 -> 176 | N18: =4+3 -> 7 | P18: =(J18-K18)/J18*100 -> 2.5082267 | Q18: =G18/(E18/60) -> 41.73913 | S18: =SUM('[4]Daily glue FEB'!$H$17:$H$18) -> 0.037372016
B19: 46062 | C19: 6 | D19: SHANDY GINGER (EXPORT) | F19: =[3]Feb!$N79 -> 139 | G19: 656 | H19: =(G19)*24/(F19/60)/17000*100 -> 39.976301 | M19: =[3]Feb!$AD19 -> 36 | Q19: =G19/(E18/60) -> 28.521739
B20: 46062 | C20: 6 | D20: STAG | F20: =[3]Feb!$N80 -> 384 | G20: 2822 | H20: =(G20)*24/(F20/60)/17000*100 -> 62.25 | J20: =SUM(89.4,98.7) -> 188.1 | K20: =(G20)*0.066 -> 186.252 | L20: =J20-K20 -> 1.848 | M20: =[3]Feb!$AD20 -> 363 | N20: 1 | P20: =(J20-K20)/J20*100 -> 0.98245614 | Q20: =G20/(E18/60) -> 122.69565 | S20: =SUM('[4]Daily glue FEB'!$H$19) -> 0.023003273
B21: 46063 | C21: 7 | D21: PINK TING | E21: 1430 | F21: =[3]Feb!$N81 -> 429 | G21: 3371 | H21: =(G21)*24/(F21/60)/17000*100 -> 66.560263 | J21: =3400*0.066 -> 224.4 | K21: =(G21)*0.066 -> 222.486 | L21: =J21-K21 -> 1.914 | M21: =[3]Feb!$AD21 -> 294 | N21: 4 | P21: =(J21-K21)/J21*100 -> 0.85294118 | Q21: =G21/(E21/60) -> 141.44056 | S21: =SUM('[4]Daily glue FEB'!$H$20) -> 0.019419689
B22: 46063 | C22: 7 | D22: GREEN TING | F22: =[3]Feb!$N82 -> 272 | G22: 1790 | H22: =(G22)*24/(F22/60)/17000*100 -> 55.743945 | J22: =1800*0.066 -> 118.8 | K22: =(G22)*0.066 -> 118.14 | L22: =J22-K22 -> 0.66 | M22: =[3]Feb!$AD22 -> 190 | N22: =2+3 -> 5 | P22: =(J22-K22)/J22*100 -> 0.55555556 | Q22: =G22/(E21/60) -> 75.104895 | S22: =SUM('[4]Daily glue FEB'!$H$21) -> 0.022426999
B23: 46063 | C23: 7 | D23: CARIB AMBER | F23: =[3]Feb!$N83 -> 332 | G23: 1854 | H23: =(G23)*24/(F23/60)/17000*100 -> 47.302622 | J23: =SUM(95,97.2)-65 -> 127.2 | K23: =(G23)*0.066 -> 122.364 | L23: =J23-K23 -> 4.836 | M23: =[3]Feb!$AD23 -> 117 | N23: =1+2 -> 3 | P23: =(J23-K23)/J23*100 -> 3.8018868 | Q23: =G23/(E21/60) -> 77.79021 | R23: =((J24+J23)-(K24+K23))/(J24+J23)*100 -> 3.4779138 | S23: =SUM('[4]Daily glue FEB'!$H$22) -> 0.028641921
B24: 46064 | C24: 8 | D24: CARIB AMBER | E24: 1435 | F24: =[3]Feb!$N84 -> 557 | G24: 3521 | H24: =(G24)*24/(F24/60)/17000*100 -> 53.545675 | J24: =SUM(65,97,86.6) -> 248.6 | K24: =(G24)*0.066 +(42*0.19) -> 240.366 | L24: =J24-K24 -> 8.234 | M24: =[3]Feb!$AD24 -> 119 | N24: 4 | O24: 42 | P24: =(J24-K24)/J24*100 -> 3.312148 | Q24: =G24/(E24/60) -> 147.21951 | S24: =SUM('[4]Daily glue FEB'!$H$23) -> 0.015627085
B25: 46064 | C25: 8 | D25: STAG | F25: =[3]Feb!$N85 -> 659 | G25: 3377 | H25: =(G25)*24/(F25/60)/17000*100 -> 43.406945 | I25: 25 | J25: =SUM(98,92.8,90.4,86.4)-66.8-64.9 -> 235.9 | K25: =(G25)*0.066+(33*0.19) -> 229.152 | L25: =J25-K25 -> 6.748 | M25: =[3]Feb!$AD25 -> 401 | O25: 33 | P25: =(J25-K25)/J25*100 -> 2.8605341 | Q25: =G25/(E24/60) -> 141.19861 | R25: =((J26+J25)-(K26+K25))/(J26+J25)*100 -> 1.7583851 | S25: =SUM([4]!Table1456782[[#This Row],[Glue usage lb/ case]]) -> 0.034268548
B26: 46065 | C26: 9 | D26: STAG | E26: 1430 | F26: =[3]Feb!$N86 -> 1320 | G26: 6114 | H26: =(G26)*24/(F26/60)/17000*100 -> 39.234225 | J26: =SUM(66.8,64.9,101,90,88,90.1)-45-47.7 -> 408.1 | K26: =(G26)*0.066 -> 403.524 | L26: =J26-K26 -> 4.576 | M26: =[3]Feb!$AD26 -> 580 | N26: =21+6+5 -> 32 | P26: =(J26-K26)/J26*100 -> 1.1212938 | Q26: =G26/(E26/60) -> 256.53147 | S26: =SUM('[4]Daily glue FEB'!$H$26:$H$28) -> 0.068275709
B27: 46066 | C27: 10 | D27: STAG | E27: 1260 | F27: =[3]Feb!$N87 -> 236 | G27: 1392 | H27: =(G27)*24/(F27/60)/17000*100 -> 49.962114 | J27: =SUM(45,47.7) -> 92.7 | K27: =(G27)*0.066 -> 91.872 | L27: =J27-K27 -> 0.828 | M27: =[3]Feb!$AD27 -> 49 | N27: 2 | P27: =(J27-K27)/J27*100 -> 0.89320388 | Q27: =G27/(E27/60) -> 66.285714 | S27: =SUM('[4]Daily glue FEB'!$H$29) -> 0.024451983
B28: 46066 | C28: 10 | D28: SHANDY SORREL | F28: =[3]Feb!$N88 -> 229 | G28: 1464 | H28: =(G28)*24/(F28/60)/17000*100 -> 54.152582 | J28: =SUM(83.3,90.5)-75.5 -> 98.3 | K28: =(G28)*0.066 -> 96.624 | L28: =J28-K28 -> 1.676 | M28: =[3]Feb!$AD28 -> 794 | N28: 6 | P28: =(J28-K28)/J28*100 -> 1.7049847 | Q28: =G28/(E27/60) -> 69.714286
B29: 46069 | C29: 11 | D29: CARIB AMBER | E29: 1380 | F29: =[3]Feb!$N89 -> 711 | G29: 4596 | H29: =(G29)*24/(F29/60)/17000*100 -> 54.755026 | J29: =SUM(64,95.7,93.2,95.5)-35.4 -> 313 | K29: =(G29)*0.066+(25*0.19) -> 308.086 | L29: =J29-K29 -> 4.914 | M29: =[3]Feb!$AD29 -> 736 | N29: =5+5 -> 10 | O29: 25 | P29: =(J29-K29)/J29*100 -> 1.5699681 | Q29: =G29/(E29/60) -> 199.82609 | R29: =((J30+J29)-(K30+K29))/(J30+J29)*100 -> 2.0494505 | S29: =SUM('[4]Daily glue FEB'!$H$33:$H$34) -> 0.036233573
B30: 46070 | C30: 12 | D30: CARIB AMBER | E30: 1440 | F30: =[3]Feb!$N90 -> 528 | G30: 2895 | H30: =(G30)*24/(F30/60)/17000*100 -> 46.44385 | J30: =SUM(35.4,98,84.7,91.4)-56.5-56.4 -> 196.6 | K30: =(G30)*0.066 -> 191.07 | L30: =J30-K30 -> 5.53 | M30: =[3]Feb!$AD30 -> 1019 | N30: =7+6 -> 13 | P30: =(J30-K30)/J30*100 -> 2.8128179 | Q30: =G30/(E30/60) -> 120.625 | S30: =SUM('[4]Daily glue FEB'!$H$35:$H$36) -> 0.037881578
B31: 46071 | D31: WASHER BREAKDOWN | F31: =[3]Feb!$N91 -> 0 | H31: =(G31)*24/(F31/60)/17000*100 -> #DIV/0! | K31: =(G31)*0.066 -> 0 | L31: =J31-K31 -> 0 | M31: =[3]Feb!$AD31 -> 1440 | P31: =(J31-K31)/J31*100 -> #DIV/0! | Q31: =G31/(F31/60) -> #DIV/0!
B32: 46072 | C32: 13 | D32: CARIB AMBER | E32: 1440 | F32: =[3]Feb!$N92 -> 749 | G32: 3122 | H32: =(G32)*24/(F32/60)/17000*100 -> 35.307312 | J32: =SUM(56.4,56.5,98.8) -> 211.7 | K32: =(G32)*0.066+ (18*0.19) -> 209.472 | L32: =J32-K32 -> 2.228 | M32: =[3]Feb!$AD32 -> 461 | N32: =2+1 -> 3 | O32: 18 | P32: =(J32-K32)/J32*100 -> 1.0524327 | Q32: =G32/(E32/60) -> 130.08333 | S32: =SUM('[4]Daily glue FEB'!$H$42:$H$43) -> 0.038471951
B33: 46072 | C33: 13 | D33: SHANDY SORREL ( LOCAL ) | F33: =[3]Feb!$N93 -> 243 | G33: 1121 | H33: =(G33)*24/(F33/60)/17000*100 -> 39.076253 | J33: =75.5 -> 75.5 | K33: =(G33)*0.066 -> 73.986 | L33: =J33-K33 -> 1.514 | M33: =[3]Feb!$AD33 -> 116 | N33: 4 | P33: =(J33-K33)/J33*100 -> 2.005298 | Q33: =G33/(E32/60) -> 46.708333 | S33: =SUM('[4]Daily glue FEB'!$H$44)/2 -> 0.008957935
B34: 46072 | C34: 13 | D34: TING ORIGINAL | F34: =[3]Feb!$N94 -> 154 | G34: 437 | H34: =(G34)*24/(F34/60)/17000*100 -> 24.036669 | J34: =450*0.066 -> 29.7 | K34: =(G34)*0.066 -> 28.842 | L34: =J34-K34 -> 0.858 | M34: =[3]Feb!$AD34 -> 180 | N34: 3 | P34: =(J34-K34)/J34*100 -> 2.8888889 | Q34: =G34/(E32/60) -> 18.208333 | S34: =SUM('[4]Daily glue FEB'!$H$44)/2 -> 0.008957935
B35: 46073 | C35: 14 | D35: TING ORIGINAL | E35: 1260 | F35: =[3]Feb!$N95 -> 439 | G35: 1334 | H35: =(G35)*24/(F35/60)/17000*100 -> 25.739783 | J35: =1350*0.066 -> 89.1 | K35: =(G35)*0.066 -> 88.044 | L35: =J35-K35 -> 1.056 | M35: =[3]Feb!$AD35 -> 178 | N35: 1 | P35: =(J35-K35)/J35*100 -> 1.1851852 | Q35: =G35/(E35/60) -> 63.52381 | S35: =SUM('[4]Daily glue FEB'!$H$46) -> 0.017384045
B36: 46073 | C36: 14 | D36: CARIB AMBER | F36: =[3]Feb!$N96 -> 557 | G36: 2454 | H36: =(G36)*24/(F36/60)/17000*100 -> 37.319252 | J36: =SUM(99.5,94.9)-26.4 -> 168 | K36: =(G36)*0.066 -> 161.964 | L36: =J36-K36 -> 6.036 | M36: =[3]Feb!$AD36 -> 394 | N36: =3+2 -> 5 | P36: =(J36-K36)/J36*100 -> 3.5928571 | Q36: =G36/(E35/60) -> 116.85714 | S36: =SUM('[4]Daily glue FEB'!$H$47) -> 0.016099656
B37: 46076 | C37: 15 | D37: CARIB AMBER | E37: 1380 | F37: =[3]Feb!$N97 -> 703 | G37: 3491 | H37: =(G37)*24/(F37/60)/17000*100 -> 42.06376 | J37: =SUM(26.4,86,92.2,87.8)-56.8 -> 235.6 | K37: =(G37)*0.066 -> 230.406 | L37: =J37-K37 -> 5.194 | M37: =[3]Feb!$AD37 -> 876 | N37: =2+2 -> 4 | P37: =(J37-K37)/J37*100 -> 2.204584 | Q37: =G37/(E37/60) -> 151.78261 | S37: =SUM('[4]Daily glue FEB'!$H$49,'[4]Daily glue FEB'!$H$50) -> 0.042270613 | AE37: =18*0.19 -> 3.42
B38: 46077 | C38: 16 | D38: CARIB AMBER | E38: 1428 | F38: =[3]Feb!$N98 -> 335 | G38: 2250 | H38: =(G38)*24/(F38/60)/17000*100 -> 56.892011 | J38: =SUM(38.6,56.8,54.1) -> 149.5 | K38: =(G38)*0.066 -> 148.5 | L38: =J38-K38 -> 1 | M38: =[3]Feb!$AD38 -> 88 | N38: =8+3 -> 11 | P38: =(J38-K38)/J38*100 -> 0.66889632 | Q38: =G38/(E38/60) -> 94.537815 | S38: =SUM('[4]Daily glue FEB'!$H$51) -> 0.012021628 | AE38: =50-AE37 -> 46.58
B39: 46077 | C39: 16 | D39: GUINNESS | F39: =[3]Feb!$N99 -> 962 | G39: 2892 | H39: =(G39)*24/(F39/60)/17000*100 -> 25.464596 | J39: =SUM(90.2,98.9,2) -> 191.1 | K39: =(G39)*0.066 -> 190.872 | L39: =J39-K39 -> 0.228 | M39: =[3]Feb!$AD39 -> 550 | N39: 4 | P39: =(J39-K39)/J39*100 -> 0.11930926 | Q39: =G39/(E38/60) -> 121.51261 | S39: =SUM('[4]Daily glue FEB'!$H$53) -> 0.01688723
B40: 46078 | C40: 17 | D40: STAG | E40: 1440 | F40: =[3]Feb!$N100 -> 1415 | G40: 4008 | H40: =(G40)*24/(F40/60)/17000*100 -> 23.993016 | I40: 140 | J40: =SUM(97,93.8,90,93.3)-53.2-53.8 -> 267.1 | K40: =(G40)*0.066 -> 264.528 | L40: =J40-K40 -> 2.572 | M40: =[3]Feb!$AD40 -> 810 | N40: =5+5+2 -> 12 | P40: =(J40-K40)/J40*100 -> 0.96293523 | Q40: =G40/(E40/60) -> 167 | S40: =SUM('[4]Daily glue FEB'!$H$54:$H$56) -> 0.04864426
B41: 46079 | C41: 18 | D41: STAG | E41: 1440 | F41: =[3]Feb!$N101 -> 1027 | G41: 1613 | H41: =(G41)*24/(F41/60)/17000*100 -> 13.303855 | J41: =SUM(53.2,53.8) -> 107 | K41: =(G41)*0.066 -> 106.458 | L41: =J41-K41 -> 0.542 | M41: =[3]Feb!$AD41 -> 815 | N41: =2+4 -> 6 | P41: =(J41-K41)/J41*100 -> 0.50654206 | Q41: =G41/(E41/60) -> 67.208333 | S41: =SUM('[4]Daily glue FEB'!$H$57:$H$58) -> 0.061097819
...

Sheet March_2026
B1: GRENADA BREWERIES LIMITED
B3: PRODUCTION DEPARTMENT
B4: 46082
B5: DATE | C5: DAY | D5: PRODUCT | E5: AVAIL. | F5: FILL | G5: CASES | H5: Line Rated | I5: Cases on Hold | J5: BBT | K5: BOTTLED | L5: Diff BBT Hls vs Hls in Package | M5: DOWNTIME (Mins) | N5: REJECTS (Cases) | O5: KEGS | P5: BOTTLED | Q5: AVERAGE | R5: YTD | S5: Glue | T5: AVG
E6: TIME | F6: TIME | G6: BOTTLED | H6: Efficiency | J6: HLS | K6: HLS | P6: LOSS | Q6: CASE/HR | R6: Ave Case per hour | S6: Usage | T6: CASE PER
F7: Mins | H7: % | Q7: Avail Time | S7: lbs/case | T7: DAY
B8: 46083 | C8: 1 | D8: CARIB AMBER | E8: 1380 | F8: =[3]Mar!$N69 -> 297 | G8: 1308 | H8: =(G8)*24/(F8/60)/17000*100 -> 37.304813 | J8: =SUM(88) -> 88 | K8: =(G8)*0.066 -> 86.328 | L8: =J8-K8 -> 1.672 | M8: =[3]Mar!$AD8 -> 154 | N8: 8 | P8: =(J8-K8)/J8*100 -> 1.9 | Q8: =(G8)/(E8/60) -> 56.869565 | S8: ='[4]Daily glue MAR'!$H$2 -> 0.014283537
B9: 46083 | C9: 1 | D9: STAG | F9: =[3]Mar!$N70 -> 976 | G9: 5279 | H9: =(G9)*24/(F9/60)/17000*100 -> 45.815815 | J9: =SUM(88,94,57,60,101.8)-46.7 -> 354.1 | K9: =(G9)*0.066 -> 348.414 | L9: =J9-K9 -> 5.686 | M9: =[3]Mar!$AD9 -> 327 | N9: 1 | P9: =(J9-K9)/J9*100 -> 1.6057611 | Q9: =(G9)/(E8/60) -> 229.52174 | S9: =SUM('[4]Daily glue MAR'!$H$3:$H$4) -> 0.040099105
B10: 46084 | C10: 2 | D10: STAG | E10: 1440 | F10: =[3]Mar!$N71 -> 1338 | G10: 6137 | H10: =(G10)*24/(F10/60)/17000*100 -> 38.852018 | J10: =SUM(46.7,99.2,100.4,104,76,64)-75.3 -> 415 | K10: =(G10)*0.066+(21*0.19) -> 409.032 | L10: =J10-K10 -> 5.968 | M10: =[3]Mar!$AD10 -> 513 | N10: =4.5+2+8 -> 14.5 | O10: 21 | P10: =(J10-K10)/J10*100 -> 1.4380723 | Q10: =(G10)/(E10/60) -> 255.70833 | S10: =SUM('[4]Daily glue MAR'!$H$5,'[4]Daily glue MAR'!$H$7) -> 0.032425381
B11: 46085 | C11: 3 | D11: STAG | E11: 1440 | F11: =[3]Mar!$N72 -> 509 | G11: 2653 | H11: =(G11)*24/(F11/60)/17000*100 -> 44.150237 | J11: =SUM(75.3,101) -> 176.3 | K11: =(G11)*0.066 -> 175.098 | L11: =J11-K11 -> 1.202 | M11: =[3]Mar!$AD11 -> 187 | N11: 4 | P11: =(J11-K11)/J11*100 -> 0.6817924 | Q11: =(G11)/(E11/60) -> 110.54167 | S11: =SUM('[4]Daily glue MAR'!$H$8) -> 0.013019917
B12: 46085 | C12: 3 | D12: CARIB AMBER | F12: =[3]Mar!$N73 -> 751 | G12: 3701 | H12: =(G12)*24/(F12/60)/17000*100 -> 41.743871 | I12: =2*70 -> 140 | J12: =SUM(90,97.8,99)-32.1 -> 254.7 | K12: =(G12)*0.066+(27*0.19) -> 249.396 | L12: =J12-K12 -> 5.304 | M12: =[3]Mar!$AD12 -> 332 | O12: 27 | P12: =(J12-K12)/J12*100 -> 2.0824499 | Q12: =(G12)/(E11/60) -> 154.20833 | S12: =SUM('[4]Daily glue MAR'!$H$9) -> 0.0090400386
B13: 46086 | C13: 4 | D13: CARIB AMBER | E13: 1435 | F13: =[3]Mar!$N74 -> 96 | G13: 481 | H13: =(G13)*24/(F13/60)/17000*100 -> 42.441176 | J13: 32.1 | K13: =(G13)*0.066 -> 31.746 | L13: =J13-K13 -> 0.354 | M13: =[3]Mar!$AD13 -> 19 | N13: 4 | P13: =(J13-K13)/J13*100 -> 1.1028037 | Q13: =(G13)/(E13/60) -> 20.111498 | S13: =SUM('[4]Daily glue MAR'!$H$11) -> 0.013752446
B14: 46086 | C14: 4 | D14: VITA MALT CLASSIC | F14: =[3]Mar!$N75 -> 825 | G14: 3488 | H14: =(G14)*24/(F14/60)/17000*100 -> 35.81262 | J14: =SUM(99,98,75,100)-50-72.9 -> 249.1 | K14: =(G14)*0.0708 -> 246.9504 | L14: =J14-K14 -> 2.1496 | M14: =[3]Mar!$AD14 -> 710 | N14: =10+3 -> 13 | P14: =(J14-K14)/J14*100 -> 0.86294661 | Q14: =(G14)/(E13/60) -> 145.83972 | S14: =SUM('[4]Daily glue MAR'!$H$12,'[4]Daily glue MAR'!$H$13) -> 0.031214123 | T14: =((J14+J15+J16)-(K15+K14+K16))/(J14+J15+J16)*100 -> 0.89903226
B15: 46087 | C15: 5 | D15: VITA MALT CLASSIC | E15: 1260 | F15: =[3]Mar!$N76 -> 366 | G15: 1015 | H15: =(G15)*24/(F15/60)/17000*100 -> 23.490839 | J15: 72.9 | K15: =(G15)*0.0708 -> 71.862 | L15: =J15-K15 -> 1.038 | M15: =[3]Mar!$AD15 -> 194 | N15: 3 | P15: =(J15-K15)/J15*100 -> 1.4238683 | Q15: =(G15)/(E15/60) -> 48.333333 | S15: =SUM('[4]Daily glue MAR'!$H$14) -> 0.029232529
B16: 46087 | C16: 5 | D16: VITA MALT GINGER | F16: =[3]Mar!$N77 -> 163 | G16: 704 | H16: =(G16)*24/(F16/60)/17000*100 -> 36.584626 | J16: 50 | K16: =(G16)*0.0708 -> 49.8432 | L16: =J16-K16 -> 0.1568 | M16: =[3]Mar!$AD16 -> 80 | N16: 1 | P16: =(J16-K16)/J16*100 -> 0.3136 | Q16: =(G16)/(E15/60) -> 33.52381 | S16: =SUM('[4]Daily glue MAR'!$H$15) -> 0.021649723
B17: 46087 | C17: 6 | D17: GUINNESS | F17: =[3]Mar!$N78 -> 512 | G17: 2795 | H17: =(G17)*24/(F17/60)/17000*100 -> 46.240809 | J17: =SUM(90.6,94) -> 184.6 | K17: =(G17)*0.066 -> 184.47 | L17: =J17-K17 -> 0.13 | M17: =[3]Mar!$AD17 -> 229 | N17: 2 | P17: =(J17-K17)/J17*100 -> 0.070422535 | Q17: =(G17)/(E15/60) -> 133.09524 | S17: =SUM('[4]Daily glue MAR'!$H$16) -> 0.0097118574
B18: 46089 | C18: 7 | D18: CARIB AMBER | E18: 970 | F18: =[3]Mar!$N79 -> 621 | G18: 3630 | H18: =(G18)*24/(F18/60)/17000*100 -> 49.514066 | J18: =SUM(93,94.4,89.3,86.5)-89-26 -> 248.2 | K18: =(G18)*0.066 -> 239.58 | L18: =J18-K18 -> 8.62 | M18: =[3]Mar!$AD18 -> 417 | N18: =2+6 -> 8 | P18: =(J18-K18)/J18*100 -> 3.4730056 | Q18: =(G18)/(E18/60) -> 224.53608 | S18: =SUM('[4]Daily glue MAR'!$H$17:$H$18) -> 0.046600172
B19: 46090 | C19: 8 | D19: CARIB AMBER | E19: 1440 | F19: =[3]Mar!$N80 -> 936 | G19: 5423 | H19: =(G19)*24/(F19/60)/17000*100 -> 49.076923 | J19: =SUM(99.5,97.5,89,26,64.5,97.8)-7.8-101.1 -> 365.4 | K19: =(G19)*0.066 -> 357.918 | L19: =J19-K19 -> 7.482 | M19: =[3]Mar!$AD19 -> 682 | N19: =4+1 -> 5 | P19: =(J19-K19)/J19*100 -> 2.047619 | Q19: =(G19)/(E19/60) -> 225.95833 | S19: =SUM('[4]Daily glue MAR'!$H$19:$H$21) -> 0.068556182
B20: 46091 | C20: 9 | D20: CARIB AMBER | E20: 1429 | F20: =[3]Mar!$N81 -> 974 | G20: 5844 | H20: =(G20)*24/(F20/60)/17000*100 -> 50.823529 | J20: =SUM(101.1,7.8,90.5,95.3,93) -> 387.7 | K20: =(G20)*0.066 -> 385.704 | L20: =J20-K20 -> 1.996 | M20: =[3]Mar!$AD20 -> 235 | N20: =5+16 -> 21 | P20: =(J20-K20)/J20*100 -> 0.51483105 | Q20: =(G20)/(E20/60) -> 245.37439 | S20: =SUM('[4]Daily glue MAR'!$H$22:$H$23) -> 0.033044631
B21: 46091 | C21: 9 | D21: CARIBE PERSSECO (LOCAL ) | F21: =[3]Mar!$N82 -> 248 | G21: 1112 | H21: =(G21)*24/(F21/60)/17000*100 -> 37.981025 | J21: =SUM(78.8,76.2)-76 -> 79 | K21: =(G21)*0.066 -> 73.392 | L21: =J21-K21 -> 5.608 | M21: =[3]Mar!$AD21 -> 226 | N21: 1 | P21: =(J21-K21)/J21*100 -> 7.0987342 | Q21: =(G21)/(E20/60) -> 46.689993 | S21: ='[4]Daily glue MAR'!$H$24 -> 0.014531638
B22: 46092 | C22: 10 | D22: CARIBE PERSSECO (LOCAL ) | E22: 1440 | F22: =[3]Mar!$N83 -> 261 | G22: 1118 | H22: =(G22)*24/(F22/60)/17000*100 -> 36.283976 | J22: 76 | K22: =(G22)*0.066 -> 73.788 | L22: =J22-K22 -> 2.212 | M22: =[3]Mar!$AD22 -> 74 | P22: =(J22-K22)/J22*100 -> 2.9105263 | Q22: =(G22)/(E22/60) -> 46.583333 | S22: ='[4]Daily glue MAR'!$H$25 -> 0.024503138
B23: 46092 | C23: 10 | D23: CARIBE ROSE (LOCAL) | F23: =[3]Mar!$N84 -> 462 | G23: 2182 | H23: =(G23)*24/(F23/60)/17000*100 -> 40.006112 | J23: =SUM(78,72) -> 150 | K23: =(G23)*0.066 -> 144.012 | L23: =J23-K23 -> 5.988 | M23: =[3]Mar!$AD23 -> 178 | N23: 11 | P23: =(J23-K23)/J23*100 -> 3.992 | Q23: =(G23)/(E22/60) -> 90.916667 | S23: ='[4]Daily glue MAR'!$H$26 -> 0.037945464
B24: 46092 | C24: 10 | D24: STAG | F24: =[3]Mar!$N85 -> 493 | G24: 3015 | H24: =(G24)*24/(F24/60)/17000*100 -> 51.802887 | J24: =SUM(97.2,81,97.4,94.8)-74-90.5 -> 205.9 | K24: =(G24)*0.066+(19*0.19) -> 202.6 | L24: =J24-K24 -> 3.3 | M24: =[3]Mar!$AD24 -> 272 | O24: 19 | P24: =(J24-K24)/J24*100 -> 1.6027198 | Q24: =(G24)/(E22/60) -> 125.625 | S24: ='[4]Daily glue MAR'!$H$27 -> 0.014992 | T24: =((J25+J24)-(K25+K24))/(J25+J24)*100 -> 1.2998205
B25: 46093 | C25: 11 | D25: STAG | E25: 1428 | F25: =[3]Mar!$N86 -> 811 | G25: 5260 | H25: =(G25)*24/(F25/60)/17000*100 -> 54.93871 | J25: =SUM(86.8,74,99.8,90.5) -> 351.1 | K25: =(G25)*0.066 -> 347.16 | L25: =J25-K25 -> 3.94 | M25: =[3]Mar!$AD25 -> 152 | N25: =6+3 -> 9 | P25: =(J25-K25)/J25*100 -> 1.1221874 | Q25: =(G25)/(E25/60) -> 221.0084 | S25: =SUM('[4]Daily glue MAR'!$H$28:$H$29) -> 0.045389626
B26: 46093 | C26: 11 | D26: STAR MALT | F26: =[3]Mar!$N87 -> 480 | G26: 2548 | H26: =(G26)*24/(F26/60)/17000*100 -> 44.964706 | J26: =SUM(90.6,95.2,91.4)-99.8-7 -> 170.4 | K26: =(G26)*0.066 -> 168.168 | L26: =J26-K26 -> 2.232 | M26: =[3]Mar!$AD26 -> 218 | N26: 3 | P26: =(J26-K26)/J26*100 -> 1.3098592 | Q26: =(G26)/(E25/60) -> 107.05882 | S26: =SUM('[4]Daily glue MAR'!$H$30) -> 0.012930083 | T26: =((J27+J26)-(K27+K26))/(J27+J26)*100 -> 2.2347514
B27: 46094 | C27: 12 | D27: STAR MALT | E27: 1250 | F27: =[3]Mar!$N88 -> 665 | G27: 3232 | H27: =(G27)*24/(F27/60)/17000*100 -> 41.168333 | J27: =SUM(17.8,95.2,99.8,7) -> 219.8 | K27: =(G27)*0.066 -> 213.312 | L27: =J27-K27 -> 6.488 | M27: =[3]Mar!$AD27 -> 244 | N27: =5+2 -> 7 | P27: =(J27-K27)/J27*100 -> 2.9517743 | Q27: =(G27)/(E27/60) -> 155.136 | S27: =SUM('[4]Daily glue MAR'!$H$31) -> 0.011791107
B28: 46094 | C28: 12 | D28: GUINNESS | F28: =[3]Mar!$N89 -> 250 | G28: 1462 | H28: =(G28)*24/(F28/60)/17000*100 -> 49.536 | J28: =SUM(91,92.7)-10.1-77.1 -> 96.5 | K28: =(G28)*0.066 -> 96.492 | L28: =J28-K28 -> 0.008 | M28: =[3]Mar!$AD28 -> 350 | N28: 5 | P28: =(J28-K28)/J28*100 -> 0.0082901554 | Q28: =(G28)/(E27/60) -> 70.176 | S28: =SUM('[4]Daily glue MAR'!$H$33) -> 0.019227086
B29: 46097 | C29: 13 | D29: GUINNESS | E29: 1380 | F29: =[3]Mar!$N90 -> 286 | G29: 1735 | H29: =(G29)*24/(F29/60)/17000*100 -> 51.386261 | J29: =SUM(10.1,77.1,91,89)-77.6-75 -> 114.6 | K29: =(G29)*0.066 -> 114.51 | L29: =J29-K29 -> 0.09 | M29: =[3]Mar!$AD29 -> 1109 | N29: =5+1 -> 6 | P29: =(J29-K29)/J29*100 -> 0.078534031 | Q29: =(G29)/(E29/60) -> 75.434783 | S29: =SUM('[4]Daily glue MAR'!$H$34) -> 0.022578313
B30: 46098 | D30: WASHER BREAKDOWN | F30: =[3]Mar!$N91 -> 0 | H30: =(G30)*24/(F30/60)/17000*100 -> #DIV/0! | K30: =(G30)*0.066 -> 0 | L30: =J30-K30 -> 0 | M30: =[3]Mar!$AD30 -> 1440 | P30: =(J30-K30)/J30*100 -> #DIV/0! | Q30: =(G30)/(E30/60) -> #DIV/0!
B31: 46099 | C31: 14 | D31: GUINNESS | E31: 1440 | F31: =[3]Mar!$N92 -> 427 | G31: 2353 | H31: =(G31)*24/(F31/60)/17000*100 -> 46.677504 | J31: =SUM(77.6,75,3) -> 155.6 | K31: =(G31)*0.066 -> 155.298 | L31: =J31-K31 -> 0.302 | M31: =[3]Mar!$AD31 -> 605 | N31: =2+2 -> 4 | P31: =(J31-K31)/J31*100 -> 0.1940874 | Q31: =(G31)/(E31/60) -> 98.041667
B32: 46099 | C32: 14 | D32: CARIB AMBER | F32: =[3]Mar!$N93 -> 435 | G32: 3171 | H32: =(G32)*24/(F32/60)/17000*100 -> 61.747667 | J32: =SUM(77,99,88.5,99)-70.5-79 -> 214 | K32: =(G32)*0.066 -> 209.286 | L32: =J32-K32 -> 4.714 | M32: =[3]Mar!$AD32 -> 133 | N32: 6 | O32: =61+39 -> 100 | P32: =(J32-K32)/J32*100 -> 2.2028037 | Q32: =(G32)/(E31/60) -> 132.125 | S32: ='[4]Daily glue MAR'!$H$42 -> 0.015865222
B33: 46100 | C33: 15 | D33: CARIB AMBER | E33: 1430 | F33: =[3]Mar!$N94 -> 938 | G33: 7581 | H33: =(G33)*24/(F33/60)/17000*100 -> 68.460053 | J33: =SUM(81,70.5,79,93.5,95.7,98.4,95.8,94,91.6)-61.3 -> 738.2 | K33: =(G33+G34+G35)*0.066 -> 726.528 | L33: =J33-K33 -> 11.672 | M33: =[3]Mar!$AD33 -> 129 | N33: =8+2+2 -> 12 | P33: =(J33-K33)/J33*100 -> 1.5811433 | Q33: =(G33)/(E33/60) -> 318.08392 | S33: =SUM('[4]Daily glue MAR'!$H$43) -> 0.011107745
B34: 46100 | C34: 15 | D34: CARIB FLINT (LOC) | F34: =[3]Mar!$N95 -> 190 | G34: 1529 | H34: =(G34)*24/(F34/60)/17000*100 -> 68.165944 | M34: =[3]Mar!$AD34 -> 58 | Q34: =(G34)/(E33/60) -> 64.153846 | S34: =SUM('[4]Daily glue MAR'!$H$45) -> 0.021760929
B35: 46100 | C35: 15 | D35: CARIB AMBER | F35: =[3]Mar!$N96 -> 221 | G35: 1898 | H35: =(G35)*24/(F35/60)/17000*100 -> 72.747405 | M35: =[3]Mar!$AD35 -> 53 | Q35: =(G35)/(E33/60) -> 79.636364
B36: 46101 | C36: 16 | D36: CARIB AMBER | E36: 1250 | F36: =[3]Mar!$N97 -> 696 | G36: 5065 | H36: =(G36)*24/(F36/60)/17000*100 -> 61.643002 | J36: =SUM(61.3,85.2,73.7,74,43.5) -> 337.7 | K36: =(G36)*0.066 -> 334.29 | L36: =J36-K36 -> 3.41 | M36: =[3]Mar!$AD36 -> 160 | N36: =4+3 -> 7 | P36: =(J36-K36)/J36*100 -> 1.009772 | Q36: =(G36)/(E36/60) -> 243.12 | S36: =SUM('[4]Daily glue MAR'!$H$46:$H$47) -> 0.046303006
B37: 46101 | C37: 16 | D37: STAG | F37: =[3]Mar!$N98 -> 322 | G37: 2325 | H37: =(G37)*24/(F37/60)/17000*100 -> 61.161856 | I37: =350+48 -> 398 | J37: =SUM(72,76,28.6)-20.8 -> 155.8 | K37: =(G37)*0.066 -> 153.45 | L37: =J37-K37 -> 2.35 | M37: =[3]Mar!$AD37 -> 163 | N37: 11 | P37: =(J37-K37)/J37*100 -> 1.508344 | Q37: =(G37)/(E36/60) -> 111.6 | S37: =SUM('[4]Daily glue MAR'!$H$48) -> 0.026426269
B38: 46104 | C38: 17 | D38: STAG | E38: 1380 | F38: =[3]Mar!$N99 -> 533 | G38: 4172 | H38: =(G38)*24/(F38/60)/17000*100 -> 66.302616 | J38: =SUM(96.3,86.3,103) -> 285.6 | K38: =(G38)*0.066+(20*0.19) -> 279.152 | L38: =J38-K38 -> 6.448 | M38: =[3]Mar!$AD38 -> 127 | N38: =7+3 -> 10 | O38: 20 | P38: =(J38-K38)/J38*100 -> 2.2577031 | Q38: =(G38)/(E38/60) -> 181.3913 | S38: =SUM('[4]Daily glue MAR'!$H$49) -> 0.024631966
B39: 46104 | C39: 17 | D39: CARIB AMBER | F39: =[3]Mar!$N100 -> 378 | G39: 2915 | H39: =(G39)*24/(F39/60)/17000*100 -> 65.322129 | J39: =SUM(94,89.6,96,96)-14 -> 361.6 | K39: =(G39+G40)*0.066+(79*0.19) -> 352.732 | L39: =J39-K39 -> 8.868 | M39: =[3]Mar!$AD39 -> 72 | N39: 15 | O39: 79 | P39: =(J39-K39)/J39*100 -> 2.4524336 | Q39: =(G39)/(E38/60) -> 126.73913
B40: 46104 | C40: 17 | D40: CARIB FLINT (LOC) | F40: =[3]Mar!$N101 -> 312 | G40: 2202 | H40: =(G40)*24/(F40/60)/17000*100 -> 59.782805 | M40: =[3]Mar!$AD40 -> 74 | N40: 5 | Q40: =(G40)/(E38/60) -> 95.73913
B41: 46105 | C41: 18 | D41: SHANDY CARIB GINGER (EXPORT) | E41: 1440 | F41: =[3]Mar!$N102 -> 243 | G41: 230 | H41: =(G41+G42)*24/(F41/60)/17000*100 -> 49.010893 | J41: =SUM(96.5) -> 96.5 | K41: =(G41+G42)*0.066 -> 92.796 | L41: =J41-K41 -> 3.704 | M41: =[3]Mar!$AD41 -> 356 | N41: 10 | P41: =(J41-K41)/J41*100 -> 3.838342 | Q41: =(G41)/(E41/60) -> 9.5833333 | S41: =SUM('[4]Daily glue MAR'!$H$52:$H$53) -> 0.049230065
...

Sheet April_2026 
B1: GRENADA BREWERIES LIMITED
B3: PRODUCTION DEPARTMENT
B4: 46113
B5: DATE | C5: DAY | D5: PRODUCT | E5: AVAIL. | F5: FILL | G5: CASES | H5: Line Rated | I5: Cases on Hold | J5: BBT | K5: BOTTLED | L5: Diff BBT Hls vs Hls in Package | M5: DOWNTIME (Mins) | N5: REJECTS (Cases) | O5: KEGS | P5: BOTTLED | Q5: AVERAGE | R5: YTD | S5: Glue | T5: AVG
E6: TIME | F6: TIME | G6: BOTTLED | H6: Efficiency | J6: HLS | K6: HLS | P6: LOSS | Q6: CASE/HR | R6: Ave Case per hour | S6: Usage | T6: CASE PER
F7: Mins | H7: % | S7: lbs/case | T7: DAY
B8: 46113 | C8: 1 | D8: VITAMALT CLASSIC | E8: 1440 | F8: =[3]Apr!$P62 -> 324 | G8: 2482 | H8: =(G8)*24/(F8/60)/17000*100 -> 64.888889 | J8: =SUM(80.7,95.2) -> 175.9 | K8: =(G8)*0.0708 -> 175.7256 | L8: =J8-K8 -> 0.1744 | M8: =[3]Apr!AD8 -> 50 | P8: =(J8-K8)/J8*100 -> 0.099147243 | Q8: =(G8)/(E8/60) -> 103.41667 | S8: ='[4]Daily glue APR'!$H$2 -> 0.013222013
B9: 46113 | C9: 1 | D9: VITAMALT GINGER | F9: =[3]Apr!$P63 -> 116 | G9: 693 | H9: =(G9)*24/(F9/60)/17000*100 -> 50.604462 | J9: 50 | K9: =(G9)*0.0708 -> 49.0644 | L9: =J9-K9 -> 0.9356 | M9: =[3]Apr!AD9 -> 27 | P9: =(J9-K9)/J9*100 -> 1.8712 | Q9: =(G9)/(E8/60) -> 28.875
B10: 46113 | C10: 1 | D10: PEARSECCO | F10: =[3]Apr!$P64 -> 0 | G10: 0 | H10: =(G10)*24/(F10/60)/17000*100 -> #DIV/0! | K10: =(G10)*0.066 -> 0 | L10: =J10-K10 -> 0 | M10: =[3]Apr!AD10 -> 974 | P10: =(J10-K10)/J10*100 -> #DIV/0! | Q10: =(G10)/(E10/60) -> #DIV/0!
B11: 46114 | C11: 2 | D11: PEARSECCO | E11: 1440 | F11: =[3]Apr!$P65 -> 180 | G11: 166 | H11: =(G11)*24/(F11/60)/17000*100 -> 7.8117647 | J11: =SUM(92)-80.5 -> 11.5 | K11: =(G11)*0.066 -> 10.956 | L11: =J11-K11 -> 0.544 | M11: =[3]Apr!AD11 -> 690 | N11: 14 | P11: =(J11-K11)/J11*100 -> 4.7304348 | Q11: =(G11)/(E11/60) -> 6.9166667 | S11: =SUM('[4]Daily glue APR'!$H$6) -> 0.04685
B12: 46114 | C12: 2 | D12: CARIB AMBER | F12: =[3]Apr!$P66 -> 550 | G12: 2702 | H12: =(G12)*24/(F12/60)/17000*100 -> 41.61369 | I12: 3 | J12: =SUM(94,92,91)-82 -> 195 | K12: =(G12)*0.066+(75*0.19) -> 192.582 | L12: =J12-K12 -> 2.418 | M12: =[3]Apr!AD12 -> 339 | N12: =3+11 -> 14 | O12: 75 | P12: =(J12-K12)/J12*100 -> 1.24 | Q12: =(G12)/(E11/60) -> 112.58333 | S12: =SUM('[4]Daily glue APR'!$H$7) -> 0.017084684
B13: 46119 | C13: 3 | D13: PEARSECCO | E13: 1380 | F13: =[3]Apr!$P67 -> 517 | G13: 1078 | H13: =(G13)*24/(F13/60)/17000*100 -> 17.662078 | I13: =1075+3 -> 1078 | J13: 76 | K13: =(G13)*0.066 -> 71.148 | L13: =J13-K13 -> 4.852 | M13: =[3]Apr!AD13 -> 1047 | N13: 37 | P13: =(J13-K13)/J13*100 -> 6.3842105 | Q13: =(G13)/(E13/60) -> 46.869565 | S13: ='[4]Daily glue APR'!$H$10 -> 0.017384045
B14: 46119 | C14: 3 | D14: CARIB AMBER | F14: =[3]Apr!$P68 -> 10 | G14: 0 | H14: =(G14)*24/(F14/60)/17000*100 -> 0 | K14: =(G14)*0.066 -> 0 | L14: =J14-K14 -> 0 | M14: =[3]Apr!AD14 -> 223 | O14: 43 | P14: =(J14-K14)/J14*100 -> #DIV/0! | Q14: =(G14)/(E14/60) -> #DIV/0!
B15: 46120 | C15: 4 | D15: CARIB AMBER | E15: 1440 | F15: =[3]Apr!$P69 -> 1158 | G15: 8044 | H15: =(G15)*24/(F15/60)/17000*100 -> 58.840597 | J15: =SUM(82,95.4,97,100.3,85.43,92)-14 -> 538.13 | K15: =(G15)*0.066 -> 530.904 | L15: =J15-K15 -> 7.226 | M15: =[3]Apr!AD15 -> 281 | N15: =42+12+5 -> 59 | P15: =(J15-K15)/J15*100 -> 1.3427982 | Q15: =(G15)/(E15/60) -> 335.16667 | S15: =SUM('[4]Daily glue APR'!$H$11:$H$12) -> 0.045436648
B16: 46120 | C16: 4 | D16: STAG | F16: =[3]Apr!$P70 -> 177 | G16: 1089 | H16: =(G16)*24/(F16/60)/17000*100 -> 52.115653 | J16: =SUM(89.8,96.5)-11.2-102 -> 73.1 | K16: =(G16)*0.066 -> 71.874 | L16: =J16-K16 -> 1.226 | M16: =[3]Apr!AD16 -> 110 | N16: 0 | P16: =(J16-K16)/J16*100 -> 1.6771546 | Q16: =(G16)/(E15/60) -> 45.375 | S16: =SUM('[4]Daily glue APR'!$H$13) -> 0.02232588
B17: 38451 | C17: 5 | D17: STAG | E17: 1440 | F17: =[3]Apr!$P71 -> 1399 | G17: 9870 | H17: =(G17)*24/(F17/60)/17000*100 -> 59.760333 | J17: =SUM(69,99.4,11.2,102,90.3,99.5,90,99.9) -> 661.3 | K17: =(G17)*0.066 -> 651.42 | L17: =J17-K17 -> 9.88 | M17: =[3]Apr!AD17 -> 264 | N17: =9+8 -> 17 | P17: =(J17-K17)/J17*100 -> 1.4940269 | Q17: =(G17)/(E17/60) -> 411.25 | S17: =SUM('[4]Daily glue APR'!$H$14,'[4]Daily glue APR'!$H$16) -> 0.042004425
B18: 46122 | C18: 6 | D18: CARIB AMBER | E18: 1260 | F18: =[3]Apr!$P72 -> 1009 | G18: 6477 | H18: =(G18)*24/(F18/60)/17000*100 -> 54.374628 | J18: =SUM(90,97.1,92.5,95,85)-14-11 -> 434.6 | K18: =(G18)*0.066 -> 427.482 | L18: =J18-K18 -> 7.118 | M18: =[3]Apr!AD18 -> 367 | N18: =19+11+4 -> 34 | P18: =(J18-K18)/J18*100 -> 1.6378279 | Q18: =(G18)/(E18/60) -> 308.42857 | S18: =SUM('[4]Daily glue APR'!$H$17,'[4]Daily glue APR'!$H$19) -> 0.047319579
B19: 46125 | C19: 7 | D19: CARIBE ROSE' | E19: 1380 | F19: =[3]Apr!$P73 -> 555 | G19: 2504 | H19: =(G19)*24/(F19/60)/17000*100 -> 38.216852 | J19: =SUM(87,87) -> 174 | K19: =(G19)*0.066 -> 165.264 | L19: =J19-K19 -> 8.736 | M19: =[3]Apr!AD19 -> 324 | N19: 5 | P19: =(J19-K19)/J19*100 -> 5.0206897 | Q19: =(G19)/(E19/60) -> 108.86957 | S19: =SUM('[4]Daily glue APR'!$H$20:$H$21) -> 0.072694995
B20: 46125 | C20: 7 | D20: CARIB AMBER | F20: =[3]Apr!$P74 -> 600 | G20: 3830 | H20: =(G20)*24/(F20/60)/17000*100 -> 54.070588 | J20: =SUM(103.8,91.4,93,97.9)-14-21-92.5 -> 258.6 | K20: =(G20)*0.066 -> 252.78 | L20: =J20-K20 -> 5.82 | M20: =[3]Apr!AD20 -> 245 | N20: =3+2 -> 5 | P20: =(J20-K20)/J20*100 -> 2.25058 | Q20: =(G20)/(E19/60) -> 166.52174
B21: 46126 | C21: 8 | D21: CARIB AMBER | E21: 1440 | F21: =[3]Apr!$P75 -> 477 | G21: 2898 | H21: =(G21)*24/(F21/60)/17000*100 -> 51.462819 | J21: =SUM(95.4,21,92.5)-14 -> 194.9 | K21: =(G21)*0.066 -> 191.268 | L21: =J21-K21 -> 3.632 | M21: =[3]Apr!AD21 -> 141 | N21: =3+4 -> 7 | P21: =(J21-K21)/J21*100 -> 1.8635198 | Q21: =(G21)/(E21/60) -> 120.75 | S21: ='[4]Daily glue APR'!$H23 -> 0.022402869
B22: 46126 | C22: 8 | D22: SHANDY LIME ( LOC ) | F22: =[3]Apr!$P76 -> 367 | G22: 1761 | H22: =(G22)*24/(F22/60)/17000*100 -> 40.644975 | J22: =SUM(96,102) -> 198 | K22: =(G22+G23)*0.066 -> 190.938 | L22: =J22-K22 -> 7.062 | M22: =[3]Apr!AD22 -> 170 | P22: =(J22-K22)/J22*100 -> 3.5666667 | Q22: =(G22)/(E21/60) -> 73.375 | S22: ='[4]Daily glue APR'!$H24 -> 0.021436197
B23: 46126 | C23: 8 | D23: SHANDY LIME( EXP) | F23: =[3]Apr!$P77 -> 455 | G23: 1132 | H23: =(G23)*24/(F23/60)/17000*100 -> 21.074079 | L23: =J23-K23 -> 0 | M23: =[3]Apr!AD23 -> 312 | Q23: =(G23)/(E21/60) -> 47.166667 | S23: ='[4]Daily glue APR'!$H25 -> 0.03966604
B24: 46126 | C24: 8 | D24: SHANDY SORREL(EXP | F24: =[3]Apr!$P78 -> 30 | G24: 242 | H24: =(G24)*24/(F24/60)/17000*100 -> 68.329412 | J24: =SUM(89.5,93)-81-85.5 -> 16 | K24: =(G24)*0.066 -> 15.972 | L24: =J24-K24 -> 0.028 | M24: =[3]Apr!AD24 -> 30 | N24: 2 | P24: =(J24-K24)/J24*100 -> 0.175 | Q24: =(G24)/(E21/60) -> 10.083333 | S24: ='[4]Daily glue APR'!$H26 -> 0.039896594
B25: 46127 | C25: 9 | D25: SHANDY SORREL(EXP | E25: 1435 | F25: =[3]Apr!$P79 -> 114 | G25: 700 | H25: =(G25)*24/(F25/60)/17000*100 -> 52.012384 | J25: =SUM(81,85.5) -> 166.5 | K25: =(G25+G26)*0.066 -> 164.01 | L25: =J25-K25 -> 2.49 | M25: =[3]Apr!AD25 -> 38 | N25: 2 | P25: =(J25-K25)/J25*100 -> 1.4954955 | Q25: =(G25)/(E25/60) -> 29.268293 | S25: ='[4]Daily glue APR'!$H$27 -> 0.026112401
B26: 46127 | C26: 9 | D26: SHANDY SOREL (LOC) | F26: =[3]Apr!$P80 -> 323 | G26: 1785 | H26: =(G26)*24/(F26/60)/17000*100 -> 46.811146 | L26: =J26-K26 -> 0 | M26: =[3]Apr!AD26 -> 104 | Q26: =(G26)/(E25/60) -> 74.634146 | S26: ='[4]Daily glue APR'!$H$26 -> 0.039896594
B27: 46127 | C27: 9 | D27: STAG | F27: =[3]Apr!$P81 -> 845 | G27: 4936 | H27: =(G27)*24/(F27/60)/17000*100 -> 49.480265 | J27: =SUM(99,90,95,90)-34 -> 340 | K27: =(G27)*0.066+(35*0.19) -> 332.426 | L27: =J27-K27 -> 7.574 | M27: =[3]Apr!AD27 -> 314 | N27: 2 | O27: 35 | P27: =(J27-K27)/J27*100 -> 2.2276471 | Q27: =(G27)/(E25/60) -> 206.38328 | S27: ='[4]Daily glue APR'!$H$28 -> 0.029212783
B28: 46128 | C28: 10 | D28: STAG | E28: 1432 | F28: =[3]Apr!$P82 -> 509 | G28: 3351 | H28: =(G28)*24/(F28/60)/17000*100 -> 55.766093 | J28: =SUM(97.4,92.8,34) -> 224.2 | K28: =(G28)*0.066 -> 221.166 | L28: =J28-K28 -> 3.034 | M28: =[3]Apr!AD28 -> 173 | N28: 23 | P28: =(J28-K28)/J28*100 -> 1.353256 | Q28: =(G28)/(E28/60) -> 140.40503 | S28: ='[4]Daily glue APR'!$H$30 -> 0.022424521
B29: 46128 | C29: 10 | D29: CARIB AMBER | F29: =[3]Apr!$P83 -> 840 | G29: 6081 | H29: =(G29)*24/(F29/60)/17000*100 -> 61.321008 | I29: 21 | J29: =SUM(88,90,91,95.4,100.9,105.2)-80.5-82 -> 408 | K29: =(G29)*0.066 -> 401.346 | L29: =J29-K29 -> 6.654 | M29: =[3]Apr!AD29 -> 137 | N29: =1+2 -> 3 | P29: =(J29-K29)/J29*100 -> 1.6308824 | Q29: =(G29)/(E28/60) -> 254.7905 | S29: ='[4]Daily glue APR'!$H$31 -> 0.023917417
B30: 46129 | C30: 11 | D30: CARIB AMBER | E30: 1198 | F30: =[3]Apr!$P84 -> 355 | G30: 2420 | H30: =(G30)*24/(F30/60)/17000*100 -> 57.743165 | J30: =SUM(80.5,82) -> 162.5 | K30: =(G30)*0.066 -> 159.72 | L30: =J30-K30 -> 2.78 | M30: =[3]Apr!AD30 -> 142 | N30: 11 | P30: =(J30-K30)/J30*100 -> 1.7107692 | Q30: =(G30)/(E30/60) -> 121.202 | S30: ='[4]Daily glue APR'!$H$32 -> 0.021775116
B31: 46129 | C31: 11 | D31: GINSENG APPLE | F31: =[3]Apr!$P85 -> 517 | G31: 2589 | H31: =(G31)*24/(F31/60)/17000*100 -> 42.418478 | J31: =SUM(99.2,106)-30.6 -> 174.6 | K31: =(G31)*0.066 -> 170.874 | L31: =J31-K31 -> 3.726 | M31: =[3]Apr!AD31 -> 414 | N31: 1 | P31: =(J31-K31)/J31*100 -> 2.1340206 | Q31: =(G31)/(E30/60) -> 129.66611 | S31: ='[4]Daily glue APR'!$H$34 -> 0.031851051
B32: 46132 | C32: 12 | D32: GINSENG APPLE (medium) | E32: 1380 | F32: =[3]Apr!$P86 -> 495 | G32: 2693 | H32: =(G32+F33)*24/(F32/60)/17000*100 -> 50.207487 | I32: 239 | J32: =SUM(30.6,50.5,99) -> 180.1 | K32: =(G32)*0.066 -> 177.738 | L32: =J32-K32 -> 2.362 | M32: =[3]Apr!AD32 -> 522 | N32: 5 | P32: =(J32-K32)/J32*100 -> 1.3114936 | Q32: =(G32)/(E32/60) -> 117.08696 | S32: ='[4]Daily glue APR'!$H35 -> 0.054057692
B33: 46132 | C33: 12 | D33: GINSENG APPLE (SHORT) | F33: =[3]Apr!$P87 -> 241 | L33: =J33-K33 -> 0 | M33: =[3]Apr!AD33 -> 58 | S33: ='[4]Daily glue APR'!$H36 -> 0.022352099
B34: 46132 | C34: 12 | D34: CARIB AMBER | F34: =[3]Apr!$P88 -> 213 | G34: 1192 | H34: =(G34)*24/(F34/60)/17000*100 -> 47.40348 | J34: =SUM(94.8,95.2)-21-90.2 -> 78.8 | K34: =(G34)*0.066 -> 78.672 | L34: =J34-K34 -> 0.128 | M34: =[3]Apr!AD34 -> 216 | N34: 4 | P34: =(J34-K34)/J34*100 -> 0.16243655 | Q34: =(G34)/(E32/60) -> 51.826087 | S34: ='[4]Daily glue APR'!$H37 -> 0.0085130224
B35: 46133 | C35: 13 | D35: CARIB AMBER | E35: 1435 | F35: =[3]Apr!$P89 -> 726 | G35: 4590 | H35: =(G35)*24/(F35/60)/17000*100 -> 53.553719 | I35: 5.2 | J35: =SUM(21,94.6,90.2,100) -> 305.8 | K35: =(G35)*0.066 -> 302.94 | L35: =J35-K35 -> 2.86 | M35: =[3]Apr!AD35 -> 207 | N35: =8+5 -> 13 | P35: =(J35-K35)/J35*100 -> 0.9352518 | Q35: =(G35)/(E35/60) -> 191.91638 | S35: ='[4]Daily glue APR'!$H$38 -> 0.034119254
B36: 46133 | C36: 13 | D36: STAG | F36: =[3]Apr!$P90 -> 667 | G36: 3311 | H36: =(G36)*24/(F36/60)/17000*100 -> 42.048152 | J36: =SUM(95.2,97,96,84.8)-65.2-86.3 -> 221.5 | K36: =(G36)*0.066 -> 218.526 | L36: =J36-K36 -> 2.974 | M36: =[3]Apr!AD36 -> 309 | N36: =1+10 -> 11 | P36: =(J36-K36)/J36*100 -> 1.3426637 | Q36: =(G36)/(E35/60) -> 138.43902 | S36: ='[4]Daily glue APR'!$H$40 -> 0.022406522
B37: 46134 | C37: 14 | D37: STAG | E37: 1436 | F37: =[3]Apr!$P91 -> 290 | G37: =2256+2 -> 2258 | H37: =(G37)*24/(F37/60)/17000*100 -> 65.953753 | I37: 368 | J37: =SUM(65.2,86.3) -> 151.5 | K37: =(G37)*0.066 -> 149.028 | L37: =J37-K37 -> 2.472 | M37: =[3]Apr!AD37 -> 84 | N37: 10 | P37: =(J37-K37)/J37*100 -> 1.6316832 | Q37: =(G37)/(E37/60) -> 94.345404 | S37: ='[4]Daily glue APR'!$H$41 -> 0.024266753
B38: 46134 | C38: 14 | D38: GUINNESS | F38: =[3]Apr!$P92 -> 1046 | G38: 5582 | H38: =(G38)*24/(F38/60)/17000*100 -> 45.203464 | J38: =SUM(93.9,92,8,93.8,86) -> 373.7 | K38: =(G38)*0.066 -> 368.412 | L38: =J38-K38 -> 5.288 | M38: =[3]Apr!AD38 -> 398 | N38: =2+3 -> 5 | P38: =(J38-K38)/J38*100 -> 1.4150388 | Q38: =(G38)/(E37/60) -> 233.2312 | S38: ='[4]Daily glue APR'!$H$42 -> 0.024174407
B39: 46135 | C39: 15 | D39: CARIB EXPORT (explorer) | E39: 1440 | F39: =[3]Apr!$P93 -> 727 | G39: 2102 | H39: =(G39)*24/(F39/60)/17000*100 -> 24.491302 | J39: =SUM(78,99,92)-23.8 -> 245.2 | K39: =(G39+G40)*0.066 -> 241.692 | L39: =J39-K39 -> 3.508 | M39: =[3]Apr!AD39 -> 524 | N39: =10+2+3 -> 15 | P39: =(J39-K39)/J39*100 -> 1.4306688 | Q39: =(G39)/(E39/60) -> 87.583333 | S39: ='[4]Daily glue APR'!$H$45 -> 0.031513453
B40: 46135 | C40: 15 | D40: CARIB AMBER (SHORT) | F40: =[3]Apr!$P94 -> 560 | G40: 1560 | H40: =(G40)*24/(F40/60)/17000*100 -> 23.596639 | M40: =[3]Apr!AD40 -> 363 | Q40: =(G40)/(E39/60) -> 65 | S40: ='[4]Daily glue APR'!$H46 -> 0.023994878
B41: 46136 | C41: 16 | D41: CARIB AMBER (SHORT) | E41: 1260 | F41: =[3]Apr!$P95 -> 58 | G41: =2620 -> 2620 | H41: =(G41)*24/(F41/60)/17000*100 -> 382.63692 | J41: =SUM(99,23.8,103) -> 225.8 | K41: =(G41+G42)*0.066 -> 224.334 | L41: =J41-K41 -> 1.466 | M41: =[3]Apr!AD41 -> 84 | N41: =13+2 -> 15 | P41: =(J41-K41)/J41*100 -> 0.64924712 | Q41: =(G41)/(E41/60) -> 124.7619 | S41: ='[4]Daily glue APR'!$H47 -> 0.034630412
...

Sheet May_2026
B1: GRENADA BREWERIES LIMITED
B3: PRODUCTION DEPARTMENT
B4: 46143
B5: DATE | C5: DAY | D5: PRODUCT | E5: AVAIL. | F5: FILL | G5: CASES | H5: Line Rated | I5: Cases on Hold | J5: GROSS | K5: BBT | L5: BOTTLED | M5: Diff BBT Hls vs Hls in Package | N5: DOWNTIME (Mins) | O5: REJECTS (Cases) | P5: KEGS | Q5: BOTTLED | R5: AVERAGE | S5: YTD | T5: Glue
E6: TIME | F6: TIME | G6: BOTTLED | H6: Efficiency | J6: EFFICIENCY | K6: HLS | L6: HLS | Q6: LOSS | R6: CASE/HR | S6: Ave Case per hour | T6: Usage | U6: AVG
F7: Mins | H7: % | J7: % | T7: lbs/case | U7: CASE PER
B8: 46146 | C8: 1 | D8: GINSENG ORIGINAL | E8: 1382 | F8: =[3]May!$N71 -> 222 | G8: 733 | H8: =(G8)*24/(F8/60)/17000*100 -> 27.968203 | K8: 49.5 | L8: =(G8)*0.066 -> 48.378 | M8: =K8-L8 -> 1.122 | N8: =[3]May!$AD8 -> 254 | O8: 15 | Q8: =(K8-L8)/K8*100 -> 2.2666667 | R8: =(G8)/(E8/60) -> 31.823444 | T8: ='[4]Daily glue MAY'!$H$2 -> 0.030422078 | U8: DAY
B9: 46146 | C9: 1 | D9: VITA MALT ( CLASSIC ) | F9: =[3]May!$N72 -> 737 | G9: 4662 | H9: =(G9)*24/(F9/60)/17000*100 -> 53.58193 | I9: 276 | K9: =SUM(94.1,100.4,100,37.8) -> 332.3 | L9: =(G9)*0.0708 -> 330.0696 | M9: =K9-L9 -> 2.2304 | N9: =[3]May!$AD9 -> 386 | O9: =8+9 -> 17 | Q9: =(K9-L9)/K9*100 -> 0.67120072 | R9: =(G9)/(E8/60) -> 202.40232 | T9: =SUM('[4]Daily glue MAY'!$H$3:$H$4) -> 0.060046593
B10: 46147 | C10: 2 | D10: CARIB FLINT (LOCAL) | E10: 1440 | F10: =[3]May!$N73 -> 1063 | G10: 2128 | H10: =(G10)*24/(F10/60)/17000*100 -> 16.957114 | K10: =SUM(95,98)-10 -> 183 | L10: =(G10+G11)*0.066 -> 182.028 | M10: =K10-L10 -> 0.972 | N10: =[3]May!$AD10 -> 939 | O10: =33+15 -> 48 | Q10: =(K10-L10)/K10*100 -> 0.53114754 | R10: =(G10)/(E10/60) -> 88.666667 | T10: ='[4]Daily glue MAY'!$H$7 -> 0.024228961
B11: 46147 | C11: 2 | D11: CARIB AMBER | F11: =[3]May!$N74 -> 107 | G11: 630 | H11: =(G11)*24/(F11/60)/17000*100 -> 49.873557 | M11: =K11-L11 -> 0 | N11: =[3]May!$AD11 -> 41 | R11: =(G11)/(E10/60) -> 26.25
B12: 46148 | C12: 3 | D12: CARIB AMBER | E12: 1432 | F12: =[3]May!$N75 -> 1426 | G12: 10035 | H12: =(G12)*24/(F12/60)/17000*100 -> 59.608943 | I12: 3 | K12: =SUM(10,93,100.3,93,96.5,103.5,84.6,94.2,105.5,89.7)-87.5-96.6 -> 686.2 | L12: =(G12)*0.066+(47*0.19) -> 671.24 | M12: =K12-L12 -> 14.96 | N12: =[3]May!$AD12 -> 242 | O12: =4+5.2+20 -> 29.2 | P12: 47 | Q12: =(K12-L12)/K12*100 -> 2.1801224 | R12: =(G12)/(E12/60) -> 420.46089 | T12: =SUM('[4]Daily glue MAY'!$H$8:$H$9) -> 0.039938397
B13: 46149 | C13: 4 | D13: CARIB AMBER | E13: 1434 | F13: =[3]May!$N76 -> 234 | G13: 2745 | H13: =(G13)*24/(F13/60)/17000*100 -> 99.366516 | K13: =SUM(87.5,96.6) -> 184.1 | L13: =(G13)*0.066 -> 181.17 | M13: =K13-L13 -> 2.93 | N13: =[3]May!$AD13 -> 80 | O13: 14 | Q13: =(K13-L13)/K13*100 -> 1.5915263 | R13: =(G13)/(E13/60) -> 114.85356 | T13: ='[4]Daily glue MAY'!$H$11 -> 0.02105618
B14: 46149 | C14: 4 | D14: TING ORIGINAL | F14: =[3]May!$N77 -> 293 | G14: 1777 | H14: =(G14)*24/(F14/60)/17000*100 -> 51.372817 | I14: 170 | K14: =1800*0.066 -> 118.8 | L14: =(G14)*0.066 -> 117.282 | M14: =K14-L14 -> 1.518 | N14: =[3]May!$AD14 -> 290 | O14: =4+1 -> 5 | Q14: =(K14-L14)/K14*100 -> 1.2777778 | R14: =(G14)/(E13/60) -> 74.351464 | T14: ='[4]Daily glue MAY'!$H$12 -> 0.02029896
B15: 46149 | C15: 4 | D15: STAG | F15: =[3]May!$N78 -> 385 | G15: 3071 | H15: =(G15)*24/(F15/60)/17000*100 -> 67.566692 | I15: 6 | K15: =SUM(92,97,98,97.6)-99-75.4 -> 210.2 | L15: =(G15)*0.066+(30*0.19) -> 208.386 | M15: =K15-L15 -> 1.814 | N15: =[3]May!$AD15 -> 124 | O15: 2 | P15: 30 | Q15: =(K15-L15)/K15*100 -> 0.86298763 | R15: =(G15)/(E13/60) -> 128.49372 | T15: ='[4]Daily glue MAY'!$H$13 -> 0.019246833
B16: 46150 | C16: 5 | D16: STAG | E16: 1280 | F16: =[3]May!$N79 -> 696 | G16: 5141 | H16: =(G16)*24/(F16/60)/17000*100 -> 62.567951 | K16: =SUM(91,79,99,75.4) -> 344.4 | L16: =(G16)*0.066 -> 339.306 | M16: =K16-L16 -> 5.094 | N16: =[3]May!$AD16 -> 159 | O16: =2+6 -> 8 | Q16: =(K16-L16)/K16*100 -> 1.4790941 | R16: =(G16)/(E16/60) -> 240.98438 | T16: ='[4]Daily glue MAY'!$H$14 -> 0.018284299
B17: 46150 | C17: 5 | D17: GUINNESS | F17: =[3]May!$N80 -> 190 | G17: 1427 | H17: =(G17)*24/(F17/60)/17000*100 -> 63.618576 | K17: =SUM(94.2) -> 94.2 | L17: =(G17)*0.066 -> 94.182 | M17: =K17-L17 -> 0.018 | N17: =[3]May!$AD17 -> 284 | Q17: =(K17-L17)/K17*100 -> 0.01910828 | R17: =(G17)/(E16/60) -> 66.890625 | T17: =SUM('[4]Daily glue MAY'!$H$15:$H$16) -> 0.045878367
B18: 46151 | C18: 6 | D18: GUINNESS | E18: 911 | F18: =[3]May!$N81 -> 845 | G18: 5853 | H18: =(G18)*24/(F18/60)/17000*100 -> 58.672607 | K18: =SUM(96,95.8,101.1,94) -> 386.9 | L18: =(G18)*0.066 -> 386.298 | M18: =K18-L18 -> 0.602 | N18: =[3]May!$AD18 -> 218 | O18: =7+5 -> 12 | Q18: =(K18-L18)/K18*100 -> 0.15559576 | R18: =(G18)/(E18/60) -> 385.48847 | T18: =SUM('[4]Daily glue MAY'!$H$17) -> 0.016267361
