Workbook

Sheet January_17
B2: Daily Bottling Hall Summary 2017
B3: Date | C3: Product Bottled | D3: Planned Production Cases | E3: Filler Start Time | F3: BBT Hls | G3: Cases bottled | H3: Bott Hls | I3: No.of Rejects | J3: Cases Per hour (524) | K3: Fill Time Mins | L3: Packer End Time | M3: Down Time Mins | N3: Change Over % (1.1) | O3: Cases on hold | P3: Bottling Loss (1.1%) | Q3: GBL Plant Utilization @15,000 | R3: GBL Plant Utilization @17,000 | S3: Line Rated Efficiency (74%) @15,000 | T3: Line Rated Efficiency (74%) @17,000 | U3: Plant Availability (95%) | V3: Comments
B4: 42738 | C4: VITAMALT | D4: 1100 | E4: 0.32777778 | F4: =SUM([3]January_2017!$J8) -> 78.7 | G4: =SUM([3]January_2017!$F8) -> 1008 | H4: =SUM([3]January_2017!$K8) -> 74.9952 | I4: =SUM([3]January_2017!$N8) -> 7.75 | J4: =SUM([3]January_2017!$Q8) -> 258.51429 | K4: =SUM([3]January_2017!$E8) -> 525 | L4: 0.72847222 | M4: =SUM([3]January_2017!$M8) -> 12 | P4: =SUM([3]January_2017!$P8) -> 4.7074968 | Q4: =($G$4+$G$5+$G$6)/(($K$4/60)*$AC$4*(1/24)) -> 0.41362286 | R4: =($G$4+$G$5+$G$6)/(($K$4/60)*$AD$4*(1/24)) -> 0.36496134 | S4: =(G4+G5+G6)*24/(K4/60)/15000 -> 0.41362286 | T4: =(G4+G5+G6)*24/(K4/60)/17000 -> 0.36496134 | U4: =((607-207)/607) -> 0.65897858 | V4: 5mins downtime due to the back-up sensor on the Filler malfunctioning. 3mins for stuck crowns; & 4mins downtime caused by lack of bottles. | AC4: 15000 | AD4: 17000
C5: STAG | D5: 1100 | F5: =SUM([3]January_2017!$J9) -> 65.2 | G5: =SUM([3]January_2017!$F9) -> 966 | H5: =SUM([3]January_2017!$K9) -> 63.756 | I5: =SUM([3]January_2017!$N9) -> 12 | M5: =SUM([3]January_2017!$M9) -> 155 | N5: =[4]Jan!$I$9/K4 -> 0.24952381 | P5: =SUM([3]January_2017!$P9) -> 2.2147239 | V5: 131mins Change-over from Vitamalt; 9mins stuck crowns & 2mins back-up sensor malfunction. 5mins downtime to increase CO2 on the line; 3mins waiting on pallet packer; 3mins Packer adjustments. | AC5: 15000 | AD5: 17000
C6: CARIB (AMBER) | F6: =SUM([3]January_2017!$J10) -> 34.1 | G6: =SUM([3]January_2017!$F10) -> 288 | H6: =SUM([3]January_2017!$K10) -> 32.688 | I6: =SUM([3]January_2017!$N10) -> 3 | M6: =SUM([3]January_2017!$M10) -> 40 | N6: =[4]Jan!$I$10/K4 -> 0.057142857 | P6: =SUM([3]January_2017!$P10) -> 4.1407625 | V6: 30mins Change-over from Stag; 7mins low water pressure on the Washer; & 2mins downtime to increase CO2 on the line. | AC6: 15000 | AD6: 17000
B7: 42739 | C7: CARIB (FLINT) | D7: 2200 | E7: 0.31736111 | F7: =SUM([3]January_2017!$J11) -> 308.3 | G7: =SUM([3]January_2017!$F11) -> 2249 | H7: =SUM([3]January_2017!$K11) -> 307.534 | I7: =SUM([3]January_2017!$N11) -> 11 | J7: =SUM([3]January_2017!$Q11) -> 459.43144 | K7: =SUM([3]January_2017!$E11) -> 598 | L7: 0.7875 | M7: =SUM([3]January_2017!$M11) -> 105 | N7: =[4]Jan!$I$11/K7 -> 0.018394649 | P7: =SUM([3]January_2017!$P11) -> 0.24845929 | Q7: =($G$7+$G$8)/(($K$7/60)*$AC$7*(1/24)) -> 0.7350903 | R7: =($G$7+$G$8)/(($K$7/60)*$AD$7*(1/24)) -> 0.64860909 | S7: =(G7+G8)*24/(K7/60)/15000 -> 0.7350903 | T7: =(G7+G8)*24/(K7/60)/17000 -> 0.64860909 | U7: =(708-M7)/708 -> 0.85169492 | V7: 13mins due to foreign object found in bottles past the EBI; & 10mins high rejection. 10mins adjusting the tape on the Sealer. 8mins cleaning & adjusting the rollers on the Sealer; 7mins changing over the Packer from cartons to crates. Pasteurizer stopped for 4mins to separate Flint from CDC Amber; & 10mins low air pressure on the Filler. | AC7: 15000 | AD7: 17000
C8: CARIB (AMBER) | D8: 2400 | G8: =SUM([3]January_2017!$F12) -> 2330 | AC8: 15000 | AD8: 17000
B9: 42740 | C9: CARIB (AMBER) | D9: 1000 | E9: 0.32152778 | F9: =SUM([3]January_2017!$J13) -> 61.3 | G9: =SUM([3]January_2017!$F13) -> 905 | H9: =SUM([3]January_2017!$K13) -> 59.73 | I9: =SUM([3]January_2017!$N13) -> 10.75 | J9: =SUM([3]January_2017!$Q$13:$Q14) -> 534.54545 | K9: =SUM([3]January_2017!$E13) -> 583 | L9: 0.77291667 | M9: =SUM([3]January_2017!$M13) -> 14 | P9: =SUM([3]January_2017!$P13) -> 2.5611746 | Q9: =($G$9+$G$10)/(($K$9/60)*$AC$9*(1/24)) -> 0.85527273 | R9: =($G$9+$G$10)/(($K$9/60)*$AD$9*(1/24)) -> 0.75465241 | S9: =(G9+G10)*24/(K9/60)/15000 -> 0.85527273 | T9: =(G9+G10)*24/(K9/60)/17000 -> 0.75465241 | U9: =(686-52)/686 -> 0.92419825 | V9: 7mins low pressure on the BBT at the end of filling. 2mins for stuck crowns & 3mins high rejection. | AC9: 15000 | AD9: 17000
C10: STAG | D10: 4200 | F10: =SUM([3]January_2017!$J14) -> 284.3 | G10: =SUM([3]January_2017!$F14) -> 4289 | H10: =SUM([3]January_2017!$K14) -> 283.074 | I10: =SUM([3]January_2017!$N14) -> 2.25 | M10: =SUM([3]January_2017!$M14) -> 38 | N10: =[4]Jan!$I$13/K9 -> 0.012006861 | P10: =SUM([3]January_2017!$P14) -> 0.43123461 | V10: 15mins downtime investigation to check why some bottles were leaking resulted in 3 worn-out pistons being changed & a crimp test done. 9mins stuck crowns; & 7mins change-over downtime. | AC10: 15000 | AD10: 17000
B11: 42741 | C11: TING | D11: 3600 | E11: 0.32777778 | F11: =SUM([3]January_2017!$J15) -> 245.916 | G11: =SUM([3]January_2017!$F15) -> 3632 | H11: =SUM([3]January_2017!$K15) -> 239.712 | I11: =SUM([3]January_2017!$N15) -> 7 | J11: =SUM([3]January_2017!$Q15) -> 433.24056 | K11: =SUM([3]January_2017!$E15) -> 503 | L11: 0.71666667 | M11: =SUM([3]January_2017!$M15) -> 96 | P11: =SUM([3]January_2017!$P15) -> 2.5228127 | Q11: =($G$11)/(($K$11/60)*$AC$11*(1/24)) -> 0.69318489 | R11: =($G$11)/(($K$11/60)*$AD$11*(1/24)) -> 0.61163373 | S11: =(G11)*24/(K11/60)/15000 -> 0.69318489 | T11: =(G11)*24/(K11/60)/17000 -> 0.61163373 | U11: =(608-96)/608 -> 0.84210526 | V11: 26mins low water pressure on the Washer due to repairs on the water supply pump (Seal replacement). 18mins downtime caused by lack of water in the condenser in the Soft Drink plant. 20mins Labeler repair @ start-up due to twisting labels (Sponge changed); 16mins downtime on the Uncaser due to a damaged sprocket; 6mins downtime to increase CO2 on the line to end filling; & 5mins stuck crowns | AC11: 15000 | AD11: 17000
B12: 42744 | C12: GUINNESS | D12: 2800 | E12: 0.35972222 | F12: =SUM([3]January_2017!$J16) -> 193.6 | G12: =SUM([3]January_2017!$F16) -> 2920 | H12: =SUM([3]January_2017!$K16) -> 192.72 | I12: =SUM([3]January_2017!$N16) -> 8.25 | J12: =SUM([3]January_2017!$Q16) -> 395.48533 | K12: =SUM([3]January_2017!$E16) -> 443 | L12: 0.67361111 | M12: =SUM([3]January_2017!$M16) -> 91 | P12: =SUM([3]January_2017!$P16) -> 0.45454545 | Q12: =($G$12)/(($K$12/60)*$AC$12*(1/24)) -> 0.63277652 | R12: =($G$12)/(($K$12/60)*$AD$12*(1/24)) -> 0.55833223 | S12: =(G12)*24/(K12/60)/15000 -> 0.63277652 | T12: =(G12)*24/(K12/60)/17000 -> 0.55833223 | U12: =(524-M12)/524 -> 0.82633588 | V12: 48mins late start due to fault with the crown transfer system on the Filler. 6mins for stuck crowns. 12mins and 6mins low air pressure on the Filler & Uncaser respectively; 2mins Labeler adjustments for flagging & missing labels; & 5mins waiting on labels. | AC12: 15000 | AD12: 17000
B13: 42745 | C13: CARIB (AMBER) | D13: 4900 | E13: 0.31736111 | F13: =SUM([3]January_2017!$J17) -> 229 | G13: =SUM([3]January_2017!$F17) -> 3240 | H13: =SUM([3]January_2017!$K17) -> 228.47 | I13: =SUM([3]January_2017!$N17) -> 9.75 | J13: =SUM([3]January_2017!$Q17) -> 353.45455 | K13: =SUM([3]January_2017!$E17) -> 550 | L13: 0.725 | M13: =SUM([3]January_2017!$M17) -> 168 | P13: =SUM([3]January_2017!$P17) -> 0.23144105 | Q13: =($G$13)/(($K$13/60)*$AC$13*(1/24)) -> 0.56552727 | R13: =($G$13)/(($K$13/60)*$AD$13*(1/24)) -> 0.49899465 | S13: =(G13)*24/(K13/60)/15000 -> 0.56552727 | T13: =(G13)*24/(K13/60)/17000 -> 0.49899465 | U13: =(615-M13)/615 -> 0.72682927 | V13: 150mins EBI downtime for repairs and adjustments to the sprocket, shaft, rollers & bearing of the belt drive system; 4mins stuck crowns; Uncaser conveyor line needed adjusting; & 5mins Labeler adjustments. | AC13: 15000 | AD13: 17000
B14: 42746 | C14: CARIB (FLINT) | D14: 300 | E14: 0.31458333 | F14: =SUM([3]January_2017!$J18) -> 311.93 | G14: =SUM([3]January_2017!$F18) -> 276 | H14: =SUM([3]January_2017!$K18) -> 311.058 | I14: =SUM([3]January_2017!$N18) -> 24.25 | J14: =SUM([3]January_2017!$Q18) -> 460.55375 | K14: =SUM([3]January_2017!$E18) -> 614 | L14: 0.71111111 | M14: =SUM([3]January_2017!$M18) -> 57 | N14: =[4]Jan!$I$17/K14 -> 0.0016286645 | P14: =SUM([3]January_2017!$P18) -> 0.2795499 | Q14: =($G$14+$G$15)/(($K$14/60)*$AC$14*(1/24)) -> 0.73688599 | R14: =($G$14+$G$15)/(($K$14/60)*$AD$14*(1/24)) -> 0.65019352 | S14: =(G14+G15)*24/(K14/60)/15000 -> 0.73688599 | T14: =(G14+G15)*24/(K14/60)/17000 -> 0.65019352 | U14: =(723-M14)/723 -> 0.92116183 | V14: 13mins downtime for stuck crowns; 3mins for air dryer fault; 9mins low air pressure on the Filler; 6mins downtime due to bottle jams on line ex. Pasteurizer; & 5mins each for EBI & Labeler adjustments. | AC14: 15000 | AD14: 17000
C15: CARIB (AMBER) | D15: 2800 | G15: =SUM([3]January_2017!$F19) -> 4437 | AC15: 15000 | AD15: 17000
B16: 42747 | C16: GUINNESS | D16: 4800 | E16: 0.31111111 | F16: =SUM([3]January_2017!$J20) -> 321.8 | G16: =SUM([3]January_2017!$F20) -> 4854 | H16: =SUM([3]January_2017!$K20) -> 320.364 | I16: =SUM([3]January_2017!$N20) -> 23.5 | J16: =SUM([3]January_2017!$Q20) -> 470.50081 | K16: =SUM([3]January_2017!$E20) -> 619 | L16: 0.80763889 | M16: =SUM([3]January_2017!$M20) -> 128 | P16: =SUM([3]January_2017!$P20) -> 0.4462399 | Q16: =($G$16)/(($K$16/60)*$AC$16*(1/24)) -> 0.75280129 | R16: =($G$16)/(($K$16/60)*$AD$16*(1/24)) -> 0.66423643 | S16: =(G16)*24/(K16/60)/15000 -> 0.75280129 | T16: =(G16)*24/(K16/60)/17000 -> 0.66423643 | U16: =(745-M16)/745 -> 0.82818792 | V16: 46mins downtime to replace damaged fingers on the Packer; 12mins adjusting the crate-stop on the Packer; 12mins waiting on pallet packer; 11mins for stuck crowns; 3mins air dryer fault; 4mins bottle jam in the worm; 7mins downtime on line ex. Pasteurizer & 4mins on the in-feed line to the Pasteurizer. | AC16: 15000 | AD16: 17000
B17: 42748 | C17: GUINNESS | D17: 2200 | E17: 0.31388889 | F17: =SUM([3]January_2017!$J21) -> 155.2 | G17: =SUM([3]January_2017!$F21) -> 2341 | H17: =SUM([3]January_2017!$K21) -> 154.506 | I17: =SUM([3]January_2017!$N21) -> 31 | J17: =SUM([3]January_2017!$Q21) -> 340.09685 | K17: =SUM([3]January_2017!$E21) -> 413 | L17: 0.69930556 | M17: =SUM([3]January_2017!$M21) -> 225 | P17: =SUM([3]January_2017!$P21) -> 0.44716495 | Q17: =($G$17)/(($K$17/60)*$AC$17*(1/24)) -> 0.54415496 | R17: =($G$17)/(($K$17/60)*$AD$17*(1/24)) -> 0.48013673 | S17: =(G17)*24/(K17/60)/15000 -> 0.54415496 | T17: =(G17)*24/(K17/60)/17000 -> 0.48013673 | U17: =(593-M17)/593 -> 0.62057336 | V17: 142mins downtime for adjustments to the crate stopper on the Packer; 28mins adjusting the centering device & 15mins adjusting the fingers. 13mins downtime for low PU; 8mins for stuck crowns; 4mins bleeding thr Fobber line; 3mins flushing the crowner; & 3mins air dryer fault. | AC17: 15000 | AD17: 17000
B18: 42751 | C18: STARMALT | D18: 4200 | E18: 0.32430556 | F18: =SUM([3]January_2017!$J22) -> 296.7 | G18: =SUM([3]January_2017!$F22) -> 4467 | H18: =SUM([3]January_2017!$K22) -> 294.822 | I18: =SUM([3]January_2017!$N22) -> 15 | J18: =SUM([3]January_2017!$Q22) -> 521.43969 | K18: =SUM([3]January_2017!$E22) -> 514 | L18: 0.72916667 | M18: =SUM([3]January_2017!$M22) -> 79 | P18: =SUM([3]January_2017!$P22) -> 0.63296259 | Q18: =($G$18)/(($K$18/60)*$AC$18*(1/24)) -> 0.8343035 | R18: =($G$18)/(($K$18/60)*$AD$18*(1/24)) -> 0.73615015 | S18: =(G18)*24/(K18/60)/15000 -> 0.8343035 | T18: =(G18)*24/(K18/60)/17000 -> 0.73615015 | U18: =(615-M18)/615 -> 0.87154472 | V18: 14mins Low air pressure on the Filler; 9mins for stuck crowns; 7mins downtime on the Filler due to air faults; 15mins Packer downtime for adjustments; & 9mins downtime due to the backup sensor on the line behind the Pasteurizer malfunctioning. | AC18: 15000 | AD18: 17000
B19: 42752 | C19: STAG | D19: 4200 | E19: 0.31597222 | F19: =SUM([3]January_2017!$J23) -> 301.1 | G19: =SUM([3]January_2017!$F23) -> 4480 | H19: =SUM([3]January_2017!$K23) -> 299.48 | I19: =SUM([3]January_2017!$N23) -> 32.75 | J19: =SUM([3]January_2017!$Q23) -> 534.39364 | K19: =SUM([3]January_2017!$E23) -> 503 | L19: 0.72152778 | M19: =SUM([3]January_2017!$M23) -> 113 | P19: =SUM([3]January_2017!$P23) -> 0.53802723 | Q19: =($G$19)/(($K$19/60)*$AC$19*(1/24)) -> 0.85502982 | R19: =($G$19)/(($K$19/60)*$AD$19*(1/24)) -> 0.75443808 | S19: =(G19)*24/(K19/60)/15000 -> 0.85502982 | T19: =(G19)*24/(K19/60)/17000 -> 0.75443808 | U19: =(612-M19)/612 -> 0.81535948 | V19: 34mins Packer downtime adjusting the centering cup assembly & 12mins for adjustments to fingers and the crate stopper. 18mins downtime resulted from the conveyor leading the Labeler tripping off; 10mins downtime on the line ex. Pasteurizer due to fallen bottles; 10mins for stuck crowns; 9mins downtime caused by Air Dryer faults. | AC19: 15000 | AD19: 17000
B20: 42753 | C20: MACKESON | D20: 5200 | E20: 0.31875 | F20: =SUM([3]January_2017!$J24) -> 349.6 | G20: =SUM([3]January_2017!$F24) -> 5258 | H20: =SUM([3]January_2017!$K24) -> 347.028 | I20: =SUM([3]January_2017!$N24) -> 24.75 | J20: =SUM([3]January_2017!$Q24) -> 528.44221 | K20: =SUM([3]January_2017!$E24) -> 597 | L20: 0.79027778 | M20: =SUM([3]January_2017!$M24) -> 105 | P20: =SUM([3]January_2017!$P24) -> 0.73569794 | Q20: =($G$20)/(($K$20/60)*$AC$20*(1/24)) -> 0.84550754 | R20: =($G$20)/(($K$20/60)*$AD$20*(1/24)) -> 0.74603606 | S20: =(G20)*24/(K20/60)/15000 -> 0.84550754 | T20: =(G20)*24/(K20/60)/17000 -> 0.74603606 | U20: =(715-M20)/715 -> 0.85314685 | V20: 27mins downtime adjusting the Sealer & tape; 21mins Labeler adjustments (10mins preparation & 11mins for missing body labels); 26mins downtime for stuck crowns (the vibrator was also malfunctioning); 6mins air fault; 6mins downtime on the Uncaser to replacing leaking suction cups; & 7mins while switching BBT's. | AC20: 15000 | AD20: 17000
B21: 42754 | C21: MACKESON | D21: 1100 | E21: 0.32152778 | F21: =SUM([3]January_2017!$J25) -> 69.7 | G21: =SUM([3]January_2017!$F25) -> 1034 | H21: =SUM([3]January_2017!$K25) -> 68.244 | I21: =SUM([3]January_2017!$N25) -> 14 | J21: =SUM([3]January_2017!$Q25) -> 488.4 | K21: =SUM([3]January_2017!$E25) -> 600 | L21: 0.7875 | M21: =SUM([3]January_2017!$M25) -> 18 | P21: =SUM([3]January_2017!$P25) -> 2.0889527 | Q21: =($G$21+$G$22)/(($K$21/60)*$AC$21*(1/24)) -> 0.78144 | R21: =($G$21+$G$22)/(($K$21/60)*$AD$21*(1/24)) -> 0.68950588 | S21: =(G21+G22)*24/(K21/60)/15000 -> 0.78144 | T21: =(G21+G22)*24/(K21/60)/17000 -> 0.68950588 | U21: =(706-101)/706 -> 0.85694051 | V21: 6mins uncaser adjustments; 3mins Sealer adjustments; & 3mins waiting on CO2 to push up product to end filling. | AC21: 15000 | AD21: 17000
C22: MAXIMALT | D22: 4900 | F22: =SUM([3]January_2017!$J26) -> 258.3 | G22: =SUM([3]January_2017!$F26) -> 3850 | H22: =SUM([3]January_2017!$K26) -> 254.1 | I22: =SUM([3]January_2017!$N26) -> 11 | M22: =SUM([3]January_2017!$M26) -> 83 | N22: =[4]Jan!$I$24/K21 -> 0.061666667 | P22: =SUM([3]January_2017!$P26) -> 1.6260163 | V22: 37mins Change-over downtime; 17mins low CO2 on the Filler; 4mins air dryer fault & 11mins stuck crows; & 6mins Videojet adjustment. | AC22: 15000 | AD22: 17000
B23: 42755 | C23: MAXIMALT | E23: 0.31875 | F23: =SUM([3]January_2017!$J27) -> 87.7 | G23: =SUM([3]January_2017!$F27) -> 1312 | H23: =SUM([3]January_2017!$K27) -> 86.592 | I23: =SUM([3]January_2017!$N27) -> 11.25 | J23: =SUM([3]January_2017!$Q27) -> 525.56818 | K23: =SUM([3]January_2017!$E27) -> 528 | L23: 0.7375 | M23: =SUM([3]January_2017!$M27) -> 12 | P23: =SUM([3]January_2017!$P27) -> 1.2633979 | Q23: =($G$23+$G$24)/(($K$23/60)*$AC$23*(1/24)) -> 0.84090909 | R23: =($G$23+$G$24)/(($K$23/60)*$AD$23*(1/24)) -> 0.74197861 | S23: =(G23+G24)*24/(K23/60)/15000 -> 0.84090909 | T23: =(G23+G24)*24/(K23/60)/17000 -> 0.74197861 | U23: =(636-(M23+M24))/636 -> 0.82075472 | V23: 6mins for stuck crowns & 2mins Air dryer fault. 4mins downtime on conveyor ex. Pasteurizer due to fallen bottles. | AC23: 15000 | AD23: 17000
C24: STAG | D24: 3500 | F24: =SUM([3]January_2017!$J28) -> 221.1 | G24: =SUM([3]January_2017!$F28) -> 3313 | H24: =SUM([3]January_2017!$K28) -> 218.658 | I24: =SUM([3]January_2017!$N28) -> 13.75 | M24: =SUM([3]January_2017!$M28) -> 102 | N24: =[4]Jan!$I$26/K23 -> 0.10795455 | P24: =SUM([3]January_2017!$P28) -> 1.1044776 | V24: 57mins Change-Over downtime; 11mins downtime for stuck crowns; 3mins for air dryer fault; 9mins Packer downtime to change damaged fingers; & 6mins downtime for fallen bottles on the line ex. Pasteurizer; & 3mins for bottle jams on the in-feed line to the Pasteurizer. | AC24: 15000 | AD24: 17000
B25: 42758 | C25: CARIB (AMBER) | D25: 4900 | E25: 0.31458333 | F25: =SUM([3]January_2017!$J29) -> 362.7 | G25: =SUM([3]January_2017!$F29) -> 5083 | H25: =SUM([3]January_2017!$K29) -> 359.228 | I25: =SUM([3]January_2017!$N29) -> 16.25 | J25: =SUM([3]January_2017!$Q29) -> 498.33333 | K25: =SUM([3]January_2017!$E29) -> 612 | L25: 0.79027778 | M25: =SUM([3]January_2017!$M29) -> 118 | P25: =SUM([3]January_2017!$P29) -> 0.95726496 | Q25: =($G$25)/(($K$25/60)*$AC$25*(1/24)) -> 0.79733333 | R25: =($G$25)/(($K$25/60)*$AD$25*(1/24)) -> 0.70352941 | S25: =(G25)*24/(K25/60)/15000 -> 0.79733333 | T25: =(G25)*24/(K25/60)/17000 -> 0.70352941 | U25: =(708-M25)/708 -> 0.83333333 | V25: 48mins adjusting the the centering device & head on the Packer; 13mins adjusting thr Packer fingers; &11mins adjustments to Packer air hose. 11mins Labeler magazine adjustments for missing labels; 6mins for stuck crowns; 3mins air dryer fault; & 2mins bleeding the Fobber line. 6mins adjusting the EBI belt (Rejection table full); & 4mins bottle backup on line ex. Pasteruizer & 3mins on Pasteurizer in-feed line. | AC25: 15000 | AD25: 17000
B26: 42759 | C26: CARIB (AMBER) | D26: 1500 | E26: 0.3125 | F26: =SUM([3]January_2017!$J30) -> 90.4 | G26: =SUM([3]January_2017!$F30) -> 1069 | H26: =SUM([3]January_2017!$K30) -> 89.364 | I26: =SUM([3]January_2017!$N30) -> 9 | J26: =SUM([3]January_2017!$Q30) -> 461.34783 | K26: =SUM([3]January_2017!$E30) -> 460 | L26: 0.69166667 | M26: =SUM([3]January_2017!$M30) -> 30 | P26: =SUM([3]January_2017!$P30) -> 1.1460177 | Q26: =($G$26+$G$27+$G$28+$G$29)/(($K$26/60)*$AC$26*(1/24)) -> 0.73815652 | R26: =($G$26+$G$27+$G$28+$G$29)/(($K$26/60)*$AD$26*(1/24)) -> 0.65131458 | S26: =(G26+G27+G28+G29)*24/(K26/60)/15000 -> 0.73815652 | T26: =(G26+G27+G28+G29)*24/(K26/60)/17000 -> 0.65131458 | U26: =(571-(M26+M28+M29))/571 -> 0.80035026 | V26: 13mins downtime on the Packer replacing fingers & suction cups; 3mins Air dryer fault on the Filler; 4mins downtime on line ex. Pasteurizer due to fallen bottles; & 2mins on in-feed line to the Pasteurizer. | AC26: 15000 | AD26: 17000
C27: CARIB (FLINT) | D27: 300 | G27: =SUM([3]January_2017!$F31) -> 285 | AC27: 15000 | AD27: 17000
C28: SHANDY (GINGER) | D28: 1400 | F28: =SUM([3]January_2017!$J32) -> 98.5 | G28: =SUM([3]January_2017!$F32) -> 1468 | H28: =SUM([3]January_2017!$K32) -> 96.888 | I28: =SUM([3]January_2017!$N32) -> 3.25 | M28: =SUM([3]January_2017!$M32) -> 27 | N28: =[4]Jan!$I$29/K26 -> 0.017391304 | P28: =SUM([3]January_2017!$P32) -> 1.6365482 | V28: 8mins Change-over from Carib to Shandy Ginger; 6mins downtime due to an object being found in a bottle by the manual sighter; 4mins Videojet adjustment; 3mins of fluctuating Fobber pressure & 2mins bleeding the Fobber line. | AC28: 15000 | AD28: 17000
C29: SHANDY (LIME) | D29: 700 | F29: =SUM([3]January_2017!$J33) -> 50.2 | G29: =SUM([3]January_2017!$F33) -> 715 | H29: =SUM([3]January_2017!$K33) -> 47.19 | I29: =SUM([3]January_2017!$N33) -> 5 | M29: =SUM([3]January_2017!$M33) -> 57 | N29: =[4]Jan!$I$30/K26 -> 0.10652174 | P29: =SUM([3]January_2017!$P33) -> 5.9960159 | V29: 49mins Change-Over downtime from Shandy Ginger to Shandy Lime; & 6mins Labeler adjustments for flagging labels. | AC29: 15000 | AD29: 17000
B30: 42760 | C30: VITAMALT | D30: 4000 | E30: 0.31597222 | F30: =SUM([3]January_2017!$J34) -> 314 | G30: =SUM([3]January_2017!$F34) -> 4202 | H30: =SUM([3]January_2017!$K34) -> 312.6288 | I30: =SUM([3]January_2017!$N34) -> 15.5 | J30: =SUM([3]January_2017!$Q34) -> 380.84592 | K30: =SUM([3]January_2017!$E34) -> 662 | L30: 0.82847222 | M30: =SUM([3]January_2017!$M34) -> 127 | P30: =SUM([3]January_2017!$P34) -> 0.4366879 | Q30: =($G$30)/(($K$30/60)*$AC$30*(1/24)) -> 0.60935347 | R30: =($G$30)/(($K$30/60)*$AD$30*(1/24)) -> 0.53766483 | S30: =(G30)*24/(K30/60)/15000 -> 0.60935347 | T30: =(G30)*24/(K30/60)/17000 -> 0.53766483 | U30: =(783-M30)/783 -> 0.83780332 | V30: 50mins downtime on the EBI for high rejections (belt adjustments); 19mins downtime due to a broken kidney on the Washer; 17mins downtime cleaning the Fobber; 9mins for stuck crowns; 7mins adjusting the Filler in-feed worm & 4mins air dryer fault. 6mins low air pressure on the Filler; 6mins Uncaser adjustments; & 4mins Packer adjustments. | AC30: 15000 | AD30: 17000
B31: 42761 | C31: CLUB SODA | D31: 350 | E31: 0.325 | F31: =SUM([3]January_2017!$J35) -> 28.045 | G31: =SUM([3]January_2017!$F35) -> 355 | H31: =SUM([3]January_2017!$K35) -> 28.045 | I31: =SUM([3]January_2017!$N35) -> 11 | J31: =SUM([3]January_2017!$Q35) -> 446.55098 | K31: =SUM([3]January_2017!$E35) -> 461 | L31: 0.7 | M31: =SUM([3]January_2017!$M35) -> 10 | P31: =SUM([3]January_2017!$P35) -> 0 | Q31: =($G$31+$G$32+$G$33+$G$34)/(($K$31/60)*$AC$31*(1/24)) -> 0.71448156 | R31: =($G$31+$G$32+$G$33+$G$34)/(($K$31/60)*$AD$31*(1/24)) -> 0.63042491 | S31: =(G31+G32+G33+G34)*24/(K31/60)/15000 -> 0.71448156 | T31: =(G31+G32+G33+G34)*24/(K31/60)/17000 -> 0.63042491 | U31: =(590-(M31+M32+M33+M34))/590 -> 0.78644068 | V31: 10mins low water pressure on the Soft Drink Plant. | AC31: 15000 | AD31: 17000
C32: ORNAGE | D32: 1200 | F32: =SUM([3]January_2017!$J36) -> 90.4 | G32: =SUM([3]January_2017!$F36) -> 1142 | H32: =SUM([3]January_2017!$K36) -> 90.218 | I32: =SUM([3]January_2017!$N36) -> 2.25 | M32: =SUM([3]January_2017!$M36) -> 28 | N32: =[4]Jan!$I$33/K31 -> 0.028199566 | P32: =SUM([3]January_2017!$P36) -> 0.20132743 | V32: 13mins Change-over downtime. 10mins low water pressure on the Soft Drink Plant (resulting in low product level in the filling bowl). 3mins Packer adjustments. | AC32: 15000 | AD32: 17000
C33: CREAM SODA | D33: 1200 | F33: =SUM([3]January_2017!$J37) -> 90.4 | G33: =SUM([3]January_2017!$F37) -> 1120 | H33: =SUM([3]January_2017!$K37) -> 88.48 | I33: =SUM([3]January_2017!$N37) -> 3.75 | M33: =SUM([3]January_2017!$M37) -> 52 | N33: =[4]Jan!$I$34/K31 -> 0.088937093 | P33: =SUM([3]January_2017!$P37) -> 2.1238938 | V33: 41mins Change-over downtime. 10mins low water pressure on the Soft Drink Plant. | AC33: 15000 | AD33: 17000
C34: KOLA CHAMPAGNE | D34: 900 | F34: =SUM([3]January_2017!$J38) -> 65.622449 | G34: =SUM([3]January_2017!$F38) -> 814 | H34: =SUM([3]January_2017!$K38) -> 64.306 | I34: =SUM([3]January_2017!$N38) -> 0 | M34: =SUM([3]January_2017!$M38) -> 36 | N34: =[4]Jan!$I$35/K31 -> 0.069414317 | P34: =SUM([3]January_2017!$P38) -> 2.0060955 | V34: 32mins Change-over downtime. 3mins low filling level as a result of low water pressure. | AC34: 15000 | AD34: 17000
B35: 42762 | C35: STAG | D35: 4200 | E35: 0.3125 | F35: =SUM([3]January_2017!$J39) -> 289.2 | G35: =SUM([3]January_2017!$F39) -> 4308 | H35: =SUM([3]January_2017!$K39) -> 288.128 | I35: =SUM([3]January_2017!$N39) -> 22.75 | J35: =SUM([3]January_2017!$Q39) -> 531.85185 | K35: =SUM([3]January_2017!$E39) -> 486 | L35: 0.70138889 | M35: =SUM([3]January_2017!$M39) -> 79 | P35: =SUM([3]January_2017!$P39) -> 0.37067773 | Q35: =($G$35)/(($K$35/60)*$AC$35*(1/24)) -> 0.85096296 | R35: =($G$35)/(($K$35/60)*$AD$35*(1/24)) -> 0.75084967 | S35: =(G35)*24/(K35/60)/15000 -> 0.85096296 | T35: =(G35)*24/(K35/60)/17000 -> 0.75084967 | U35: =(566-M35)/566 -> 0.86042403 | V35: 24mins Packer adjustments to the head (air hose).12mins downtime for jams & fallen bottles on the conveyor line ex. Pasteurizer. 5mins adjusting the in-feed worm on the Filler; 5mins flushing the crowner; 4mins air dryer fault; & 7mins low CO2 on the Filler. | AC35: 15000 | AD35: 17000
B36: 42765 | C36: CARIB (AMBER) | D36: 4900 | E36: 0.42152778 | F36: =SUM([3]January_2017!$J40) -> 319.4 | G36: =SUM([3]January_2017!$F40) -> 4456 | H36: =SUM([3]January_2017!$K40) -> 317.846 | I36: =SUM([3]January_2017!$N40) -> 8.75 | J36: =SUM([3]January_2017!$Q40) -> 587.6044 | K36: =SUM([3]January_2017!$E40) -> 455 | L36: 0.77916667 | M36: =SUM([3]January_2017!$M40) -> 23 | P36: =SUM([3]January_2017!$P40) -> 0.48653726 | Q36: =($G$36)/(($K$36/60)*$AC$36*(1/24)) -> 0.94016703 | R36: =($G$36)/(($K$36/60)*$AD$36*(1/24)) -> 0.82955915 | S36: =(G36)*24/(K36/60)/15000 -> 0.94016703 | T36: =(G36)*24/(K36/60)/17000 -> 0.82955915 | U36: =(696-M36)/696 -> 0.96695402 | V36: 4mins downtime for Air dryer fault on the Filler; 2mins stuck crowns; 8mins downtime switching BBT's; 3mins Labeler adjustments for missing labels; & 2mins switching pallet packer. | AC36: 15000 | AD36: 17000
B37: 42766 | C37: CARIB (AMBER) | D37: 2100 | E37: 0.31388889 | F37: =SUM([3]January_2017!$J41) -> 133.9 | G37: =SUM([3]January_2017!$F41) -> 2007 | H37: =SUM([3]January_2017!$K41) -> 132.462 | I37: =SUM([3]January_2017!$N41) -> 16 | J37: =SUM([3]January_2017!$Q41) -> 546.83417 | K37: =SUM([3]January_2017!$E41) -> 597 | L37: 0.78263889 | M37: =SUM([3]January_2017!$M41) -> 15 | P37: =SUM([3]January_2017!$P41) -> 1.0739358 | Q37: =($G$37+$G$38)/(($K$37/60)*$AC$38*(1/24)) -> 0.87493467 | R37: =($G$37+$G$38)/(($K$37/60)*$AD$38*(1/24)) -> 0.77200118 | S37: =(G37+G38)*24/(K37/60)/15000 -> 0.87493467 | T37: =(G37+G38)*24/(K37/60)/17000 -> 0.77200118 | U37: =(702-(M37+M38))/702 -> 0.91452991 | V37: 8mis downtime changing a gasket on the gaf filter line. 5mins Air dryer fault on the Filler. | AC37: 15000 | AD37: 17000
C38: STAG | D38: 2800 | F38: =SUM([3]January_2017!$J42) -> 227.4 | G38: =SUM([3]January_2017!$F42) -> 3434 | H38: =SUM([3]January_2017!$K42) -> 226.644 | I38: =SUM([3]January_2017!$N42) -> 10 | M38: =SUM([3]January_2017!$M42) -> 45 | N38: =[4]Jan!$I$39/K37 -> 0.031825796 | P38: =SUM([3]January_2017!$P42) -> 0.33245383 | V38: 19mins Change-Over downtime; 9mins adjustments to the Packer head; 5mins downtime for jammed & fallen bottles on conveyor ex. Pasteurizer; 2mins Air dryer fault on the Filler & 3mins for stuck crowns. | AC38: 15000 | AD38: 17000
AC39: 15000 | AD39: 17000
AC40: 15000 | AD40: 17000
AC41: 15000 | AD41: 17000
...

Sheet February_17
B2: Daily Bottling Hall Summary 2017
B3: Date | C3: Product Bottled | D3: Planned Production Cases | E3: Filler Start Time | F3: BBT Hls | G3: Cases bottled | H3: Bott Hls | I3: No.of Rejects | J3: Cases Per hour (524) | K3: Fill Time Mins | L3: Packer End Time | M3: Down Time Mins | N3: Change Over % (1.1) | O3: Cases on hold | P3: Bottling Loss (1.1%) | Q3: Reworks Cases | R3: GBL Plant Utilization @ 15,000 | S3: GBL Plant Utilization @ 17,000 | T3: Line Rated Efficiency (74%) @15,000 | U3: Line Rated Efficiency (15000 74%) | V3: Line Rated Efficiency (74%) @17,000 | W3: Plant Availability (95%) | X3: Comments | AE3: 15000 | AF3: 17000
B4: 42767 | C4: STAG | D4: 2200 | E4: 0.34027778 | F4: =SUM([3]February_2017!$J8) -> 145 | G4: =SUM([3]February_2017!$F8) -> 2121 | H4: =SUM([3]February_2017!$K8) -> 143.786 | I4: =SUM([3]February_2017!$N8) -> 12.5 | J4: =SUM([3]February_2017!$Q8:$Q9) -> 488.87273 | K4: =SUM([3]February_2017!$E8) -> 825 | L4: 0.94097222 | M4: =SUM([3]February_2017!$M8) -> 57 | O4: =SUM([3]February_2017!$H8) -> 0 | P4: =SUM([3]February_2017!$P8) -> 0.83724138 | R4: =($G4+$G5)/(($K4/60)*AE$3*(1/24)) -> 0.78219636 | S4: =($G4+$G5)/(($K4/60)*AF$3*(1/24)) -> 0.69017326 | T4: =(G4+G5)*24/(K4/60)/15000 -> 0.78219636 | U4: =(H4+H7)*24/(M4/60)/15000 -> 0.24216589 | V4: =(G4+G5)*24/(K4/60)/17000 -> 0.69017326 | W4: =(929-(M4+M5))/929 -> 0.82454252 | X4: 20mins late start fixing a leaking gasket & clamp on the Gaf Filter line; 20mins for repairs to the Uncaser; 5mins for stuck crowns; & 3mins Air dryer fault. | AE4: 15000 | AF4: 17000
C5: STARMALT | D5: 2700 | F5: =SUM([3]February_2017!$J9) -> 307.7 | G5: =SUM([3]February_2017!$F9) -> 4601 | H5: =SUM([3]February_2017!$K9) -> 303.666 | I5: =SUM([3]February_2017!$N9) -> 14.5 | M5: =SUM([3]February_2017!$M9) -> 106 | N5: =[4]Feb!$I$9/K4 -> 0.048484848 | O5: =SUM([3]February_2017!$H9) -> 210 | P5: =SUM([3]February_2017!$P9) -> 1.3110172 | X5: 40mins Change-Over downtime; 21mins for repairs to the Uncaser; 2mins air dryer fault & 11mins for stuck crowns; 6mins for Videojet date adjustment; 8mins downtime switching/waiting on Pallet Packer; & 4mins downtime on conveyor ex. Pasteurizer for jammed bottles & 3mins for jammed bottles on the conveyor ex. Filler. | AE5: 15000 | AF5: 17000
B6: 42774 | C6: =[3]February_2017!$D10 -> CARIB (FLINT) | D6: 2650 | E6: 0.37777778 | F6: =SUM([3]February_2017!$J10) -> 229.6 | G6: =SUM([3]February_2017!$F10) -> 3069 | H6: =SUM([3]February_2017!$K10) -> 228.624 | I6: =SUM([3]February_2017!$N10) -> 22 | J6: =SUM([3]February_2017!$Q10) -> 330.95541 | K6: =SUM([3]February_2017!$E10) -> 628 | L6: 0.81527778 | M6: =SUM([3]February_2017!$M10) -> 147 | N6: =[4]Feb!$I$10/K6 -> 0.042993631 | O6: =SUM([3]February_2017!$H10) -> 2 | P6: =SUM([3]February_2017!$P10) -> 0.42508711 | R6: =($G6+$G7)/(($K6/60)*AE$3*(1/24)) -> 0.52952866 | S6: =($G6+$G7)/(($K6/60)*AF$3*(1/24)) -> 0.46723117 | T6: =(G6+G7)*24/(K6/60)/15000 -> 0.52952866 | U6: =(H6+H9)*24/(M6/60)/15000 -> 0.21009502 | V6: =(G6+G7)*24/(K6/60)/17000 -> 0.46723117 | W6: =(753-(M6))/753 -> 0.80478088 | X6: 74mins late startup due to adjustments/repairs on the EBI passageway. 10mins downtime for stuck crowns; 8mins adjusting the wear strip for the table-top parts; 5mins for adjustments & stuck bottles in the in-feed worm; 8mins Change-over from export to local & 19mins changing from cartons to crates. | AE6: 15000 | AF6: 17000
C7: =[3]February_2017!$D11 -> CARIB (AMBER) | D7: 2255 | G7: =SUM([3]February_2017!$F11) -> 395 | AE7: 15000 | AF7: 17000
B8: 42775 | C8: =[3]February_2017!$D12 -> CARIB (AMBER) | D8: 2800 | E8: 0.31597222 | F8: =SUM([3]February_2017!$J12) -> 286.2 | G8: =SUM([3]February_2017!$F12) -> 4322 | H8: =SUM([3]February_2017!$K12) -> 285.252 | I8: =SUM([3]February_2017!$N12) -> 15.25 | J8: =SUM([3]February_2017!$Q12) -> 557.17105 | K8: =SUM([3]February_2017!$E12) -> 608 | L8: 0.79166667 | M8: =SUM([3]February_2017!$M12) -> 23 | O8: =SUM([3]February_2017!$H12) -> 0 | P8: =SUM([3]February_2017!$P12) -> 0.3312369 | R8: =($G8+$G9)/(($K8/60)*AE$3*(1/24)) -> 0.89147368 | S8: =($G8+$G9)/(($K8/60)*AF$3*(1/24)) -> 0.78659443 | T8: =(G8+G9)*24/(K8/60)/15000 -> 0.89147368 | U8: =(H8+H11)*24/(M8/60)/15000 -> 2.5996883 | V8: =(G8+G9)*24/(K8/60)/17000 -> 0.78659443 | W8: =(597-(M8+M9))/597 -> 0.91792295 | X8: 6mins low air pressure on the Filler; 4mins for stuck crowns; 2mins flushing the crowner. 2mins due to no crowns in the hopper; & 3mins downtime because crowns had finished in the bin. | AE8: 15000 | AF8: 17000
C9: STAG | D9: 1400 | F9: =SUM([3]February_2017!$J13) -> 95.6 | G9: =SUM([3]February_2017!$F13) -> 1324 | H9: =SUM([3]February_2017!$K13) -> 93.084 | I9: =SUM([3]February_2017!$N13) -> 6.25 | M9: =SUM([3]February_2017!$M13) -> 26 | N9: =[4]Feb!$I$9/K8 -> 0.065789474 | O9: =SUM([3]February_2017!$H13) -> 0 | P9: =SUM([3]February_2017!$P13) -> 2.6317992 | X9: 10mins change-over downtime; 6mins Labeler adjustments for missing neck labels; & 4mins downtime removing bent crown in the bin on top the crowner. | AE9: 15000 | AF9: 17000
B10: 42776 | C10: STAG | D10: 4200 | E10: 0.30833333 | F10: =SUM([3]February_2017!$J14) -> 284 | G10: =SUM([3]February_2017!$F14) -> 4287 | H10: =SUM([3]February_2017!$K14) -> 282.942 | I10: =SUM([3]February_2017!$N14) -> 21.5 | J10: =SUM([3]February_2017!$Q14) -> 546.11465 | K10: =SUM([3]February_2017!$E14) -> 471 | L10: 0.69652778 | M10: =SUM([3]February_2017!$M14) -> 62 | N10: =[4]Feb!$I$13/K10 -> 0.014861996 | P10: =SUM([3]February_2017!$P14) -> 0.37253521 | R10: =($G10)/(($K10/60)*AE$3*(1/24)) -> 0.87378344 | S10: =($G10)/(($K10/60)*AF$3*(1/24)) -> 0.77098539 | T10: =(G10)*24/(K10/60)/15000 -> 0.87378344 | U10: =(H10+H13)*24/(M10/60)/15000 -> 0.49533213 | V10: =(G10)*24/(K10/60)/17000 -> 0.77098539 | W10: =(591-M10)/591 -> 0.89509306 | X10: 9mins downtime replacing a broken bolt on the Shuffler for the Packer & 8mins for a broken bolt beneath the Packer. 8mins Labeler startup adjustments due to the operator being late; 6mins downtime due to the crown transfer sensor malfunctioning; 3mins for stuck crowns; 6mins downtime switching BBT's; & 2mins switching Labeler from local to export and 5mins from export to local. | AE10: 15000 | AF10: 17000
B11: 42779 | C11: CARIB (AMBER) | D11: 4900 | E11: 0.33333333 | F11: =SUM([3]February_2017!$J15) -> 339.9 | G11: =SUM([3]February_2017!$F15) -> 5115 | H11: =SUM([3]February_2017!$K15) -> 337.59 | I11: =SUM([3]February_2017!$N15) -> 11.25 | J11: =SUM([3]February_2017!$Q15) -> 514.93289 | K11: =SUM([3]February_2017!$E15) -> 596 | L11: 0.78194444 | M11: =SUM([3]February_2017!$M15) -> 49 | P11: =SUM([3]February_2017!$P15) -> 0.67961165 | R11: =($G11)/(($K11/60)*AE$3*(1/24)) -> 0.82389262 | S11: =($G11)/(($K11/60)*AF$3*(1/24)) -> 0.72696407 | T11: =(G11)*24/(K11/60)/15000 -> 0.82389262 | U11: =(H11+H14)*24/(M11/60)/15000 -> 1.3389649 | V11: =(G11)*24/(K11/60)/17000 -> 0.72696407 | W11: =(686-M11)/686 -> 0.92857143 | X11: 10mins late start due to low temperature on the Washer; 10mins downtime resulting from adjustments to the pusher for EBI rejection; 7mins downtime for stuck crowns; 3mins for jammed bottle in the Filler worm; 2mins HPI temperature fault; 6mins downtime switching BBT's (low level in the filling bowl); & 3mins waiting on the forklift. | AE11: 15000 | AF11: 17000
B12: 42780 | C12: CARIB (AMBER) | D12: 4900 | E12: 0.31319444 | F12: =SUM([3]February_2017!$J16) -> 320.6 | G12: =SUM([3]February_2017!$F16) -> 4707 | H12: =SUM([3]February_2017!$K16) -> 320.162 | I12: =SUM([3]February_2017!$N16) -> 38.75 | J12: =SUM([3]February_2017!$Q16) -> 531.12605 | K12: =SUM([3]February_2017!$E16) -> 595 | L12: 0.78402778 | M12: =SUM([3]February_2017!$M16) -> 71 | P12: =SUM([3]February_2017!$P16) -> 0.13661884 | R12: =($G12+$G13)/(($K12/60)*AE$3*(1/24)) -> 0.84980168 | S12: =($G12+$G13)/(($K12/60)*AF$3*(1/24)) -> 0.74982501 | T12: =(G12+G13)*24/(K12/60)/15000 -> 0.84980168 | U12: =(H12+H15)*24/(M12/60)/15000 -> 0.82304992 | V12: =(G12+G13)*24/(K12/60)/17000 -> 0.74982501 | W12: =(709-(M12+M13))/709 -> 0.87447109 | X12: 27mins Packer downtime for adjustments to the cup on the head; 11mins downtime for back up on the conveyor line ex. Pasteurizer due to bottle jams. 4mins on line ex. Filler; 8mins downtime for stuck crowns; & 10mins product delay for an air lock on the line. | AE12: 15000 | AF12: 17000
C13: STAG | F13: =SUM([3]February_2017!$J17) -> 37.9 | G13: =SUM([3]February_2017!$F17) -> 560 | H13: =SUM([3]February_2017!$K17) -> 36.96 | I13: =SUM([3]February_2017!$N17) -> 1.5 | M13: =SUM([3]February_2017!$M17) -> 18 | N13: =[4]Feb!$I$16/K12 -> 0.021848739 | P13: =SUM([3]February_2017!$P17) -> 2.4802111 | X13: 13mins change-over downtime; 2mins EBI adjustments; 1min for stuck crowns. | AE13: 15000 | AF13: 17000
B14: 42781 | C14: STAG | D14: 5600 | E14: 0.32152778 | F14: =SUM([3]February_2017!$J18) -> 347 | G14: =SUM([3]February_2017!$F18) -> 5240 | H14: =SUM([3]February_2017!$K18) -> 345.84 | I14: =SUM([3]February_2017!$N18) -> 33.75 | J14: =SUM([3]February_2017!$Q18) -> 583.30241 | K14: =SUM([3]February_2017!$E18) -> 539 | L14: 0.75 | M14: =SUM([3]February_2017!$M18) -> 49 | P14: =SUM([3]February_2017!$P18) -> 0.33429395 | R14: =($G14)/(($K14/60)*AE$3*(1/24)) -> 0.93328386 | S14: =($G14)/(($K14/60)*AF$3*(1/24)) -> 0.82348576 | T14: =(G14)*24/(K14/60)/15000 -> 0.93328386 | U14: =(H14+H17)*24/(M14/60)/15000 -> 0.84317388 | V14: =(G14)*24/(K14/60)/17000 -> 0.82348576 | W14: =(654-M14)/654 -> 0.92507645 | X14: 27mins downtime for stuck crowns in the chute; hopper; & bin. 3mins stuck bottles in the in-feed worm; 6mins product delay switching BBT's; & 4mins downtime due to slow packing. | AE14: 15000 | AF14: 17000
B15: 42782 | C15: MACKESON | D15: 4200 | E15: 0.31458333 | F15: =SUM([3]February_2017!$J19) -> 289.5 | G15: =SUM([3]February_2017!$F19) -> 4372 | H15: =SUM([3]February_2017!$K19) -> 288.552 | I15: =SUM([3]February_2017!$N19) -> 16.75 | J15: =SUM([3]February_2017!$Q19) -> 484.87985 | K15: =SUM([3]February_2017!$E19) -> 541 | L15: 0.75 | M15: =SUM([3]February_2017!$M19) -> 121 | P15: =SUM([3]February_2017!$P19) -> 0.32746114 | R15: =($G15)/(($K15/60)*AE$3*(1/24)) -> 0.77580776 | S15: =($G15)/(($K15/60)*AF$3*(1/24)) -> 0.68453626 | T15: =(G15)*24/(K15/60)/15000 -> 0.77580776 | U15: =(H15+H18)*24/(M15/60)/15000 -> 0.29744053 | V15: =(G15)*24/(K15/60)/17000 -> 0.68453626 | W15: =(652-M15)/652 -> 0.81441718 | X15: 42mins downtime for adjustments on the Sealer; 20mins downtime to make adjustments on the Labeler & remove bottles with upside down labels from the line; 16mins low temperature on the Pasteurizer at startup; 13mins downtime for stuck crowns in the chute and hopper. 1min flushing the crowner; & 8mins Labeler adjustments for missing labels. | AE15: 15000 | AF15: 17000
B16: 42783 | C16: =[3]February_2017!$D20 -> GINGER | D16: 1200 | E16: 0.32291667 | F16: =SUM([3]February_2017!$J20) -> 90.4 | G16: =SUM([3]February_2017!$F20) -> 1126 | H16: =SUM([3]February_2017!$K20) -> 88.954 | I16: =SUM([3]February_2017!$N20) -> 1.75 | J16: =SUM([3]February_2017!$Q20) -> 401.09756 | K16: =SUM([3]February_2017!$E20) -> 492 | L16: 0.70833333 | M16: =SUM([3]February_2017!$M20) -> 49 | P16: =SUM([3]February_2017!$P20) -> 1.5995575 | R16: =($G$16+$G$17+$G$18)/(($K$16/60)*AE3*(1/24)) -> 0.6417561 | S16: =($G$16+$G$17+$G$18)/(($K$16/60)*AF3*(1/24)) -> 0.56625538 | T16: =(G16+G17+G18)*24/(K16/60)/15000 -> 0.6417561 | U16: =(H16+H19)*24/(M16/60)/15000 -> 0.72678661 | V16: =(G16+G17+G18)*24/(K16/60)/17000 -> 0.56625538 | W16: =(590-M16)/590 -> 0.91694915 | X16: 13mins low water pressure in the Soft Drink Plant; 9mins adjusting the guide in the crown transfer chute; 4mins for stuck crowns in the chute; 4mins adjusting the centering cup on the Packer; 5mins adjusting the guard rail; & 4mins Labeler downtime for adjustments. | AE16: 15000 | AF16: 17000
C17: =[3]February_2017!$D21 -> BANANA | D17: 1200 | F17: =SUM([3]February_2017!$J21) -> 90.4 | G17: =SUM([3]February_2017!$F21) -> 1070 | H17: =SUM([3]February_2017!$K21) -> 84.53 | I17: =SUM([3]February_2017!$N21) -> 0.5 | M17: =SUM([3]February_2017!$M21) -> 43 | N17: =[4]Feb!$I$20/K16 -> 0.054878049 | P17: =SUM([3]February_2017!$P21) -> 6.4933628 | X17: 27mins change-over downtime; 7mins for Labeler adjustments; & 4mins Packer downtime for adjustments. | AE17: 15000 | AF17: 17000
C18: =[3]February_2017!$D22 -> GRAPE | D18: 1200 | F18: =SUM([3]February_2017!$J22) -> 90.4 | G18: =SUM([3]February_2017!$F22) -> 1093 | H18: =SUM([3]February_2017!$K22) -> 86.347 | I18: =SUM([3]February_2017!$N22) -> 6.75 | M18: =SUM([3]February_2017!$M22) -> 90 | N18: =[4]Feb!$I$21/K16 -> 0.038617886 | P18: =SUM([3]February_2017!$P22) -> 4.4834071 | X18: 19mins change-over downtime; 24mins Product delay (Grape mixing was not complete); 28mins downtime resulted from the pump in the Soft Drink Plant tripping off (A fuse had to be changed); 8mins downtime for stuck crowns; & 6mins low air pressure on the Filler. | AE18: 15000 | AF18: 17000
B19: 42786 | C19: CARIB (AMBER) | D19: 4200 | E19: 0.38194444 | F19: =SUM([3]February_2017!$J23) -> 284.5 | G19: =SUM([3]February_2017!$F23) -> 3985 | H19: =SUM([3]February_2017!$K23) -> 282.01 | I19: =SUM([3]February_2017!$N23) -> 27.75 | J19: =SUM([3]February_2017!$Q23) -> 496.05809 | K19: =SUM([3]February_2017!$E23) -> 482 | L19: 0.71111111 | M19: =SUM([3]February_2017!$M23) -> 114 | P19: =SUM([3]February_2017!$P23) -> 0.87521968 | R19: =($G$19)/(($K$19/60)*15000*(1/24)) -> 0.79369295 | S19: =($G$19)/(($K$19/60)*17000*(1/24)) -> 0.70031731 | T19: =(G19)*24/(K19/60)/15000 -> 0.79369295 | U19: =(H19+H22)*24/(M19/60)/15000 -> 0.46919074 | V19: =(G19)*24/(K19/60)/17000 -> 0.70031731 | W19: =(532-M19)/532 -> 0.78571429 | X19: 70mins late start due to a breakdown on the Boiler (low temperature on the Washer & Pasteurizer); 14mins downtime for stuck crowns; 9mins adjusting the Labeler for body labels; 5mins Pasteurizer downtime (hydraulics cut off); & 5mins low CO2 on the Filler. | AE19: 15000 | AF19: 17000
B20: 42787 | C20: =[3]February_2017!$D24 -> CARIB (FLINT) | D20: 500 | E20: 0.31111111 | F20: =SUM([3]February_2017!$J24) -> 263.3 | G20: =SUM([3]February_2017!$F24) -> 992 | H20: =SUM([3]February_2017!$K24) -> 262.03 | I20: =SUM([3]February_2017!$N24) -> 17.5 | J20: =SUM([3]February_2017!$Q24) -> 539.16084 | K20: =SUM([3]February_2017!$E24) -> 429 | L20: 0.66805556 | M20: =SUM([3]February_2017!$M24) -> 39 | N20: =[4]Feb!$I$23/K20 -> 0.011655012 | P20: =SUM([3]February_2017!$P24) -> 0.48233954 | R20: =($G$20+$G$21)/(($K$20/60)*15000*(1/24)) -> 0.86265734 | S20: =($G$20+$G$21)/(($K$20/60)*17000*(1/24)) -> 0.76116824 | T20: =(G20+G21)*24/(K20/60)/15000 -> 0.86265734 | U20: =(H20+H23)*24/(M20/60)/15000 -> 1.326848 | V20: =(G20+G21)*24/(K20/60)/17000 -> 0.76116824 | W20: =(542-M20)/542 -> 0.92804428 | X20: 9mins EBI adjustments (changing the belt); 5mins Labeler downtime for adjustments; 5mins change-over from export to local and local to export; 5mins downtime for bottle jams ex. Pasteurizer; 4mins cleaning the Fobber line; 3mins adjusting the centering bell on the Filler; & 3mins adjusting the in-feed worm on the Filler. | AE20: 15000 | AF20: 17000
C21: =[3]February_2017!$D25 -> CARIB (AMBER) | D21: 3700 | G21: =SUM([3]February_2017!$F25) -> 2863 | AE21: 15000 | AF21: 17000
B22: 42789 | C22: =[3]February_2017!$D26 -> STAG | D22: 4900 | E22: 0.31597222 | F22: =SUM([3]February_2017!$J26) -> 276.95 | G22: =SUM([3]February_2017!$F26) -> 4169 | H22: =SUM([3]February_2017!$K26) -> 275.154 | I22: =SUM([3]February_2017!$N26) -> 12 | J22: =SUM([3]February_2017!$Q26) -> 535.63169 | K22: =SUM([3]February_2017!$E26) -> 467 | L22: 0.69791667 | M22: =SUM([3]February_2017!$M26) -> 43 | P22: =SUM([3]February_2017!$P26) -> 0.64849251 | R22: =($G22)/(($K$22/60)*15000*(1/24)) -> 0.85701071 | S22: =($G22)/(($K$22/60)*17000*(1/24)) -> 0.75618592 | T22: =(G22)*24/(K22/60)/15000 -> 0.85701071 | U22: =(H22+H25)*24/(M22/60)/15000 -> 1.533312 | V22: =(G22)*24/(K22/60)/17000 -> 0.75618592 | W22: =(582-M22)/582 -> 0.92611684 | X22: 13mins EBI downtime adjusting the blue belt in the passageway; 14mins downtime for stuck crowns in the chute and hopper; 6mins product delat switching BBT's; & 3mins downtime to repair broken rail on the in-feed conveyor to the Packer. | AE22: 15000 | AF22: 17000
B23: 42790 | C23: =[3]February_2017!$D27 -> GUINNESS | D23: 4200 | E23: 0.32291667 | F23: =SUM([3]February_2017!$J27) -> 278.1 | G23: =SUM([3]February_2017!$F27) -> 4197 | H23: =SUM([3]February_2017!$K27) -> 277.002 | I23: =SUM([3]February_2017!$N27) -> 26 | J23: =SUM([3]February_2017!$Q27) -> 369.77974 | K23: =SUM([3]February_2017!$E27) -> 681 | L23: 0.84861111 | M23: =SUM([3]February_2017!$M27) -> 239 | P23: =SUM([3]February_2017!$P27) -> 0.39482201 | R23: =($G23)/(($K$23/60)*15000*(1/24)) -> 0.59164758 | S23: =($G23)/(($K$23/60)*17000*(1/24)) -> 0.52204198 | T23: =(G23)*24/(K23/60)/15000 -> 0.59164758 | U23: =(H23+H26)*24/(M23/60)/15000 -> 0.1112644 | V23: =(G23)*24/(K23/60)/17000 -> 0.52204198 | W23: =(795-M23)/795 -> 0.69937107 | X23: 110mins Washer downtime caused by a damaged motor on the load table; 49mins Labeler downtime for alignment issues at startup (back station). 15mins of adjustments for flagging labels; 17mins downtime due to low filling bowl level (explanation needed); 15mins Packer downtime for adjustments to the Head; The Videojet cut off for 12mins; & 7mins downtime on line ex. Pasteurizer. | AE23: 15000 | AF23: 17000
B24: 42793 | C24: =[3]February_2017!$D28 -> CARIB (AMBER) | D24: 4900 | E24: 0.31597222 | F24: =SUM([3]February_2017!$J28) -> 348.1 | G24: =SUM([3]February_2017!$F28) -> 5036 | H24: =SUM([3]February_2017!$K28) -> 345.676 | I24: =SUM([3]February_2017!$N28) -> 31.25 | J24: =SUM([3]February_2017!$Q28) -> 543.45324 | K24: =SUM([3]February_2017!$E28) -> 556 | L24: 0.75486111 | M24: =SUM([3]February_2017!$M28) -> 117 | P24: =SUM([3]February_2017!$P28) -> 0.69635162 | R24: =($G24)/(($K$24/60)*15000*(1/24)) -> 0.86952518 | S24: =($G24)/(($K$24/60)*17000*(1/24)) -> 0.7672281 | T24: =(G24)*24/(K24/60)/15000 -> 0.86952518 | U24: =(H24+H27)*24/(M24/60)/15000 -> 0.28363159 | V24: =(G24)*24/(K24/60)/17000 -> 0.7672281 | W24: =(658-M24)/658 -> 0.82218845 | X24: 85mins downtime for repairs to the crown transfer sensor; & 14mins for stuck crowns; 7mins downtime for fallen & jammed bottles on the conveyor line ex. Pasteurizer; & 4mins Packer downtime for adjustments. | AE24: 15000 | AF24: 17000
B25: 42794 | C25: STAG | D25: 4900 | E25: 0.33680556 | F25: =SUM([3]February_2017!$J29) -> 412.9 | G25: =SUM([3]February_2017!$F29) -> 6237 | H25: =SUM([3]February_2017!$K29) -> 411.642 | I25: =SUM([3]February_2017!$N29) -> 38.25 | J25: =SUM([3]February_2017!$Q29) -> 591.18483 | K25: =SUM([3]February_2017!$E29) -> 633 | L25: 0.80763889 | M25: =SUM([3]February_2017!$M29) -> 65 | P25: =SUM([3]February_2017!$P29) -> 0.30467426 | R25: =($G25)/(($K$25/60)*15000*(1/24)) -> 0.94589573 | S25: =($G25)/(($K$25/60)*17000*(1/24)) -> 0.83461388 | T25: =(G25)*24/(K25/60)/15000 -> 0.94589573 | U25: =(H25+H28)*24/(M25/60)/15000 -> 0.60796357 | V25: =(G25)*24/(K25/60)/17000 -> 0.83461388 | W25: =(736-M25)/736 -> 0.91168478 | X25: 15mins late startup replacing damaged oring on the gaf filter. 9mins downtime making adjustments for half-fills; 10mins for stuck crowns; 15mins low air pressure on the Filler; 7mins downtime picking up fallen bottles on line ex. Pasteurizer; & 4mins adjusting the in-feed sensor to the Packer. | AE25: 15000 | AF25: 17000
AE26: 15000 | AF26: 17000
AE27: 15000 | AF27: 17000
AE28: 15000 | AF28: 17000
AE29: 15000 | AF29: 17000
AE30: 15000 | AF30: 17000
AE31: 15000 | AF31: 17000
AE32: 15000 | AF32: 17000
AE33: 15000 | AF33: 17000
AE34: 15000 | AF34: 17000
AE35: 15000 | AF35: 17000
AE36: 15000 | AF36: 17000
AE37: 15000 | AF37: 17000
... AE54: 15000 | AF54: 17000
U55: =G55*24/(K55/60)/15400 -> #DIV/0! | AE55: 15000 | AF55: 17000
U56: =G56*24/(K56/60)/15400 -> #DIV/0! | AE56: 15000 | AF56: 17000
AE57: 15000 | AF57: 17000
...

Sheet March_17
B2: Daily Bottling Hall Summary 2017
B3: Date | C3: Product Bottled | D3: Planned Production Cases | E3: Filler Start Time | F3: BBT Hls | G3: Cases bottled | H3: Bott Hls | I3: No.of Rejects | J3: Cases Per hour (524 @ 17000bph) | K3: Fill Time Mins | L3: Packer End Time | M3: Down Time Mins | N3: Change Over % (1.1) | O3: Cases on hold | P3: Bottling Loss (1.1%) | Q3: Reworks Cases | R3: GBL Plant Utilization @ 15,000 | S3: GBL Plant Utilization @ 17,000 | T3: Line Rated Efficiency (74%) @15,000 | U3: Line Rated Efficiency (15000 74%) | V3: Line Rated Efficiency (74%) @17,000 | W3: Plant Availability (95%) | X3: Comments | AE3: 15000 | AF3: 17000
B4: 42795 | C4: SHANDY SORREL | D4: 2800 | E4: 0.31458333 | F4: =SUM([3]March_2017!$J8) -> 171 | G4: =SUM([3]March_2017!$F8) -> 2582 | H4: =SUM([3]March_2017!$K8) -> 170.412 | I4: =SUM([3]March_2017!$N8) -> 10.25 | J4: =SUM([3]March_2017!$Q8) -> 607.52941 | K4: =SUM([3]March_2017!$E8) -> 255 | L4: 0.54513889 | M4: =SUM([3]March_2017!$M8) -> 25 | O4: =SUM([3]March_2017!$H8) -> 0 | P4: =SUM([3]March_2017!$P8) -> 0.34385965 | R4: =($G4)/(($K4/60)*AE$3*(1/24)) -> 0.97204706 | S4: =($G4)/(($K4/60)*AF$3*(1/24)) -> 0.85768858 | T4: =(G4)*24/(K4/60)/15000 -> 0.97204706 | U4: =(H4+H7)*24/(M4/60)/15000 -> 1.0553242 | V4: =(G4)*24/(K4/60)/17000 -> 0.85768858 | W4: =(360-(M4))/360 -> 0.93055556 | X4: 13mins downtime for broken and jammed bottles on line ex. Pasteurizer; 7mins downtime for stuck crowns; & 1min flushing the crowner.
B5: 42796 | C5: VITAMALT | D5: 4000 | E5: 0.32986111 | F5: =SUM([3]March_2017!$J9) -> 298.9 | G5: =SUM([3]March_2017!$F9) -> 3985 | H5: =SUM([3]March_2017!$K9) -> 296.484 | I5: =SUM([3]March_2017!$N9) -> 22.75 | J5: =SUM([3]March_2017!$Q9) -> 387.52026 | K5: =SUM([3]March_2017!$E9) -> 617 | L5: 0.8 | M5: =SUM([3]March_2017!$M9) -> 159 | O5: =SUM([3]March_2017!$H9) -> 0 | P5: =SUM([3]March_2017!$P9) -> 0.80829709 | R5: =($G5)/(($K5/60)*AE$3*(1/24)) -> 0.62003241 | S5: =($G5)/(($K5/60)*AF$3*(1/24)) -> 0.54708742 | T5: =(G5)*24/(K5/60)/15000 -> 0.62003241 | U5: =(H5+H8)*24/(M5/60)/15000 -> 0.38899442 | V5: =(G5)*24/(K5/60)/17000 -> 0.54708742 | W5: =(724-(M5))/724 -> 0.78038674 | X5: 100mins downtime repairing a broken guide on the crown transfer shute; 20mins downtime removing bent crowns from the chute and bin on top the crowner; 6mins Labeler downtime for start-up adjustments; 5mins caustic carry over on the Washer; 5mins Packer adjustments; & 3mins air dryer fault.
B6: 42797 | C6: TING | D6: 1800 | E6: 0.33333333 | F6: =SUM([3]March_2017!$J10) -> 122.958 | G6: =SUM([3]March_2017!$F10) -> 1802 | H6: =SUM([3]March_2017!$K10) -> 118.932 | I6: =SUM([3]March_2017!$N10) -> 5.5 | J6: =SUM([3]March_2017!$Q10) -> 345.89438 | K6: =SUM([3]March_2017!$E10) -> 587 | L6: 0.77638889 | M6: =SUM([3]March_2017!$M10) -> 179 | O6: =SUM([3]March_2017!$H10) -> 0 | P6: =SUM([3]March_2017!$P10) -> 3.2742888 | R6: =($G6+$G7)/(($K6/60)*AE$3*(1/24)) -> 0.55343101 | S6: =($G6+$G7)/(($K6/60)*AF$3*(1/24)) -> 0.48832148 | T6: =(G6+G7)*24/(K6/60)/15000 -> 0.55343101 | U6: =(H6+H9)*24/(M6/60)/15000 -> 0.2153886 | V6: =(G6+G7)*24/(K6/60)/17000 -> 0.48832148 | W6: =(698-(M6+M7))/698 -> 0.67621777 | X6: 166mins late start-up due to a broken key on the EBI Shaft; 6mins for stuck crowns; 2mins air dryer fault; & 2mins for stuck bottles in the Filler in-feed worm.
C7: GINSENG | D7: 1500 | F7: =SUM([3]March_2017!$J11) -> 104.5 | G7: =SUM([3]March_2017!$F11) -> 1582 | H7: =SUM([3]March_2017!$K11) -> 104.412 | I7: =SUM([3]March_2017!$N11) -> 9.5 | M7: =SUM([3]March_2017!$M11) -> 47 | N7: =[4]Mar!$I$11/K6 -> 0.042589438 | O7: =SUM([3]March_2017!$H11) -> 0 | P7: =SUM([3]March_2017!$P11) -> 0.084210526 | X7: 25mins Change-over downtime; 9mins Videojet adjustments because it was not printing; & 6mins downtime for jammed bottles on conveyor line ex. Pasteurizer.
B8: 42800 | C8: CARIB (AMBER) | D8: 4900 | E8: 0.38125 | F8: =SUM([3]March_2017!$J12) -> 349.8 | G8: =SUM([3]March_2017!$F12) -> 5068 | H8: =SUM([3]March_2017!$K12) -> 347.788 | I8: =SUM([3]March_2017!$N12) -> 20 | J8: =SUM([3]March_2017!$Q12) -> 512.78246 | K8: =SUM([3]March_2017!$E12) -> 593 | L8: 0.78055556 | M8: =SUM([3]March_2017!$M12) -> 135 | P8: =SUM([3]March_2017!$P12) -> 0.57518582 | R8: =($G8)/(($K8/60)*AE$3*(1/24)) -> 0.82045194 | S8: =($G8)/(($K8/60)*AF$3*(1/24)) -> 0.72392818 | T8: =(G8)*24/(K8/60)/15000 -> 0.82045194 | U8: =(H8+H11)*24/(M8/60)/15000 -> 0.47386311 | V8: =(G8)*24/(K8/60)/17000 -> 0.72392818 | W8: =(594-(M8))/594 -> 0.77272727 | X8: Late start-up due to malfunction on panel that controls the conveyor lines to the Washer & Crate Rinser. 6mins downtime due to the line ex. Washer tripping off & 5mins due to bottle jams on line ex. Pasteurizer. 14mins for stuck crowns; 2mins air dryer fault; 9mins downtime switching pallet packer; & 9mins downtime to low filling bowl level when switching BBT's.
B9: 42801 | C9: CARIB (AMBER) | D9: 4900 | E9: 0.34375 | F9: =SUM([3]March_2017!$J13) -> 285 | G9: =SUM([3]March_2017!$F13) -> 4283 | H9: =SUM([3]March_2017!$K13) -> 282.678 | I9: =SUM([3]March_2017!$N13) -> 18 | J9: =SUM([3]March_2017!$Q13) -> 520.87379 | K9: =SUM([3]March_2017!$E13) -> 618 | L9: 0.78541667 | M9: =SUM([3]March_2017!$M13) -> 95 | P9: =SUM([3]March_2017!$P13) -> 0.81473684 | R9: =($G9+$G10)/(($K9/60)*AE$3*(1/24)) -> 0.83339806 | S9: =($G9+$G10)/(($K9/60)*AF$3*(1/24)) -> 0.73535123 | T9: =(G9+G10)*24/(K9/60)/15000 -> 0.83339806 | U9: =(H9+H12)*24/(M9/60)/15000 -> 0.64000269 | V9: =(G9+G10)*24/(K9/60)/17000 -> 0.73535123 | W9: =(707-(M9+M10))/707 -> 0.83451202 | X9: 25mins late start waiting for product release; 10mins downtime for low PU. 8mins Pasteurizer downtime for hydraulics malfunction; 9mins for jammed bottle ex. Pasteurizer; 8mins downtime for stuck crowns; 2mins dryer fault; 3mins for jammed bottle in the in-feed worm; & 7mins low bowl level while switching BBT's.
C10: STAG | D10: 1000 | F10: =SUM([3]March_2017!$J14) -> 72 | G10: =SUM([3]March_2017!$F14) -> 1082 | H10: =SUM([3]March_2017!$K14) -> 71.412 | I10: =SUM([3]March_2017!$N14) -> 1 | M10: =SUM([3]March_2017!$M14) -> 22 | N10: =[4]Mar!$I$14/K9 -> 0.027508091 | P10: =SUM([3]March_2017!$P14) -> 0.81666667 | X10: 17mins Change-over downtime; 3mins for stuck crowns & 2mins air dryer fault.
B11: 42802 | C11: STAG | D11: 4900 | E11: 0.32847222 | F11: =SUM([3]March_2017!$J15) -> 320.9 | G11: =SUM([3]March_2017!$F15) -> 4827 | H11: =SUM([3]March_2017!$K15) -> 318.582 | I11: =SUM([3]March_2017!$N15) -> 44 | J11: =SUM([3]March_2017!$Q15) -> 451.82527 | K11: =SUM([3]March_2017!$E15) -> 641 | L11: 0.80208333 | M11: =SUM([3]March_2017!$M15) -> 172 | P11: =SUM([3]March_2017!$P15) -> 0.72234341 | R11: =($G11)/(($K11/60)*AE$3*(1/24)) -> 0.72292044 | S11: =($G11)/(($K11/60)*AF$3*(1/24)) -> 0.63787097 | T11: =(G11)*24/(K11/60)/15000 -> 0.72292044 | U11: =(H11+H14)*24/(M11/60)/15000 -> 0.31644726 | V11: =(G11)*24/(K11/60)/17000 -> 0.63787097 | W11: =(733-(M11))/733 -> 0.76534789 | X11: 58mins waiting on product release (perceived high haze); 33mins downtime resulting from the conveyor ex. Pasteurizer coming off the track; 14mins for jammed bottles on conveyor ex. Pasteurizer. 20mins for stuck crowns in the chute; 10mins stuck crowns in the bin on top the crowner; 8mins flushing the crowner; & 5mins air dryer fault. 9mins adjusting the EBI belt at start-up; & 8mins of caustic carry-over on the Washer.
B12: 42803 | C12: STAG | D12: 5600 | E12: 0.34097222 | F12: =SUM([3]March_2017!$J16) -> 351.8 | G12: =SUM([3]March_2017!$F16) -> 5313 | H12: =SUM([3]March_2017!$K16) -> 350.658 | I12: =SUM([3]March_2017!$N16) -> 13 | J12: =SUM([3]March_2017!$Q16) -> 508.42105 | K12: =SUM([3]March_2017!$E16) -> 627 | L12: 0.79236111 | M12: =SUM([3]March_2017!$M16) -> 115 | P12: =SUM([3]March_2017!$P16) -> 0.32461626 | R12: =($G12)/(($K12/60)*AE$3*(1/24)) -> 0.81347368 | S12: =($G12)/(($K12/60)*AF$3*(1/24)) -> 0.7177709 | T12: =(G12)*24/(K12/60)/15000 -> 0.81347368 | U12: =(H12+H15)*24/(M12/60)/15000 -> 0.46668856 | V12: =(G12)*24/(K12/60)/17000 -> 0.7177709 | W12: =(720-(M12))/720 -> 0.84027778 | X12: 27mins adjusting the fingers on the gripper cylinder for the Labeler; 10mins low steam on the Pasteurizer at start-up & 17mins around mid-day. 21mins delay waiting on product release; 10mins downtime on the Pasteurizer due to the hydraulics malfunctioning; 8mins downtime for jammed bottles on conveyor ex. Pasterizer; & 6mins for stuck crowns.
B13: 42804 | C13: STAG | D13: 1100 | E13: 0.34027778 | F13: =SUM([3]March_2017!$J17) -> 103 | G13: =SUM([3]March_2017!$F17) -> 1467 | H13: =SUM([3]March_2017!$K17) -> 101.572 | I13: =SUM([3]March_2017!$N17) -> 7.25 | J13: =SUM([3]March_2017!$Q17) -> 522.12766 | K13: =SUM([3]March_2017!$E17) -> 564 | L13: 0.74722222 | M13: =SUM([3]March_2017!$M17) -> 42 | P13: =SUM([3]March_2017!$P17) -> 1.3864078 | R13: =($G13+$G14)/(($K13/60)*AE$3*(1/24)) -> 0.83540426 | S13: =($G13+$G14)/(($K13/60)*AF$3*(1/24)) -> 0.7371214 | T13: =(G13+G14)*24/(K13/60)/15000 -> 0.83540426 | U13: =(H13+H16)*24/(M13/60)/15000 -> 0.23216457 | V13: =(G13+G14)*24/(K13/60)/17000 -> 0.7371214 | W13: =(644-(M13+M14))/644 -> 0.88198758 | X13: 20mins late start waiting on product release & 4mins for stuck crowns.
C14: CARIB (AMBER) | D14: 3500 | F14: =SUM([3]March_2017!$J18) -> 249.3 | G14: =SUM([3]March_2017!$F18) -> 3441 | H14: =SUM([3]March_2017!$K18) -> 248.386 | I14: =SUM([3]March_2017!$N18) -> 11.5 | M14: =SUM([3]March_2017!$M18) -> 34 | N14: =[4]Mar!$I$18/K13 -> 0.010638298 | P14: =SUM([3]March_2017!$P18) -> 0.36662655 | X14: 15mins low air pressure on the Uncaser; 6mins change-over downtime; & 6mins stuck crowns & 3mins air dryer fault.
B15: 42807 | C15: CARIB (AMBER) | D15: 835 | E15: 0.33472222 | F15: =SUM([3]March_2017!$J19) -> 208.6 | G15: =SUM([3]March_2017!$F19) -> 1464 | H15: =SUM([3]March_2017!$K19) -> 208.396 | I15: =SUM([3]March_2017!$N19) -> 11 | J15: =SUM([3]March_2017!$Q19) -> 491.5493 | K15: =SUM([3]March_2017!$E19) -> 639 | L15: 0.80347222 | M15: =SUM([3]March_2017!$M19) -> 36 | P15: =SUM([3]March_2017!$P19) -> 0.097794823 | R15: =($G15+$G16+$G17+$G18)/(($K15/60)*AE$3*(1/24)) -> 0.78647887 | S15: =($G15+$G16+$G17+$G18)/(($K15/60)*AF$3*(1/24)) -> 0.69395195 | T15: =(G15+G16+G18+G17)*24/(K15/60)/15000 -> 0.78647887 | U15: =(H15+H18)*24/(M15/60)/15000 -> 0.81057067 | V15: =(G15+G16+G17+G18)*24/(K15/60)/17000 -> 0.69395195 | W15: =(728-(M15+M17+M18))/728 -> 0.87774725 | X15: 12mins late start waiting on product release; 9mins for stuck crowns; 3mins air dryer faults; & 4mins labeler adjustments.
C16: CARIB (FLINT) | D16: 1800 | G16: =SUM([3]March_2017!$F20) -> 1587
C17: SHANDY LIME | D17: 1400 | F17: =SUM([3]March_2017!$J21) -> 50.2 | G17: =SUM([3]March_2017!$F21) -> 736 | H17: =SUM([3]March_2017!$K21) -> 48.576 | I17: =SUM([3]March_2017!$N21) -> 0 | M17: =SUM([3]March_2017!$M21) -> 22 | N17: =[4]Mar!$I$20/(K15) -> 0.021909233 | P17: =SUM([3]March_2017!$P21) -> 3.2350598 | X17: 14mins change-over
C18: SHANDY GINGER | D18: 700 | F18: =SUM([3]March_2017!$J22) -> 99.7 | G18: =SUM([3]March_2017!$F22) -> 1448 | H18: =SUM([3]March_2017!$K22) -> 95.568 | I18: =SUM([3]March_2017!$N22) -> 0 | M18: =SUM([3]March_2017!$M22) -> 31 | N18: =[4]Mar!$I$21/K15 -> 0.034428795 | P18: =SUM([3]March_2017!$P22) -> 4.1444333 | X18: 22mins change-over.
B19: 42808 | C19: GUINNESS | D19: 4900 | E19: 0.32986111 | F19: =SUM([3]March_2017!$J23) -> 310.7 | G19: =SUM([3]March_2017!$F23) -> 4671 | H19: =SUM([3]March_2017!$K23) -> 308.286 | I19: =SUM([3]March_2017!$N23) -> 19 | J19: =SUM([3]March_2017!$Q23) -> 495.15901 | K19: =SUM([3]March_2017!$E23) -> 566 | L19: 0.75763889 | M19: =SUM([3]March_2017!$M23) -> 94 | P19: =SUM([3]March_2017!$P23) -> 0.77695526 | R19: =($G19)/(($K19/60)*AE$3*(1/24)) -> 0.79225442 | S19: =($G19)/(($K19/60)*AF$3*(1/24)) -> 0.69904801 | T19: =(G19)*24/(K19/60)/15000 -> 0.79225442 | U19: =(H19+H22)*24/(M19/60)/15000 -> 0.40440102 | V19: =(G19)*24/(K19/60)/17000 -> 0.69904801 | W19: =(665-(M19))/665 -> 0.85864662 | X19: 58mins downtime making adjustments on the Labeler back station; 12mins for stuck crowns; 5mins removing jammed bottles from in-feed worm on the Filler; 3mins lost checking the Fobber pressure; & 8mins downtime for jammed bottles on conveyor ex. Pasterizer.
B20: 42809 | C20: STARMALT | D20: 4900 | E20: 0.33472222 | F20: =SUM([3]March_2017!$J24) -> 344.7 | G20: =SUM([3]March_2017!$F24) -> 5197 | H20: =SUM([3]March_2017!$K24) -> 343.002 | I20: =SUM([3]March_2017!$N24) -> 10 | J20: =SUM([3]March_2017!$Q24) -> 564.8913 | K20: =SUM([3]March_2017!$E24) -> 552 | L20: 0.73680556 | M20: =SUM([3]March_2017!$M24) -> 60 | P20: =SUM([3]March_2017!$P24) -> 0.49260226 | R20: =($G20)/(($K20/60)*AE$3*(1/24)) -> 0.90382609 | S20: =($G20)/(($K20/60)*AF$3*(1/24)) -> 0.79749361 | T20: =(G20)*24/(K20/60)/15000 -> 0.90382609 | U20: =(H20+H23)*24/(M20/60)/15000 -> 0.688728 | V20: =(G20)*24/(K20/60)/17000 -> 0.79749361 | W20: =(641-(M20))/641 -> 0.90639626 | X20: 19mins late start due to low PU; & 3mins low PU after start up. 10mins downtime for jammed bottles on conveyor ex. Pasteurizer; 2mins to fix rail on line ex. Pasteurizer; 7mins for stuck crowns; 3mins to remove broken/jammed bottle on the Packer; 3mins adjusting a finger on the Packer head; & 4mins switching pallet packer.
